Workbook

Sheet Cover
B1: Amazon.com, Inc. (NASDAQ: AMZN) — valuation model
B2: Unlevered DCF, trading comparables and residual income, triangulated. Public information only. Not investment advice.
B4: Prepared by | C4: Jung Ryul Lee
B5: Data as of | C5: Market data 21 Aug 2026; financials FY2025 (Form 10-K)
B6: Units | C6: US$ millions except per share
B8: What this model does
B9: Five-year unlevered free cash flow DCF (FY2026E–FY2030E) with a Gordon terminal value and an exit-multiple cross-check.
B10: Relative valuation on EV/EBITDA and P/E for Microsoft, Alphabet and Meta.
B11: Residual income model anchored on FY2025 book equity, as a check on terminal-value dependence.
B13: Key outputs (live links)
B14: DCF value per share ($) | C14: ='DCF Model'!E30 -> 119.00948
B15: Comparables, average ($) | C15: =Comps!E23 -> 206.6104
B16: Residual income ($) | C16: ='Residual Income'!E29 -> 91.029967
B17: Share price, 21 Aug 2026 ($) | C17: =Assumptions!C50 -> 258.63
B18: DCF upside / (downside) | C18: ='DCF Model'!E31 -> -0.53984657
B19: WACC | C19: =Assumptions!C44 -> 0.09866
B20: Market-implied perpetuity growth (reverse DCF) | C20: ='DCF Model'!E43 -> 0.07086836
B21: Terminal value share of DCF EV | C21: ='DCF Model'!E25 -> 0.87897286
B22: EV, exit-multiple method ($mn) | C22: ='DCF Model'!E37 -> 2700419.8
B23: Sensitivity check (should read OK) | C23: =Sensitivity!E13 -> 0
B25: Contents
B26: Assumptions | C26: Base-year actuals, forecast drivers, WACC inputs, equity bridge, share price
B27: DCF Model | C27: FCFF build, terminal value, equity bridge, exit-multiple cross-check, reverse DCF
B28: Comps | C28: Peer multiples applied to Amazon's FY2025 EBITDA and net income
B29: Residual Income | C29: Book equity plus PV of excess returns
B30: Sensitivity | C30: Value per share and upside across WACC and terminal growth
B31: Summary | C31: Triangulation: low / median / high and upside vs. price
B33: Colour code
B34: 1,234 Blue text: hard-coded input
B35: 1,234 Black text: formula
B36: 1,234 Green text: link to another sheet
B37: Shaded yellow: key assumption to flex
B38: Shaded green: key output
B40: Method notes and limitations
B41: • Heavy AI/data-centre capex (20% of revenue in year 1, stepping down to 11.5%) depresses near-term FCF; the terminal value is ~90% of EV, so the DCF is very sensitive to WACC and g.
B42: • The exit-multiple cross-check (15x EBITDA) implies roughly twice the Gordon EV: the market is pricing higher long-run cash generation than the base case.
B43: • End-of-year discounting from the valuation date; no stub-period adjustment for FY2026 cash flows already earned.
B44: • Debt excludes lease liabilities (lease costs are inside EBIT). Peer multiples are approximate.
B46: Review log (changes in this published version)
... B54: Sources
...

Sheet Assumptions
B2: AMAZON.COM, INC. (NASDAQ: AMZN) — DCF ASSUMPTIONS & DRIVERS
B3: All figures in US$ millions unless noted. Base year = FY2025 actuals (Form 10-K). Market data as of 21 Aug 2026.
B5: HISTORICAL / BASE YEAR (FY2025 actuals)
B6: Net sales (revenue) | E6: 716924
B7: Operating income (EBIT) | E7: 79975
B8: Cash flow from operations | E8: 139514
B9: Capital expenditures (net) | E9: 173030
B10: Depreciation & amortization | E10: 61844
B12: PROJECTION DRIVERS (Years 1–5, then terminal)
B13: Driver | C13: Value | D13: Unit/Note
B14: Revenue growth — Year 1 | C14: 0.13 | D14: % ; consensus ~11-15% guide
B15: Revenue growth — Year 2 | C15: 0.12 | D15: %
B16: Revenue growth — Year 3 | C16: 0.11 | D16: %
B17: Revenue growth — Year 4 | C17: 0.1 | D17: %
B18: Revenue growth — Year 5 | C18: 0.09 | D18: %
B19: EBIT margin — Year 1 | C19: 0.115 | D19: % ; expanding from 11.2%
B20: EBIT margin — Year 2 | C20: 0.12 | D20: %
B21: EBIT margin — Year 3 | C21: 0.125 | D21: %
B22: EBIT margin — Year 4 | C22: 0.13 | D22: %
B23: EBIT margin — Year 5 | C23: 0.135 | D23: %
B24: Tax rate (effective) | C24: 0.15 | D24: % ; 2025 Tax Act lowered cash taxes
B25: D&A as % of revenue | C25: 0.09 | D25: %
... B28: Chg. in NWC as % of ΔRevenue | C28: -0.02 | D28: % ; negative WC (float) is a source of cash
B30: WACC & TERMINAL VALUE INPUTS
B31: Input | C31: Value | D31: Note
B32: Risk-free rate | C32: 0.0474 | D32: US 10-yr Treasury (CMT) 4.74%, 21 Aug 2026
B33: Equity risk premium | C33: 0.05 | D33: Market ERP assumption
B34: Beta (levered) | C34: 1.15 | D34: AMZN ~1.1-1.2
B35: Pre-tax cost of debt | C35: 0.05 | D35: Blend of senior notes yield
B36: Weight of equity (E/V) | C36: 0.9 | D36: Market-cap heavy structure
B37: Weight of debt (D/V) | C37: 0.1 | D37: 1 - E/V
B38: Terminal growth rate (g) | C38: 0.035 | D38: Long-run nominal GDP-ish
B39: Exit EV/EBITDA (alt. TV method) | C39: 15 | D39: Cross-check multiple
B41: COST OF CAPITAL (computed)
B42: Cost of equity (Ke = Rf + β·ERP) | C42: =C32+C34*C33 -> 0.1049
B43: After-tax cost of debt (Kd·(1-t)) | C43: =C35*(1-C24) -> 0.0425
B44: WACC | C44: =C36*C42+C37*C43 -> 0.09866
B46: NET DEBT & SHARES (equity bridge)
B47: Total debt | C47: 89295 | D47: FY2025 long-term debt ~$89.3B, excl. lease liabilities (leases sit in EBIT)
B48: Cash, equiv. & marketable securities | C48: 123000 | D48: FY2025 ~$123.0B
...

Sheet DCF Model
B2: AMAZON — DISCOUNTED CASH FLOW (UNLEVERED FCF)
B3: US$ millions. FCFF = EBIT·(1-tax) + D&A − Capex − ΔNWC. Discounted at WACC.
B5: ($ millions) | C5: FY2025A | D5: FY2026E | E5: FY2027E | F5: FY2028E | G5: FY2029E | H5: FY2030E
B6: Revenue | C6: =Assumptions!$E$6 -> 716924 | D6: =C6*(1+Assumptions!$C$14) -> 810124.12 | E6: =D6*(1+Assumptions!$C$15) -> 907339.01 | F6: =E6*(1+Assumptions!$C$16) -> 1007146.3 | G6: =F6*(1+Assumptions!$C$17) -> 1107860.9 | H6: =G6*(1+Assumptions!$C$18) -> 1207568.4
B7: % growth | D7: =Assumptions!$C$14 -> 0.13 | E7: =Assumptions!$C$15 -> 0.12 | F7: =Assumptions!$C$16 -> 0.11 | G7: =Assumptions!$C$17 -> 0.1 | H7: =Assumptions!$C$18 -> 0.09
B8: EBIT (operating income) | C8: =Assumptions!$E$7 -> 79975 | D8: =D6*Assumptions!$C$19 -> 93164.274 | E8: =E6*Assumptions!$C$20 -> 108880.68 | F8: =F6*Assumptions!$C$21 -> 125893.29 | G8: =G6*Assumptions!$C$22 -> 144021.92 | H8: =H6*Assumptions!$C$23 -> 163021.74
B9: EBIT margin | C9: =C8/C6 -> 0.11155297 | D9: =Assumptions!$C$19 -> 0.115 | E9: =Assumptions!$C$20 -> 0.12 | F9: =Assumptions!$C$21 -> 0.125 | G9: =Assumptions!$C$22 -> 0.13 | H9: =Assumptions!$C$23 -> 0.135
B10: Less: taxes on EBIT | D10: =-D8*Assumptions!$C$24 -> -13974.641 | E10: =-E8*Assumptions!$C$24 -> -16332.102 | F10: =-F8*Assumptions!$C$24 -> -18883.993 | G10: =-G8*Assumptions!$C$24 -> -21603.288 | H10: =-H8*Assumptions!$C$24 -> -24453.261
B11: NOPAT (EBIT after tax) | D11: =D8+D10 -> 79189.633 | E11: =E8+E10 -> 92548.579 | F11: =F8+F10 -> 107009.3 | G11: =G8+G10 -> 122418.63 | H11: =H8+H10 -> 138568.48
B12: Add: depreciation & amortization | D12: =D6*Assumptions!$C$25 -> 72911.171 | E12: =E6*Assumptions!$C$25 -> 81660.511 | F12: =F6*Assumptions!$C$25 -> 90643.168 | G12: =G6*Assumptions!$C$25 -> 99707.484 | H12: =H6*Assumptions!$C$25 -> 108681.16
B13: Less: capital expenditures | D13: =-D6*(Assumptions!$C$26+(Assumptions!$C$27-Assumptions!$C$26)*(D16-1)/4) -> -162024.82 | E13: =-E6*(Assumptions!$C$26+(Assumptions!$C$27-Assumptions!$C$26)*(E16-1)/4) -> -162186.85 | F13: =-F6*(Assumptions!$C$26+(Assumptions!$C$27-Assumptions!$C$26)*(F16-1)/4) -> -158625.54 | G13: =-G6*(Assumptions!$C$26+(Assumptions!$C$27-Assumptions!$C$26)*(G16-1)/4) -> -150946.05 | H13: =-H6*(Assumptions!$C$26+(Assumptions!$C$27-Assumptions!$C$26)*(H16-1)/4) -> -138870.37
B14: Less: change in net working capital | D14: =-(D6-C6)*Assumptions!$C$28 -> 1864.0024 | E14: =-(E6-D6)*Assumptions!$C$28 -> 1944.2979 | F14: =-(F6-E6)*Assumptions!$C$28 -> 1996.1458 | G14: =-(G6-F6)*Assumptions!$C$28 -> 2014.2926 | H14: =-(H6-G6)*Assumptions!$C$28 -> 1994.1497
B15: Unlevered Free Cash Flow (FCFF) | D15: =D11+D12+D13+D14 -> -8060.0181 | E15: =E11+E12+E13+E14 -> 13966.54 | F15: =F11+F12+F13+F14 -> 41023.065 | G15: =G11+G12+G13+G14 -> 73194.358 | H15: =H11+H12+H13+H14 -> 110373.42
B16: Discount period (t) | D16: 1 | E16: 2 | F16: 3 | G16: 4 | H16: 5
B17: Discount factor 1/(1+WACC)^t | D17: =1/(1+Assumptions!$C$44)^D16 -> 0.9101997 | E17: =1/(1+Assumptions!$C$44)^E16 -> 0.82846349 | F17: =1/(1+Assumptions!$C$44)^F16 -> 0.75406722 | G17: =1/(1+Assumptions!$C$44)^G16 -> 0.68635175 | H17: =1/(1+Assumptions!$C$44)^H16 -> 0.62471716
B18: PV of FCFF | D18: =D15*D17 -> -7336.226 | E18: =E15*E17 -> 11570.768 | F18: =F15*F17 -> 30934.149 | G18: =G15*G17 -> 50237.076 | H18: =H15*H17 -> 68952.167
B20: TERMINAL VALUE & ENTERPRISE / EQUITY VALUE
B21: Sum of PV of explicit FCFF (Yr1–5) | E21: =SUM(D18:H18) -> 154357.93
B22: Terminal value (Gordon: FCFF₅·(1+g)/(WACC−g)) | E22: =H15*(1+Assumptions!$C$38)/(Assumptions!$C$44-Assumptions!$C$38) -> 1794478.2
B23: PV of terminal value | E23: =E22*H17 -> 1121041.4
B24: Enterprise Value (EV) | E24: =E21+E23 -> 1275399.3
B25: TV as % of EV | E25: =E23/E24 -> 0.87897286
B26: Less: total debt | E26: =-Assumptions!$C$47 -> -89295
B27: Add: cash & marketable securities | E27: =Assumptions!$C$48 -> 123000
B28: Equity Value (NPV to shareholders) | E28: =E24+E26+E27 -> 1309104.3
B29: Diluted shares outstanding (mm) | E29: =Assumptions!$C$49 -> 11000
B30: Implied value per share | E30: =E28/E29 -> 119.00948
B31: Upside / (downside) vs. share price | E31: =E30/Assumptions!$C$50-1 -> -0.53984657
B32: CROSS-CHECK — EXIT MULTIPLE TERMINAL VALUE
B33: Terminal EBITDA (Yr5 EBIT + D&A) | E33: =H8+H12 -> 271702.89
B34: × Exit EV/EBITDA multiple | E34: =Assumptions!$C$39 -> 15
B35: Terminal value (exit multiple) | E35: =E33*E34 -> 4075543.4
B36: PV of terminal value (exit) | E36: =E35*H17 -> 2546061.9
B37: Implied EV (exit-multiple method) | E37: =E21+E36 -> 2700419.8
B39: REVERSE DCF — WHAT THE SHARE PRICE IMPLIES
B40: Market enterprise value (price × shares + debt − cash) | E40: =Assumptions!$C$50*Assumptions!$C$49+Assumptions!$C$47-Assumptions!$C$48 -> 2811225
B41: Required PV of terminal value | E41: =E40-E21 -> 2656867.1
B42: Required terminal value at year 5 | E42: =E41/H17 -> 4252911.9
B43: Market-implied perpetuity growth (at this WACC) | E43: =(E42*Assumptions!$C$44-H15)/(E42+H15) -> 0.07086836
B44: Market-implied EV / year-5 EBITDA | E44: =E42/E33 -> 15.652803

Sheet Comps
B2: AMAZON — RELATIVE VALUATION (COMPARABLE COMPANIES)
B3: US$ millions except per-share/multiples. Peer multiples are approximate, as of Aug 2026 (inputs, blue); applied to Amazon's FY2025 metrics.
B5: PEER TRADING MULTIPLES (current, approx.)
B6: Peer | C6: EV/EBITDA | D6: EV/Sales | E6: P/E
B7: Microsoft (MSFT) | C7: 17.3 | D7: 10.5 | E7: 26.5
B8: Alphabet (GOOGL) | C8: 21.6 | D8: 9.8 | E8: 27.5
B9: Meta Platforms (META) | C9: 16 | D9: 8 | E9: 24
B10: Median (peer set) | C10: =MEDIAN(C7:C9) -> 17.3 | D10: =MEDIAN(D7:D9) -> 9.8 | E10: =MEDIAN(E7:E9) -> 26.5
B12: AMAZON FY2025 METRICS (applied)
B13: Metric | D13: Value
B14: EBITDA (EBIT + D&A) | D14: =Assumptions!$E$7+Assumptions!$E$10 -> 141819
B15: Revenue (net sales) | D15: =Assumptions!$E$6 -> 716924
B16: Net income (FY2025 actual) | D16: 77670
B18: IMPLIED VALUATION (peer median applied)
B19: Method | C19: Implied EV | D19: Implied Equity | E19: Per share
B20: EV/EBITDA | C20: =C10*D14 -> 2453468.7 | D20: =C20-Assumptions!$C$47+Assumptions!$C$48 -> 2487173.7 | E20: =D20/Assumptions!$C$49 -> 226.1067
B21: EV/Sales (excl. from avg — margin mismatch) | C21: =D10*D15 -> 7025855.2 | D21: =C21-Assumptions!$C$47+Assumptions!$C$48 -> 7059560.2 | E21: =D21/Assumptions!$C$49 -> 641.7782
B22: P/E (on net income) | C22: n/a | D22: =E10*D16 -> 2058255 | E22: =D22/Assumptions!$C$49 -> 187.11409
B23: Average implied value / share | E23: =AVERAGE(E20,E22) -> 206.6104
B25: Note: comps capture what the market pays TODAY for peer earnings/EBITDA. Amazon's depressed near-term FCF (heavy AI capex) hurts a DCF but not an EBITDA multiple, so comps typically read higher than the DCF.

Sheet Residual Income
B2: AMAZON — RESIDUAL INCOME (RI) VALUATION
B3: Equity value = Book value of equity + PV of future residual income. RI = Net income − (Cost of equity × Opening book equity).
B5: INPUTS
B6: Input | C6: Value | D6: Note
B7: Beginning book value of equity (FY2025) | C7: 411065 | D7: Total stockholders' equity, 31 Dec 2025 (Form 10-K)
B8: Net income — Year 1 | C8: 82000 | D8: ~FY2026E net income
B9: Net income growth (Yr2–5) | C9: 0.12 | D9: Assumed NI growth
B10: Dividend/buyback payout ratio | C10: 0.15 | D10: Share of NI returned; rest retained to book
B11: Terminal RI growth | C11: 0.03 | D11: Long-run residual income growth
B12: Cost of equity (Ke, from Assumptions) | C12: =Assumptions!$C$42 -> 0.1049 | D12: Rf + beta*ERP
B14: RESIDUAL INCOME PROJECTION
B15: ($ millions) | C15: Year 1 | D15: Year 2 | E15: Year 3 | F15: Year 4 | G15: Year 5
B16: Opening book equity | C16: =C7 -> 411065 | D16: =C20 -> 480765 | E16: =D20 -> 558829 | F16: =E20 -> 646260.68 | G16: =F20 -> 744184.16
B17: Net income | C17: =C8 -> 82000 | D17: =C17*(1+C9) -> 91840 | E17: =D17*(1+C9) -> 102860.8 | F17: =E17*(1+C9) -> 115204.1 | G17: =F17*(1+C9) -> 129028.59
B18: Less: equity charge (Ke × opening BV) | C18: =-C16*$C$12 -> -43120.719 | D18: =-D16*$C$12 -> -50432.249 | E18: =-E16*$C$12 -> -58621.162 | F18: =-F16*$C$12 -> -67792.745 | G18: =-G16*$C$12 -> -78064.919
B19: Residual income (RI) | C19: =C17+C18 -> 38879.281 | D19: =D17+D18 -> 41407.751 | E19: =E17+E18 -> 44239.638 | F19: =F17+F18 -> 47411.351 | G19: =G17+G18 -> 50963.669
B20: Closing book equity | C20: =C16+C17*(1-$C$10) -> 480765 | D20: =D16+D17*(1-$C$10) -> 558829 | E20: =E16+E17*(1-$C$10) -> 646260.68 | F20: =F16+F17*(1-$C$10) -> 744184.16 | G20: =G16+G17*(1-$C$10) -> 853858.46
B21: Discount factor 1/(1+Ke)^t | C21: =1/(1+$C$12)^1 -> 0.90505928 | D21: =1/(1+$C$12)^2 -> 0.8191323 | E21: =1/(1+$C$12)^3 -> 0.74136329 | F21: =1/(1+$C$12)^4 -> 0.67097773 | G21: =1/(1+$C$12)^5 -> 0.60727462
B22: PV of RI | C22: =C19*C21 -> 35188.055 | D22: =D19*D21 -> 33918.427 | E22: =E19*E21 -> 32797.644 | F22: =F19*F21 -> 31811.96 | G22: =G19*G21 -> 30948.943
B24: EQUITY VALUE BUILD
B25: Beginning book value of equity | E25: =C7 -> 411065
B26: Add: PV of explicit RI (Yr1–5) | E26: =SUM(C22:G22) -> 164665.03
B27: Add: PV of terminal RI (RI₅·(1+g)/(Ke−g), discounted) | E27: =(G19*(1+C11)/($C$12-C11))*G21 -> 425599.61
B28: Equity Value (RI method) | E28: =E25+E26+E27 -> 1001329.6
B29: Implied value per share | E29: =E28/Assumptions!$C$49 -> 91.029967
B31: Why RI helps: value is anchored on today's book equity, so far less of the answer sits in a distant terminal value than in the DCF (where TV was ~88% of EV). It's a useful check when capex/FCF timing distorts the DCF.

Sheet Sensitivity
B2: SENSITIVITY — IMPLIED VALUE / SHARE (WACC × Terminal growth)
B3: Value per share ($) re-running the DCF at each WACC (rows) and terminal growth (columns). Centre cell = base case. Steps are inputs.
B4: WACC step | C4: 0.005 | D4: g step | E4: 0.005
B6: WACC ↓ / g → | C6: =Assumptions!$C$38+(-2)*$E$4 -> 0.025 | D6: =Assumptions!$C$38+(-1)*$E$4 -> 0.03 | E6: =Assumptions!$C$38+(0)*$E$4 -> 0.035 | F6: =Assumptions!$C$38+(1)*$E$4 -> 0.04 | G6: =Assumptions!$C$38+(2)*$E$4 -> 0.045
B7: =Assumptions!$C$44+(-2)*$C$4 -> 0.08866 | C7: =(SUMPRODUCT('DCF Model'!$D$15:$H$15,(1+$B7)^(-'DCF Model'!$D$16:$H$16))+'DCF Model'!$H$15*(1+C$6)/($B7-C$6)*(1+$B7)^(-'DCF Model'!$H$16)-Assumptions!$C$47+Assumptions!$C$48)/Assumptions!$C$49 -> 123.30105 | D7: =(SUMPRODUCT('DCF Model'!$D$15:$H$15,(1+$B7)^(-'DCF Model'!$D$16:$H$16))+'DCF Model'!$H$15*(1+D$6)/($B7-D$6)*(1+$B7)^(-'DCF Model'!$H$16)-Assumptions!$C$47+Assumptions!$C$48)/Assumptions!$C$49 -> 132.86559 | E7: =(SUMPRODUCT('DCF Model'!$D$15:$H$15,(1+$B7)^(-'DCF Model'!$D$16:$H$16))+'DCF Model'!$H$15*(1+E$6)/($B7-E$6)*(1+$B7)^(-'DCF Model'!$H$16)-Assumptions!$C$47+Assumptions!$C$48)/Assumptions!$C$49 -> 144.21256 | F7: =(SUMPRODUCT('DCF Model'!$D$15:$H$15,(1+$B7)^(-'DCF Model'!$D$16:$H$16))+'DCF Model'!$H$15*(1+F$6)/($B7-F$6)*(1+$B7)^(-'DCF Model'!$H$16)-Assumptions!$C$47+Assumptions!$C$48)/Assumptions!$C$49 -> 157.89142 | G7: =(SUMPRODUCT('DCF Model'!$D$15:$H$15,(1+$B7)^(-'DCF Model'!$D$16:$H$16))+'DCF Model'!$H$15*(1+G$6)/($B7-G$6)*(1+$B7)^(-'DCF Model'!$H$16)-Assumptions!$C$47+Assumptions!$C$48)/Assumptions!$C$49 -> 174.70333
B8: =Assumptions!$C$44+(-1)*$C$4 -> 0.09366 | C8: =(SUMPRODUCT('DCF Model'!$D$15:$H$15,(1+$B8)^(-'DCF Model'!$D$16:$H$16))+'DCF Model'!$H$15*(1+C$6)/($B8-C$6)*(1+$B8)^(-'DCF Model'!$H$16)-Assumptions!$C$47+Assumptions!$C$48)/Assumptions!$C$49 -> 113.10776 | D8: =(SUMPRODUCT('DCF Model'!$D$15:$H$15,(1+$B8)^(-'DCF Model'!$D$16:$H$16))+'DCF Model'!$H$15*(1+D$6)/($B8-D$6)*(1+$B8)^(-'DCF Model'!$H$16)-Assumptions!$C$47+Assumptions!$C$48)/Assumptions!$C$49 -> 121.13085 | E8: =(SUMPRODUCT('DCF Model'!$D$15:$H$15,(1+$B8)^(-'DCF Model'!$D$16:$H$16))+'DCF Model'!$H$15*(1+E$6)/($B8-E$6)*(1+$B8)^(-'DCF Model'!$H$16)-Assumptions!$C$47+Assumptions!$C$48)/Assumptions!$C$49 -> 130.52168 | F8: =(SUMPRODUCT('DCF Model'!$D$15:$H$15,(1+$B8)^(-'DCF Model'!$D$16:$H$16))+'DCF Model'!$H$15*(1+F$6)/($B8-F$6)*(1+$B8)^(-'DCF Model'!$H$16)-Assumptions!$C$47+Assumptions!$C$48)/Assumptions!$C$49 -> 141.66257 | G8: =(SUMPRODUCT('DCF Model'!$D$15:$H$15,(1+$B8)^(-'DCF Model'!$D$16:$H$16))+'DCF Model'!$H$15*(1+G$6)/($B8-G$6)*(1+$B8)^(-'DCF Model'!$H$16)-Assumptions!$C$47+Assumptions!$C$48)/Assumptions!$C$49 -> 155.09299
B9: =Assumptions!$C$44+(0)*$C$4 -> 0.09866 | C9: =(SUMPRODUCT('DCF Model'!$D$15:$H$15,(1+$B9)^(-'DCF Model'!$D$16:$H$16))+'DCF Model'!$H$15*(1+C$6)/($B9-C$6)*(1+$B9)^(-'DCF Model'!$H$16)-Assumptions!$C$47+Assumptions!$C$48)/Assumptions!$C$49 -> 104.32292 | D9: =(SUMPRODUCT('DCF Model'!$D$15:$H$15,(1+$B9)^(-'DCF Model'!$D$16:$H$16))+'DCF Model'!$H$15*(1+D$6)/($B9-D$6)*(1+$B9)^(-'DCF Model'!$H$16)-Assumptions!$C$47+Assumptions!$C$48)/Assumptions!$C$49 -> 111.13144 | E9: =(SUMPRODUCT('DCF Model'!$D$15:$H$15,(1+$B9)^(-'DCF Model'!$D$16:$H$16))+'DCF Model'!$H$15*(1+E$6)/($B9-E$6)*(1+$B9)^(-'DCF Model'!$H$16)-Assumptions!$C$47+Assumptions!$C$48)/Assumptions!$C$49 -> 119.00948 | F9: =(SUMPRODUCT('DCF Model'!$D$15:$H$15,(1+$B9)^(-'DCF Model'!$D$16:$H$16))+'DCF Model'!$H$15*(1+F$6)/($B9-F$6)*(1+$B9)^(-'DCF Model'!$H$16)-Assumptions!$C$47+Assumptions!$C$48)/Assumptions!$C$49 -> 128.23052 | G9: =(SUMPRODUCT('DCF Model'!$D$15:$H$15,(1+$B9)^(-'DCF Model'!$D$16:$H$16))+'DCF Model'!$H$15*(1+G$6)/($B9-G$6)*(1+$B9)^(-'DCF Model'!$H$16)-Assumptions!$C$47+Assumptions!$C$48)/Assumptions!$C$49 -> 139.16998
B10: =Assumptions!$C$44+(1)*$C$4 -> 0.10366 | C10: =(SUMPRODUCT('DCF Model'!$D$15:$H$15,(1+$B10)^(-'DCF Model'!$D$16:$H$16))+'DCF Model'!$H$15*(1+C$6)/($B10-C$6)*(1+$B10)^(-'DCF Model'!$H$16)-Assumptions!$C$47+Assumptions!$C$48)/Assumptions!$C$49 -> 96.677398 | D10: =(SUMPRODUCT('DCF Model'!$D$15:$H$15,(1+$B10)^(-'DCF Model'!$D$16:$H$16))+'DCF Model'!$H$15*(1+D$6)/($B10-D$6)*(1+$B10)^(-'DCF Model'!$H$16)-Assumptions!$C$47+Assumptions!$C$48)/Assumptions!$C$49 -> 102.51339 | E10: =(SUMPRODUCT('DCF Model'!$D$15:$H$15,(1+$B10)^(-'DCF Model'!$D$16:$H$16))+'DCF Model'!$H$15*(1+E$6)/($B10-E$6)*(1+$B10)^(-'DCF Model'!$H$16)-Assumptions!$C$47+Assumptions!$C$48)/Assumptions!$C$49 -> 109.19937 | F10: =(SUMPRODUCT('DCF Model'!$D$15:$H$15,(1+$B10)^(-'DCF Model'!$D$16:$H$16))+'DCF Model'!$H$15*(1+F$6)/($B10-F$6)*(1+$B10)^(-'DCF Model'!$H$16)-Assumptions!$C$47+Assumptions!$C$48)/Assumptions!$C$49 -> 116.93562 | G10: =(SUMPRODUCT('DCF Model'!$D$15:$H$15,(1+$B10)^(-'DCF Model'!$D$16:$H$16))+'DCF Model'!$H$15*(1+G$6)/($B10-G$6)*(1+$B10)^(-'DCF Model'!$H$16)-Assumptions!$C$47+Assumptions!$C$48)/Assumptions!$C$49 -> 125.99069
B11: =Assumptions!$C$44+(2)*$C$4 -> 0.10866 | C11: =(SUMPRODUCT('DCF Model'!$D$15:$H$15,(1+$B11)^(-'DCF Model'!$D$16:$H$16))+'DCF Model'!$H$15*(1+C$6)/($B11-C$6)*(1+$B11)^(-'DCF Model'!$H$16)-Assumptions!$C$47+Assumptions!$C$48)/Assumptions!$C$49 -> 89.966421 | D11: =(SUMPRODUCT('DCF Model'!$D$15:$H$15,(1+$B11)^(-'DCF Model'!$D$16:$H$16))+'DCF Model'!$H$15*(1+D$6)/($B11-D$6)*(1+$B11)^(-'DCF Model'!$H$16)-Assumptions!$C$47+Assumptions!$C$48)/Assumptions!$C$49 -> 95.012761 | E11: =(SUMPRODUCT('DCF Model'!$D$15:$H$15,(1+$B11)^(-'DCF Model'!$D$16:$H$16))+'DCF Model'!$H$15*(1+E$6)/($B11-E$6)*(1+$B11)^(-'DCF Model'!$H$16)-Assumptions!$C$47+Assumptions!$C$48)/Assumptions!$C$49 -> 100.74419 | F11: =(SUMPRODUCT('DCF Model'!$D$15:$H$15,(1+$B11)^(-'DCF Model'!$D$16:$H$16))+'DCF Model'!$H$15*(1+F$6)/($B11-F$6)*(1+$B11)^(-'DCF Model'!$H$16)-Assumptions!$C$47+Assumptions!$C$48)/Assumptions!$C$49 -> 107.31037 | G11: =(SUMPRODUCT('DCF Model'!$D$15:$H$15,(1+$B11)^(-'DCF Model'!$D$16:$H$16))+'DCF Model'!$H$15*(1+G$6)/($B11-G$6)*(1+$B11)^(-'DCF Model'!$H$16)-Assumptions!$C$47+Assumptions!$C$48)/Assumptions!$C$49 -> 114.90799
B13: Check: centre cell − DCF value per share | E13: =E9-'DCF Model'!E30 -> 0
B15: Upside / (downside) vs. share price
B16: WACC ↓ / g → | C16: =C6 -> 0.025 | D16: =D6 -> 0.03 | E16: =E6 -> 0.035 | F16: =F6 -> 0.04 | G16: =G6 -> 0.045
B17: =B7 -> 0.08866 | C17: =C7/Assumptions!$C$50-1 -> -0.52325311 | D17: =D7/Assumptions!$C$50-1 -> -0.48627156 | E17: =E7/Assumptions!$C$50-1 -> -0.44239817 | F17: =F7/Assumptions!$C$50-1 -> -0.38950848 | G17: =G7/Assumptions!$C$50-1 -> -0.32450479
B18: =B8 -> 0.09366 | C18: =C8/Assumptions!$C$50-1 -> -0.56266576 | D18: =D8/Assumptions!$C$50-1 -> -0.53164423 | E18: =E8/Assumptions!$C$50-1 -> -0.49533434 | F18: =F8/Assumptions!$C$50-1 -> -0.4522578 | G18: =G8/Assumptions!$C$50-1 -> -0.4003287
B19: =B9 -> 0.09866 | C19: =C9/Assumptions!$C$50-1 -> -0.59663258 | D19: =D9/Assumptions!$C$50-1 -> -0.57030723 | E19: =E9/Assumptions!$C$50-1 -> -0.53984657 | F19: =F9/Assumptions!$C$50-1 -> -0.50419317 | G19: =G9/Assumptions!$C$50-1 -> -0.46189546
B20: =B10 -> 0.10366 | C20: =C10/Assumptions!$C$50-1 -> -0.62619418 | D20: =D10/Assumptions!$C$50-1 -> -0.60362915 | E20: =E10/Assumptions!$C$50-1 -> -0.57777762 | F20: =F10/Assumptions!$C$50-1 -> -0.54786522 | G20: =G10/Assumptions!$C$50-1 -> -0.51285354
B21: =B11 -> 0.10866 | C21: =C11/Assumptions!$C$50-1 -> -0.65214236 | D21: =D11/Assumptions!$C$50-1 -> -0.63263055 | E21: =E11/Assumptions!$C$50-1 -> -0.61046984 | F21: =F11/Assumptions!$C$50-1 -> -0.58508152 | G21: =G11/Assumptions!$C$50-1 -> -0.5557051

Sheet Summary
B2: AMAZON — VALUATION SUMMARY (TRIANGULATION)
B3: Implied value per share by method. No single number is 'right' — the range is the finding.
B5: Method | C5: Implied value / share | D5: Anchored on | E5: vs. price
B6: DCF (Gordon growth terminal) | C6: ='DCF Model'!$E$30 -> 119.00948 | D6: Future unlevered cash flows | E6: =C6/Assumptions!$C$50-1 -> -0.53984657
B7: Comparable companies (avg) | C7: =Comps!$E$23 -> 206.6104 | D7: Peer trading multiples | E7: =C7/Assumptions!$C$50-1 -> -0.20113523
B8: Residual income | C8: ='Residual Income'!$E$29 -> 91.029967 | D8: Book equity + excess returns | E8: =C8/Assumptions!$C$50-1 -> -0.64803013
B9: Low | C9: =MIN(C6:C8) -> 91.029967 | E9: =C9/Assumptions!$C$50-1 -> -0.64803013
B10: Median | C10: =MEDIAN(C6:C8) -> 119.00948 | E10: =C10/Assumptions!$C$50-1 -> -0.53984657
B11: High | C11: =MAX(C6:C8) -> 206.6104 | E11: =C11/Assumptions!$C$50-1 -> -0.20113523
B12: Share price, 21 Aug 2026 | C12: =Assumptions!$C$50 -> 258.63
B13: Interpretation: DCF is the intrinsic anchor but leans heavily on terminal assumptions and near-term capex. Comps reflect what the market pays today for peers. Residual income reduces terminal-value dependence. A wide spread signals the valuation is sensitive to which lens you trust — tighten the blue inputs to narrow it.
