Workbook

Sheet Cover
B1: Rubrik, Inc. (NYSE: RBRK) — equity valuation
B2: Ten-year unlevered DCF with Base / Bull / Bear scenarios, EV / NTM revenue bands and a reverse DCF. Not investment advice.
B4: Prepared by | C4: Jung Ryul Lee (valuation). Originally prepared for a team project; this version is my rebuild.
B5: Data as of | C5: Valuation date 24 Apr 2026: share price 23 Apr 2026; FY2026 results and FY2027 guidance (8-K, 12 Mar 2026)
B6: Units | C6: US$ millions except per share
B8: What this model does
B9: Rubrik sells data-security and backup software by subscription. Revenue grew 48% in FY2026 to $1.3bn and the company is free-cash-flow positive because customers pay upfront, but GAAP operating losses remain.
B10: The DCF treats stock-based compensation as a real cost and runs ten years so growth can fade before the terminal value.
B11: FY2027E is pinned to company guidance; the check on the DCF sheet confirms FY2027E free cash flow matches guidance.
B13: Key outputs (live links)
B14: Scenario | C14: =scen_name -> Base
B15: DCF value per share ($) | C15: =vps -> 21.747566
B16: Share price, 23 Apr 2026 ($) | C16: =price -> 54.02
B17: Upside / (downside) | C17: =upside -> -0.59741641
B18: DCF value per share, SBC added back ($) | C18: =vps_ab -> 40.19374
B19: WACC | C19: =wacc -> 0.11884175
B20: Current EV / NTM revenue | C20: =mkt_ev_ntm -> 7.4828589
B21: Market-implied long-run margin excl. SBC | C21: =Sensitivity!C26 -> 0.59593122
B22: FY2027E FCF vs. guidance | C22: =DCF!F30 -> Within $25mn
B23: Sensitivity check | C23: =chk_sens -> 0
B25: Contents
B26: Summary | C26: Headline outputs, football field, revenue and margin chart
B27: Inputs | C27: Scenario switch, market data, guidance, forecast drivers, multiple bands
B28: Historical | C28: FY2025A–FY2026A GAAP financials and ratios
B29: DCF | C29: Projection, FY2027 guidance check, WACC, valuation bridge, reverse DCF
B30: Sensitivity | C30: Value per share across long-run margin, WACC and terminal growth
B31: Multiples | C31: EV / NTM revenue bands applied to FY2027E revenue
B33: Colour code
B34: 1,234 Blue text: hard-coded input
B35: 1,234 Black text: formula
B36: 1,234 Green text: link to another sheet
B37: Shaded yellow: key assumption to flex
B38: Shaded green: key output
B40: Method notes and limitations
B41: • Diluted shares use the ~232mn FY2027 guidance figure (RSUs and options); the convertible notes are treated as debt.
B42: • Cash taxes ignore Rubrik's net operating losses, which understates value slightly.
B43: • Beta of 1.5 is a team input; RBRK's trading history is short, so the cost of equity is uncertain (see Sensitivity).
B44: • Peer multiples came from a licensed Bloomberg screen and are not reproduced; the bands on Inputs are our judgement.
B46: Review log (changes in this published version)
... B54: Sources
...

Sheet Summary
B1: Rubrik, Inc. (NYSE: RBRK) — valuation summary
B2: Valuation date 24 Apr 2026. US$ unless noted. Scenario shown is the live scenario on Inputs.
B4: Headline
B5: Scenario | C5: =scen_name -> Base
B6: DCF value per share ($) | C6: =vps -> 21.747566
B7: DCF value per share, SBC added back ($) | C7: =vps_ab -> 40.19374
B8: Share price, 23 Apr 2026 ($) | C8: =price -> 54.02
B9: Upside / (downside) | C9: =upside -> -0.59741641
B10: WACC | C10: =wacc -> 0.11884175
B11: Current EV / NTM revenue | C11: =mkt_ev_ntm -> 7.4828589
B12: Market-implied long-run margin excl. SBC | C12: =Sensitivity!C26 -> 0.59593122
B13: Model long-run margin excl. SBC (live) | C13: =m_lr -> 0.28
B14: FY2027E FCF check vs. guidance | C14: =DCF!F30 -> Within $25mn
B15: Sensitivity check | C15: =chk_sens -> 0
B17: Valuation range ($ per share): football field
B18: Method | C18: Low | D18: High | F18: Width
B19: DCF: long-run margin ±4pts (base WACC) | C19: =MIN(Sensitivity!E10:E14) -> 13.545845 | D19: =MAX(Sensitivity!E10:E14) -> 29.899806 | F19: =MAX(D19-C19,0.6) -> 16.353961
B20: DCF: WACC ±1pt (base margin) | C20: =MIN(Sensitivity!C12:G12) -> 16.84835 | D20: =MAX(Sensitivity!C12:G12) -> 29.897449 | F20: =MAX(D20-C20,0.6) -> 13.049099
B21: DCF: terminal growth ±1pt (base WACC) | C21: =MIN(Sensitivity!E30:E34) -> 20.282024 | D21: =MAX(Sensitivity!E30:E34) -> 23.610048 | F21: =MAX(D21-C21,0.6) -> 3.3280242
B22: DCF: SBC as a cost vs. SBC added back | C22: =vps -> 21.747566 | D22: =vps_ab -> 40.19374 | F22: =MAX(D22-C22,0.6) -> 18.446174
B23: EV / NTM revenue, Low to High band | C23: =Multiples!H10 -> 43.780603 | D23: =Multiples!H12 -> 85.211638 | F23: =MAX(D23-C23,0.6) -> 41.431034
B24: Share price, 23 Apr 2026 | C24: =price -> 54.02 | D24: =price -> 54.02 | F24: =MAX(D24-C24,0.6) -> 0.6
B41: Revenue and cash-flow margin, live scenario
B42: Year | C42: Revenue ($mn) | D42: UFCF margin | F42: Op. margin excl. SBC
B43: FY2027E | C43: =DCF!D7 -> 1602 | D43: =DCF!D21 -> -0.088639201 | F43: =DCF!D9 -> 0.06
B44: FY2028E | C44: =DCF!E7 -> 1922.4 | D44: =DCF!E21 -> -0.036666667 | F44: =DCF!E9 -> 0.096666667
B45: FY2029E | C45: =DCF!F7 -> 2268.432 | D45: =DCF!F21 -> 0.014350282 | F45: =DCF!F9 -> 0.13333333
B46: FY2030E | C46: =DCF!G7 -> 2631.3811 | D46: =DCF!G21 -> 0.063072414 | F46: =DCF!G9 -> 0.17
B47: FY2031E | C47: =DCF!H7 -> 2999.7745 | D47: =DCF!H21 -> 0.10178947 | F47: =DCF!H9 -> 0.20666667
B48: FY2032E | C48: =DCF!I7 -> 3359.7474 | D48: =DCF!I21 -> 0.14029048 | F48: =DCF!I9 -> 0.24333333
B49: FY2033E | C49: =DCF!J7 -> 3695.7222 | D49: =DCF!J21 -> 0.17856364 | F49: =DCF!J9 -> 0.28
B50: FY2034E | C50: =DCF!K7 -> 3991.3799 | D50: =DCF!K21 -> 0.17182963 | F50: =DCF!K9 -> 0.28
B51: FY2035E | C51: =DCF!L7 -> 4230.8627 | D51: =DCF!L21 -> 0.16484151 | F51: =DCF!L9 -> 0.28
B52: FY2036E | C52: =DCF!M7 -> 4442.4059 | D52: =DCF!M21 -> 0.16124762 | F52: =DCF!M9 -> 0.28
B71: Reading the result
B72: ="At the April 2026 price the market pays "&TEXT(mkt_ev_ntm,"0.0")&"x NTM revenue, which at this WACC needs a long-run margin excl. SBC of about "&TEXT(Sensitivity!C26,"0%")&" (model: "&TEXT(m_lr,"0%")&")." -> At the April 2026 price the market pays 7.5x NTM revenue, which at this WACC needs a long-run margin excl. SBC of about 60% (model: 28%).
B73: ="Treating SBC as a cost matters: adding it back, as many sell-side models do, lifts the DCF from $"&TEXT(vps,"0")&" to $"&TEXT(vps_ab,"0")&" per share." -> Treating SBC as a cost matters: adding it back, as many sell-side models do, lifts the DCF from $22 to $40 per share.
B74: Most of the gap to the price is the cost of capital (beta 1.5) and the long-run margin; see the Sensitivity sheet.
B75: Upside case: subscription ARR keeps compounding above 20% and SBC falls toward 8% of revenue.
B76: Risks: competition from Cohesity/Veritas, a high beta (short trading history), dilution from SBC and the convertible.

Sheet Inputs
B1: Inputs
B2: Blue = hard-coded input. Shaded = assumption to flex. Everything else in the workbook is a formula on this sheet.
B4: Scenario
B5: Scenario (1 = Base, 2 = Bull, 3 = Bear) | C5: 1 | D5: =CHOOSE(scen,"Base","Bull","Bear") -> Base
B7: Market data and capital structure
B8: Valuation date | C8: 46136 | N8: Project date
B9: Share price ($) | C9: 54.02 | N9: NYSE close, 23 Apr 2026
B10: Diluted shares (mn) | C10: 232 | N10: FY2027 guided weighted-average diluted shares (~232mn), 8-K 12 Mar 2026
B11: Cash and short-term investments ($mn) | C11: 1675.8 | N11: 31 Jan 2026: cash 380.2 + short-term investments 1,295.6
B12: Convertible senior notes ($mn) | C12: 1130.7 | N12: 31 Jan 2026, net carrying amount
B13: Risk-free rate (10-yr UST) | C13: 0.0435 | N13: Approx., Apr 2026 (team input)
B14: Equity beta | C14: 1.5 | N14: Team input; RBRK listed Apr 2024, so the beta history is short
B15: Equity risk premium | C15: 0.055 | N15: Team input
B16: Pre-tax cost of debt | C16: 0.05 | N16: Team input; economic cost of the convertible (coupon is low)
B17: Tax rate for WACC | C17: 0.21 | N17: US federal statutory
B18: Terminal growth rate | C18: 0.035 | N18: Team used 4.0%; 3.5% keeps it in line with the other US models in this repo
B19: Net interest income FY2027E ($mn) | C19: 50 | N19: Approx. yield on cash less convertible coupon; used only to reconcile to FCF guidance
B21: FY2027 guidance (8-K, 12 Mar 2026)
C22: Low | D22: High | E22: Mid
B23: Revenue ($mn) | C23: 1597 | D23: 1607 | E23: =AVERAGE(C23:D23) -> 1602
B24: Subscription ARR ($mn) | C24: 1829 | D24: 1839 | E24: =AVERAGE(C24:D24) -> 1834
B25: Free cash flow ($mn) | C25: 265 | D25: 275 | E25: =AVERAGE(C25:D25) -> 270
B27: Forecast drivers (fiscal years end 31 January)
B28: Revenue growth | D28: FY2027E | E28: FY2028E | F28: FY2029E | G28: FY2030E | H28: FY2031E | I28: FY2032E | J28: FY2033E | K28: FY2034E | L28: FY2035E | M28: FY2036E | N28: Rationale
B29: Base | D29: =gd_rev/Hist_rev26-1 -> 0.21714025 | E29: 0.2 | F29: 0.18 | G29: 0.16 | H29: 0.14 | I29: 0.12 | J29: 0.1 | K29: 0.08 | L29: 0.06 | M29: 0.05 | N29: FY2027 = guidance midpoint (+21.7%); fades as ARR growth (+25% guided) decelerates
B30: Bull | D30: 0.23 | E30: 0.23 | F30: 0.21 | G30: 0.19 | H30: 0.17 | I30: 0.15 | J30: 0.12 | K30: 0.1 | L30: 0.08 | M30: 0.06 | N30: Data-security platform consolidation keeps growth above 20% for two more years
B31: Bear | D31: 0.2 | E31: 0.16 | F31: 0.13 | G31: 0.11 | H31: 0.09 | I31: 0.08 | J31: 0.07 | K31: 0.06 | L31: 0.05 | M31: 0.04 | N31: Low end of guidance, then faster fade toward market growth
B32: Live | D32: =CHOOSE(scen,D29,D30,D31) -> 0.21714025 | E32: =CHOOSE(scen,E29,E30,E31) -> 0.2 | F32: =CHOOSE(scen,F29,F30,F31) -> 0.18 | G32: =CHOOSE(scen,G29,G30,G31) -> 0.16 | H32: =CHOOSE(scen,H29,H30,H31) -> 0.14 | I32: =CHOOSE(scen,I29,I30,I31) -> 0.12 | J32: =CHOOSE(scen,J29,J30,J31) -> 0.1 | K32: =CHOOSE(scen,K29,K30,K31) -> 0.08 | ... M32: =CHOOSE(scen,M29,M30,M31) -> 0.05
B34: Margins and cash conversion | C34: Base | D34: Bull | E34: Bear | F34: Live
B35: Operating margin excl. SBC, FY2027E | C35: 0.06 | D35: 0.06 | E35: 0.06 | F35: =CHOOSE(scen,C35,D35,E35) -> 0.06 | N35: Calibrated so FY2027E FCF matches guidance (check on DCF sheet)
B36: Operating margin excl. SBC, long run (reached FY2033E) | C36: 0.28 | D36: 0.33 | E36: 0.22 | F36: =CHOOSE(scen,C36,D36,E36) -> 0.28 | N36: Scaled security software: CrowdStrike / Palo Alto guide to high-20s to 30s
B37: Stock-based compensation, % revenue, FY2027E | C37: 0.22 | D37: 0.22 | E37: 0.22 | F37: =CHOOSE(scen,C37,D37,E37) -> 0.22 | N37: FY2026A 25.0%, FY2025A 103% (IPO vesting)
B38: Stock-based compensation, % revenue, long run | C38: 0.1 | D38: 0.08 | E38: 0.12 | F38: =CHOOSE(scen,C38,D38,E38) -> 0.1 | N38: Mature software peers 8-12%
B39: D&A, % revenue | C39: 0.03 | D39: 0.03 | E39: 0.03 | F39: =CHOOSE(scen,C39,D39,E39) -> 0.03 | N39: FY2026A 2.8%
B40: Capex, % revenue | C40: 0.03 | D40: 0.03 | E40: 0.03 | F40: =CHOOSE(scen,C40,D40,E40) -> 0.03 | N40: FY2026A 2.2%; set equal to D&A in steady state
B41: Cash from working capital, % of revenue increase | C41: 0.4 | D41: 0.4 | E41: 0.4 | F41: =CHOOSE(scen,C41,D41,E41) -> 0.4 | N41: FY2026A ~43%: customers pay upfront, so deferred revenue funds growth
B42: Cash tax rate on positive GAAP operating profit | C42: 0.21 | D42: 0.21 | E42: 0.21 | F42: =CHOOSE(scen,C42,D42,E42) -> 0.21 | N42: NOLs ignored (conservative)
B43: Years to reach the long-run margin and SBC (from FY2027E) | C43: 6
B45: Trading multiples: EV / NTM revenue bands (team assumptions)
B46: Band | C46: Multiple | N46: Rationale
...

Sheet Historical
B1: Historical financials
B2: US$ millions. GAAP, fiscal years end 31 January. Source: Rubrik 8-K Ex. 99.1, 12 Mar 2026.
B4: US$ mn | C4: FY2025A | D4: FY2026A | E4: Change
B5: Total revenue | C5: 886.5 | D5: 1316.2 | E5: =IF(C5>0,D5/C5-1,"n/m") -> 0.48471517
B6: Subscription revenue | C6: 828.7 | D6: 1263.9 | E6: =IF(C6>0,D6/C6-1,"n/m") -> 0.52515989
B7: Subscription ARR (year end) | C7: 1092.6 | D7: 1462.1 | E7: =IF(C7>0,D7/C7-1,"n/m") -> 0.33818415
B8: Gross profit | C8: 620.8 | D8: 1054.3 | E8: =IF(C8>0,D8/C8-1,"n/m") -> 0.69829253
B9: Research & development | C9: 531.6 | D9: 373.7 | E9: =IF(C9>0,D9/C9-1,"n/m") -> -0.29702784
B10: Sales & marketing | C10: 867.5 | D10: 769 | E10: =IF(C10>0,D10/C10-1,"n/m") -> -0.11354467
B11: General & administrative | C11: 355.7 | D11: 257 | E11: =IF(C11>0,D11/C11-1,"n/m") -> -0.27748102
B12: GAAP operating income / (loss) | C12: -1134 | D12: -345.4 | E12: =IF(C12>0,D12/C12-1,"n/m") -> n/m
B13: Stock-based compensation | C13: 913.9 | D13: 329.4 | E13: =IF(C13>0,D13/C13-1,"n/m") -> -0.63956669
B14: Depreciation & amortization | C14: 28.9 | D14: 37.1 | E14: =IF(C14>0,D14/C14-1,"n/m") -> 0.28373702
B15: Capital expenditure | C15: 16.9 | D15: 29.6 | E15: =IF(C15>0,D15/C15-1,"n/m") -> 0.75147929
B16: Cash from operations | C16: 48.2 | D16: 282.9 | E16: =IF(C16>0,D16/C16-1,"n/m") -> 4.8692946
B17: Free cash flow (company definition, before SBC) | C17: 21.6 | D17: 237.8 | E17: =IF(C17>0,D17/C17-1,"n/m") -> 10.009259
B19: Ratios
C20: FY2025A | D20: FY2026A
B21: Revenue growth | D21: =D5/C5-1 -> 0.48471517
B22: Subscription ARR growth | D22: =D7/C7-1 -> 0.33818415
B23: Gross margin | C23: =C8/C5 -> 0.70028201 | D23: =D8/D5 -> 0.80101808
B24: R&D % revenue | C24: =C9/C5 -> 0.59966159 | D24: =D9/D5 -> 0.28392342
B25: S&M % revenue | C25: =C10/C5 -> 0.9785674 | D25: =D10/D5 -> 0.58425771
B26: G&A % revenue | C26: =C11/C5 -> 0.40124083 | D26: =D11/D5 -> 0.19525908
B27: GAAP operating margin | C27: =C12/C5 -> -1.2791878 | D27: =D12/D5 -> -0.26242212 | F27: FY2025 includes ~$0.6bn of IPO-related RSU expense
B28: SBC % revenue | C28: =C13/C5 -> 1.0309081 | D28: =D13/D5 -> 0.25026592
B29: Operating margin excl. SBC | C29: =(C12+C13)/C5 -> -0.24827975 | D29: =(D12+D13)/D5 -> -0.012156207
B30: FCF margin (company definition) | C30: =C17/C5 -> 0.024365482 | D30: =D17/D5 -> 0.18067163
B31: FCF margin after SBC | C31: =(C17-C13)/C5 -> -1.0065426 | D31: =(D17-D13)/D5 -> -0.069594287
B32: Rule of 40 (revenue growth + FCF margin) | D32: =D21+D30 -> 0.6653868
B33: Cash from working capital, % of revenue increase (approx.) | D33: =(D17-int_inc-(D12+D13)-D14+D15)/(D5-C5) -> 0.45683035 | F33: FCF less interest income, less EBIT excl. SBC and D&A, plus capex; uses the FY2027E interest input as a proxy

Sheet DCF
B1: Unlevered free cash flow DCF
B2: US$ millions except per share. SBC is treated as a cash-equivalent cost. Mid-year discounting from the valuation date.
B4: US$ mn | C4: FY2026A | D4: FY2027E | E4: FY2028E | F4: FY2029E | G4: FY2030E | H4: FY2031E | I4: FY2032E | J4: FY2033E | K4: FY2034E | L4: FY2035E | M4: FY2036E
B5: Fiscal year end | C5: 46053 | D5: 46418 | E5: 46783 | F5: 47149 | G5: 47514 | H5: 47879 | I5: 48244 | J5: 48610 | K5: 48975 | L5: 49340 | M5: 49705
B6: Year index | D6: 1 | E6: 2 | F6: 3 | G6: 4 | H6: 5 | I6: 6 | J6: 7 | K6: 8 | L6: 9 | M6: 10
B7: Revenue | C7: =Hist_rev26 -> 1316.2 | D7: =C7*(1+D8) -> 1602 | E7: =D7*(1+E8) -> 1922.4 | F7: =E7*(1+F8) -> 2268.432 | G7: =F7*(1+G8) -> 2631.3811 | H7: =G7*(1+H8) -> 2999.7745 | I7: =H7*(1+I8) -> 3359.7474 | J7: =I7*(1+J8) -> 3695.7222 | K7: =J7*(1+K8) -> 3991.3799 | ... M7: =L7*(1+M8) -> 4442.4059
B8: Growth | C8: =Historical!D21 -> 0.48471517 | D8: =Inputs!D32 -> 0.21714025 | E8: =Inputs!E32 -> 0.2 | F8: =Inputs!F32 -> 0.18 | G8: =Inputs!G32 -> 0.16 | H8: =Inputs!H32 -> 0.14 | I8: =Inputs!I32 -> 0.12 | J8: =Inputs!J32 -> 0.1 | K8: =Inputs!K32 -> 0.08 | ... M8: =Inputs!M32 -> 0.05
B9: Operating margin excl. SBC | C9: =Historical!D29 -> -0.012156207 | D9: =m27+(m_lr-m27)*MIN(1,(D$6-1)/ramp) -> 0.06 | E9: =m27+(m_lr-m27)*MIN(1,(E$6-1)/ramp) -> 0.096666667 | F9: =m27+(m_lr-m27)*MIN(1,(F$6-1)/ramp) -> 0.13333333 | G9: =m27+(m_lr-m27)*MIN(1,(G$6-1)/ramp) -> 0.17 | H9: =m27+(m_lr-m27)*MIN(1,(H$6-1)/ramp) -> 0.20666667 | I9: =m27+(m_lr-m27)*MIN(1,(I$6-1)/ramp) -> 0.24333333 | J9: =m27+(m_lr-m27)*MIN(1,(J$6-1)/ramp) -> 0.28 | K9: =m27+(m_lr-m27)*MIN(1,(K$6-1)/ramp) -> 0.28 | ... M9: =m27+(m_lr-m27)*MIN(1,(M$6-1)/ramp) -> 0.28
B10: Operating profit excl. SBC | D10: =D7*D9 -> 96.12 | E10: =E7*E9 -> 185.832 | F10: =F7*F9 -> 302.4576 | G10: =G7*G9 -> 447.33479 | H10: =H7*H9 -> 619.95339 | I10: =I7*I9 -> 817.53854 | J10: =J7*J9 -> 1034.8022 | K10: =K7*K9 -> 1117.5864 | ... M10: =M7*M9 -> 1243.8736
B11: SBC % revenue | C11: =Historical!D28 -> 0.25026592 | D11: =s27+(s_lr-s27)*MIN(1,(D$6-1)/ramp) -> 0.22 | E11: =s27+(s_lr-s27)*MIN(1,(E$6-1)/ramp) -> 0.2 | F11: =s27+(s_lr-s27)*MIN(1,(F$6-1)/ramp) -> 0.18 | G11: =s27+(s_lr-s27)*MIN(1,(G$6-1)/ramp) -> 0.16 | H11: =s27+(s_lr-s27)*MIN(1,(H$6-1)/ramp) -> 0.14 | I11: =s27+(s_lr-s27)*MIN(1,(I$6-1)/ramp) -> 0.12 | J11: =s27+(s_lr-s27)*MIN(1,(J$6-1)/ramp) -> 0.1 | K11: =s27+(s_lr-s27)*MIN(1,(K$6-1)/ramp) -> 0.1 | ... M11: =s27+(s_lr-s27)*MIN(1,(M$6-1)/ramp) -> 0.1
B12: (−) Stock-based compensation | D12: =-D7*D11 -> -352.44 | E12: =-E7*E11 -> -384.48 | F12: =-F7*F11 -> -408.31776 | G12: =-G7*G11 -> -421.02098 | H12: =-H7*H11 -> -419.96843 | I12: =-I7*I11 -> -403.16969 | J12: =-J7*J11 -> -369.57222 | K12: =-K7*K11 -> -399.13799 | ... M12: =-M7*M11 -> -444.24059
B13: GAAP operating profit | C13: =Historical!D12 -> -345.4 | D13: =D10+D12 -> -256.32 | E13: =E10+E12 -> -198.648 | F13: =F10+F12 -> -105.86016 | G13: =G10+G12 -> 26.313811 | H13: =H10+H12 -> 199.98497 | I13: =I10+I12 -> 414.36885 | J13: =J10+J12 -> 665.22999 | K13: =K10+K12 -> 718.44839 | ... M13: =M10+M12 -> 799.63305
B14: GAAP operating margin | C14: =C13/C7 -> -0.26242212 | D14: =D13/D7 -> -0.16 | E14: =E13/E7 -> -0.10333333 | F14: =F13/F7 -> -0.046666667 | G14: =G13/G7 -> 0.01 | H14: =H13/H7 -> 0.066666667 | I14: =I13/I7 -> 0.12333333 | J14: =J13/J7 -> 0.18 | ... M14: =M13/M7 -> 0.18
B15: (−) Cash taxes | D15: =-MAX(0,D13)*tax -> 0 | E15: =-MAX(0,E13)*tax -> 0 | F15: =-MAX(0,F13)*tax -> 0 | G15: =-MAX(0,G13)*tax -> -5.5259004 | H15: =-MAX(0,H13)*tax -> -41.996843 | I15: =-MAX(0,I13)*tax -> -87.017458 | J15: =-MAX(0,J13)*tax -> -139.6983 | K15: =-MAX(0,K13)*tax -> -150.87416 | ... M15: =-MAX(0,M13)*tax -> -167.92294
B16: NOPAT | D16: =D13+D15 -> -256.32 | E16: =E13+E15 -> -198.648 | F16: =F13+F15 -> -105.86016 | G16: =G13+G15 -> 20.787911 | H16: =H13+H15 -> 157.98812 | I16: =I13+I15 -> 327.35139 | J16: =J13+J15 -> 525.53169 | K16: =K13+K15 -> 567.57423 | ... M16: =M13+M15 -> 631.71011
B17: (+) D&A | D17: =D7*da -> 48.06 | E17: =E7*da -> 57.672 | F17: =F7*da -> 68.05296 | G17: =G7*da -> 78.941434 | H17: =H7*da -> 89.993234 | I17: =I7*da -> 100.79242 | J17: =J7*da -> 110.87166 | K17: =K7*da -> 119.7414 | ... M17: =M7*da -> 133.27218
B18: (−) Capex | D18: =-D7*capex -> -48.06 | E18: =-E7*capex -> -57.672 | F18: =-F7*capex -> -68.05296 | G18: =-G7*capex -> -78.941434 | H18: =-H7*capex -> -89.993234 | I18: =-I7*capex -> -100.79242 | J18: =-J7*capex -> -110.87166 | K18: =-K7*capex -> -119.7414 | ... M18: =-M7*capex -> -133.27218
B19: (+) Cash from working capital | D19: =(D7-C7)*nwc -> 114.32 | E19: =(E7-D7)*nwc -> 128.16 | F19: =(F7-E7)*nwc -> 138.4128 | G19: =(G7-F7)*nwc -> 145.17965 | H19: =(H7-G7)*nwc -> 147.35734 | I19: =(I7-H7)*nwc -> 143.98917 | J19: =(J7-I7)*nwc -> 134.3899 | K19: =(K7-J7)*nwc -> 118.26311 | ... M19: =(M7-L7)*nwc -> 84.617254
B20: Unlevered free cash flow (after SBC) | D20: =D16+D17+D18+D19 -> -142 | E20: =E16+E17+E18+E19 -> -70.488 | F20: =F16+F17+F18+F19 -> 32.55264 | G20: =G16+G17+G18+G19 -> 165.96756 | H20: =H16+H17+H18+H19 -> 305.34547 | I20: =I16+I17+I18+I19 -> 471.34056 | J20: =J16+J17+J18+J19 -> 659.92159 | K20: =K16+K17+K18+K19 -> 685.83733 | ... M20: =M16+M17+M18+M19 -> 716.32737
B21: UFCF margin | D21: =D20/D7 -> -0.088639201 | E21: =E20/E7 -> -0.036666667 | F21: =F20/F7 -> 0.014350282 | G21: =G20/G7 -> 0.063072414 | H21: =H20/H7 -> 0.10178947 | I21: =I20/I7 -> 0.14029048 | J21: =J20/J7 -> 0.17856364 | K21: =K20/K7 -> 0.17182963 | ... M21: =M20/M7 -> 0.16124762
B23: Memo: UFCF before SBC (comparable to company FCF) | D23: =D20-D12 -> 210.44 | E23: =E20-E12 -> 313.992 | F23: =F20-F12 -> 440.8704 | G23: =G20-G12 -> 586.98854 | H23: =H20-H12 -> 725.31389 | I23: =I20-I12 -> 874.51025 | J23: =J20-J12 -> 1029.4938 | K23: =K20-K12 -> 1084.9753 | ... M23: =M20-M12 -> 1160.568
B24: Discount period (years, mid-year) | D24: =MAX(0,(D$5-val_date)/365.25-0.5) -> 0.27207392 | E24: =MAX(0,(E$5-val_date)/365.25-0.5) -> 1.2713895 | F24: =MAX(0,(F$5-val_date)/365.25-0.5) -> 2.2734428 | G24: =MAX(0,(G$5-val_date)/365.25-0.5) -> 3.2727584 | H24: =MAX(0,(H$5-val_date)/365.25-0.5) -> 4.2720739 | I24: =MAX(0,(I$5-val_date)/365.25-0.5) -> 5.2713895 | J24: =MAX(0,(J$5-val_date)/365.25-0.5) -> 6.2734428 | K24: =MAX(0,(K$5-val_date)/365.25-0.5) -> 7.2727584 | ... M24: =MAX(0,(M$5-val_date)/365.25-0.5) -> 9.2713895
B25: Discount factor | D25: =1/(1+wacc)^D24 -> 0.96990973 | E25: =1/(1+wacc)^E24 -> 0.86695396 | F25: =1/(1+wacc)^F24 -> 0.77468871 | G25: =1/(1+wacc)^G24 -> 0.69245562 | H25: =1/(1+wacc)^H24 -> 0.61895155 | I25: =1/(1+wacc)^I24 -> 0.55324993 | J25: =1/(1+wacc)^J24 -> 0.49437052 | K25: =1/(1+wacc)^K24 -> 0.44189316 | ... M25: =1/(1+wacc)^M24 -> 0.35305853
B26: PV of UFCF | D26: =D20*D25 -> -137.72718 | E26: =E20*E25 -> -61.10985 | F26: =F20*F25 -> 25.218163 | G26: =G20*G25 -> 114.92517 | H26: =H20*H25 -> 188.99405 | I26: =I20*I25 -> 260.76914 | J26: =J20*J25 -> 326.24578 | K26: =K20*K25 -> 303.06683 | ... M26: =M20*M25 -> 252.90549
B28: Check: FY2027E against company guidance
B29: FY2027E revenue vs. guidance midpoint | D29: =D7 -> 1602 | E29: =gd_rev -> 1602 | F29: =IF(AND(D29>=gd_rev_lo,D29<=gd_rev_hi),"In range","Outside") -> In range
B30: FY2027E FCF (before SBC, incl. interest) vs. guidance | D30: =D23+int_inc -> 260.44 | E30: =gd_fcf -> 270 | F30: =IF(AND(D30>=gd_fcf_lo-25,D30<=gd_fcf_hi+25),"Within $25mn","Recalibrate") -> Within $25mn
B32: Discount rate
B33: Cost of equity (CAPM) | C33: =rf+beta*erp -> 0.126
B34: After-tax cost of debt | C34: =kd*(1-tax_w) -> 0.0395
B35: Market value of equity ($mn) | C35: =price*shares -> 12532.64
B36: Debt (convertible notes, $mn) | C36: =debt -> 1130.7
B37: Equity weight | C37: =mcap/(mcap+debt) -> 0.91724571
B38: WACC | C38: =we*ke+(1-we)*kd_at -> 0.11884175
B40: Valuation
B41: Sum of PV of UFCF, FY2027E–FY2036E | C41: =SUM(D26:M26) -> 1548.7596
B42: Terminal value at FY2036E (Gordon) | C42: =M20*(1+g)/(wacc-g) -> 8842.8354
B43: PV of terminal value | C43: =tv/(1+wacc)^(M24+0.5) -> 2951.5756
B44: Enterprise value | C44: =sum_pv+pv_tv -> 4500.3352
B45: (+) Cash and short-term investments | C45: =cash -> 1675.8
...

Sheet Sensitivity
B1: Sensitivity
B2: Value per share ($). Each margin row re-runs the full 10-year projection with that long-run margin; columns re-discount at that WACC.
B4: WACC step | C4: 0.01
B5: Long-run margin step | C5: 0.04
B6: Terminal growth step | C6: 0.005
B8: 1) Long-run operating margin excl. SBC (rows) × WACC (columns)
B9: Margin ↓ / WACC → | C9: =wacc+(-2)*$C$4 -> 0.098841754 | D9: =wacc+(-1)*$C$4 -> 0.10884175 | E9: =wacc+(0)*$C$4 -> 0.11884175 | F9: =wacc+(1)*$C$4 -> 0.12884175 | G9: =wacc+(2)*$C$4 -> 0.13884175
B10: =m_lr+(-2)*$C$5 -> 0.2 | C10: =(SUMPRODUCT($I40:$R40,(1+C$9)^(-DCF!$D$24:$M$24))+$R40*(1+g)/(C$9-g)/(1+C$9)^(DCF!$M$24+0.5)+cash-debt)/shares -> 18.49558 | D10: =(SUMPRODUCT($I40:$R40,(1+D$9)^(-DCF!$D$24:$M$24))+$R40*(1+g)/(D$9-g)/(1+D$9)^(DCF!$M$24+0.5)+cash-debt)/shares -> 15.672269 | E10: =(SUMPRODUCT($I40:$R40,(1+E$9)^(-DCF!$D$24:$M$24))+$R40*(1+g)/(E$9-g)/(1+E$9)^(DCF!$M$24+0.5)+cash-debt)/shares -> 13.545845 | F10: =(SUMPRODUCT($I40:$R40,(1+F$9)^(-DCF!$D$24:$M$24))+$R40*(1+g)/(F$9-g)/(1+F$9)^(DCF!$M$24+0.5)+cash-debt)/shares -> 11.892113 | G10: =(SUMPRODUCT($I40:$R40,(1+G$9)^(-DCF!$D$24:$M$24))+$R40*(1+g)/(G$9-g)/(1+G$9)^(DCF!$M$24+0.5)+cash-debt)/shares -> 10.573353
B11: =m_lr+(-1)*$C$5 -> 0.24 | C11: =(SUMPRODUCT($I41:$R41,(1+C$9)^(-DCF!$D$24:$M$24))+$R41*(1+g)/(C$9-g)/(1+C$9)^(DCF!$M$24+0.5)+cash-debt)/shares -> 24.205262 | D11: =(SUMPRODUCT($I41:$R41,(1+D$9)^(-DCF!$D$24:$M$24))+$R41*(1+g)/(D$9-g)/(1+D$9)^(DCF!$M$24+0.5)+cash-debt)/shares -> 20.469435 | E11: =(SUMPRODUCT($I41:$R41,(1+E$9)^(-DCF!$D$24:$M$24))+$R41*(1+g)/(E$9-g)/(1+E$9)^(DCF!$M$24+0.5)+cash-debt)/shares -> 17.654952 | F11: =(SUMPRODUCT($I41:$R41,(1+F$9)^(-DCF!$D$24:$M$24))+$R41*(1+g)/(F$9-g)/(1+F$9)^(DCF!$M$24+0.5)+cash-debt)/shares -> 15.46538 | G11: =(SUMPRODUCT($I41:$R41,(1+G$9)^(-DCF!$D$24:$M$24))+$R41*(1+g)/(G$9-g)/(1+G$9)^(DCF!$M$24+0.5)+cash-debt)/shares -> 13.718633
B12: =m_lr+(0)*$C$5 -> 0.28 | C12: =(SUMPRODUCT($I42:$R42,(1+C$9)^(-DCF!$D$24:$M$24))+$R42*(1+g)/(C$9-g)/(1+C$9)^(DCF!$M$24+0.5)+cash-debt)/shares -> 29.897449 | D12: =(SUMPRODUCT($I42:$R42,(1+D$9)^(-DCF!$D$24:$M$24))+$R42*(1+g)/(D$9-g)/(1+D$9)^(DCF!$M$24+0.5)+cash-debt)/shares -> 25.249616 | E12: =(SUMPRODUCT($I42:$R42,(1+E$9)^(-DCF!$D$24:$M$24))+$R42*(1+g)/(E$9-g)/(1+E$9)^(DCF!$M$24+0.5)+cash-debt)/shares -> 21.747566 | F12: =(SUMPRODUCT($I42:$R42,(1+F$9)^(-DCF!$D$24:$M$24))+$R42*(1+g)/(F$9-g)/(1+F$9)^(DCF!$M$24+0.5)+cash-debt)/shares -> 19.022628 | G12: =(SUMPRODUCT($I42:$R42,(1+G$9)^(-DCF!$D$24:$M$24))+$R42*(1+g)/(G$9-g)/(1+G$9)^(DCF!$M$24+0.5)+cash-debt)/shares -> 16.84835
B13: =m_lr+(1)*$C$5 -> 0.32 | C13: =(SUMPRODUCT($I43:$R43,(1+C$9)^(-DCF!$D$24:$M$24))+$R43*(1+g)/(C$9-g)/(1+C$9)^(DCF!$M$24+0.5)+cash-debt)/shares -> 35.572139 | D13: =(SUMPRODUCT($I43:$R43,(1+D$9)^(-DCF!$D$24:$M$24))+$R43*(1+g)/(D$9-g)/(1+D$9)^(DCF!$M$24+0.5)+cash-debt)/shares -> 30.012812 | E13: =(SUMPRODUCT($I43:$R43,(1+E$9)^(-DCF!$D$24:$M$24))+$R43*(1+g)/(E$9-g)/(1+E$9)^(DCF!$M$24+0.5)+cash-debt)/shares -> 25.823686 | F13: =(SUMPRODUCT($I43:$R43,(1+F$9)^(-DCF!$D$24:$M$24))+$R43*(1+g)/(F$9-g)/(1+F$9)^(DCF!$M$24+0.5)+cash-debt)/shares -> 22.563856 | G13: =(SUMPRODUCT($I43:$R43,(1+G$9)^(-DCF!$D$24:$M$24))+$R43*(1+g)/(G$9-g)/(1+G$9)^(DCF!$M$24+0.5)+cash-debt)/shares -> 19.962502
B14: =m_lr+(2)*$C$5 -> 0.36 | C14: =(SUMPRODUCT($I44:$R44,(1+C$9)^(-DCF!$D$24:$M$24))+$R44*(1+g)/(C$9-g)/(1+C$9)^(DCF!$M$24+0.5)+cash-debt)/shares -> 41.246829 | D14: =(SUMPRODUCT($I44:$R44,(1+D$9)^(-DCF!$D$24:$M$24))+$R44*(1+g)/(D$9-g)/(1+D$9)^(DCF!$M$24+0.5)+cash-debt)/shares -> 34.776008 | E14: =(SUMPRODUCT($I44:$R44,(1+E$9)^(-DCF!$D$24:$M$24))+$R44*(1+g)/(E$9-g)/(1+E$9)^(DCF!$M$24+0.5)+cash-debt)/shares -> 29.899806 | F14: =(SUMPRODUCT($I44:$R44,(1+F$9)^(-DCF!$D$24:$M$24))+$R44*(1+g)/(F$9-g)/(1+F$9)^(DCF!$M$24+0.5)+cash-debt)/shares -> 26.105083 | G14: =(SUMPRODUCT($I44:$R44,(1+G$9)^(-DCF!$D$24:$M$24))+$R44*(1+g)/(G$9-g)/(1+G$9)^(DCF!$M$24+0.5)+cash-debt)/shares -> 23.076654
B16: Check: centre cell − DCF value per share | E16: =E12-vps -> 0
B18: 2) Upside / (downside) vs. $54.02
B19: Margin ↓ / WACC → | C19: =C9 -> 0.098841754 | D19: =D9 -> 0.10884175 | E19: =E9 -> 0.11884175 | F19: =F9 -> 0.12884175 | G19: =G9 -> 0.13884175
B20: =B10 -> 0.2 | C20: =C10/price-1 -> -0.65761607 | D20: =D10/price-1 -> -0.70988026 | E20: =E10/price-1 -> -0.74924389 | F20: =F10/price-1 -> -0.77985722 | G20: =G10/price-1 -> -0.80426966
B21: =B11 -> 0.24 | C21: =C11/price-1 -> -0.55192035 | D21: =D11/price-1 -> -0.62107674 | E21: =E11/price-1 -> -0.67317749 | F21: =F11/price-1 -> -0.7137101 | G21: =G11/price-1 -> -0.74604529
B22: =B12 -> 0.28 | C22: =C12/price-1 -> -0.44654852 | D22: =D12/price-1 -> -0.53258764 | E22: =E12/price-1 -> -0.59741641 | F22: =F12/price-1 -> -0.64785954 | G22: =G12/price-1 -> -0.68810904
B23: =B13 -> 0.32 | C23: =C13/price-1 -> -0.34150058 | D23: =D13/price-1 -> -0.44441296 | E23: =E13/price-1 -> -0.52196064 | F23: =F13/price-1 -> -0.58230552 | G23: =G13/price-1 -> -0.6304609
B24: =B14 -> 0.36 | C24: =C14/price-1 -> -0.23645263 | D24: =D14/price-1 -> -0.35623829 | E24: =E14/price-1 -> -0.44650488 | F24: =F14/price-1 -> -0.51675151 | G24: =G14/price-1 -> -0.57281277
B26: Market-implied long-run margin (linear fit at base WACC) | C26: =FORECAST(price,B10:B14,E10:E14) -> 0.59593122
B28: 3) Terminal growth (rows) × WACC (columns), base margins
B29: g ↓ / WACC → | C29: =C9 -> 0.098841754 | D29: =D9 -> 0.10884175 | E29: =E9 -> 0.11884175 | F29: =F9 -> 0.12884175 | G29: =G9 -> 0.13884175
B30: =g+(-2)*$C$6 -> 0.025 | C30: =(SUMPRODUCT(DCF!$D$20:$M$20,(1+C$29)^(-DCF!$D$24:$M$24))+DCF!$M$20*(1+$B30)/(C$29-$B30)/(1+C$29)^(DCF!$M$24+0.5)+cash-debt)/shares -> 27.032225 | D30: =(SUMPRODUCT(DCF!$D$20:$M$20,(1+D$29)^(-DCF!$D$24:$M$24))+DCF!$M$20*(1+$B30)/(D$29-$B30)/(1+D$29)^(DCF!$M$24+0.5)+cash-debt)/shares -> 23.234534 | E30: =(SUMPRODUCT(DCF!$D$20:$M$20,(1+E$29)^(-DCF!$D$24:$M$24))+DCF!$M$20*(1+$B30)/(E$29-$B30)/(1+E$29)^(DCF!$M$24+0.5)+cash-debt)/shares -> 20.282024 | F30: =(SUMPRODUCT(DCF!$D$20:$M$20,(1+F$29)^(-DCF!$D$24:$M$24))+DCF!$M$20*(1+$B30)/(F$29-$B30)/(1+F$29)^(DCF!$M$24+0.5)+cash-debt)/shares -> 17.928192 | G30: =(SUMPRODUCT(DCF!$D$20:$M$20,(1+G$29)^(-DCF!$D$24:$M$24))+DCF!$M$20*(1+$B30)/(G$29-$B30)/(1+G$29)^(DCF!$M$24+0.5)+cash-debt)/shares -> 16.013347
B31: =g+(-1)*$C$6 -> 0.03 | C31: =(SUMPRODUCT(DCF!$D$20:$M$20,(1+C$29)^(-DCF!$D$24:$M$24))+DCF!$M$20*(1+$B31)/(C$29-$B31)/(1+C$29)^(DCF!$M$24+0.5)+cash-debt)/shares -> 28.360786 | D31: =(SUMPRODUCT(DCF!$D$20:$M$20,(1+D$29)^(-DCF!$D$24:$M$24))+DCF!$M$20*(1+$B31)/(D$29-$B31)/(1+D$29)^(DCF!$M$24+0.5)+cash-debt)/shares -> 24.178178 | E31: =(SUMPRODUCT(DCF!$D$20:$M$20,(1+E$29)^(-DCF!$D$24:$M$24))+DCF!$M$20*(1+$B31)/(E$29-$B31)/(1+E$29)^(DCF!$M$24+0.5)+cash-debt)/shares -> 20.973555 | F31: =(SUMPRODUCT(DCF!$D$20:$M$20,(1+F$29)^(-DCF!$D$24:$M$24))+DCF!$M$20*(1+$B31)/(F$29-$B31)/(1+F$29)^(DCF!$M$24+0.5)+cash-debt)/shares -> 18.447728 | G31: =(SUMPRODUCT(DCF!$D$20:$M$20,(1+G$29)^(-DCF!$D$24:$M$24))+DCF!$M$20*(1+$B31)/(G$29-$B31)/(1+G$29)^(DCF!$M$24+0.5)+cash-debt)/shares -> 16.411669
B32: =g+(0)*$C$6 -> 0.035 | C32: =(SUMPRODUCT(DCF!$D$20:$M$20,(1+C$29)^(-DCF!$D$24:$M$24))+DCF!$M$20*(1+$B32)/(C$29-$B32)/(1+C$29)^(DCF!$M$24+0.5)+cash-debt)/shares -> 29.897449 | D32: =(SUMPRODUCT(DCF!$D$20:$M$20,(1+D$29)^(-DCF!$D$24:$M$24))+DCF!$M$20*(1+$B32)/(D$29-$B32)/(1+D$29)^(DCF!$M$24+0.5)+cash-debt)/shares -> 25.249616 | E32: =(SUMPRODUCT(DCF!$D$20:$M$20,(1+E$29)^(-DCF!$D$24:$M$24))+DCF!$M$20*(1+$B32)/(E$29-$B32)/(1+E$29)^(DCF!$M$24+0.5)+cash-debt)/shares -> 21.747566 | F32: =(SUMPRODUCT(DCF!$D$20:$M$20,(1+F$29)^(-DCF!$D$24:$M$24))+DCF!$M$20*(1+$B32)/(F$29-$B32)/(1+F$29)^(DCF!$M$24+0.5)+cash-debt)/shares -> 19.022628 | G32: =(SUMPRODUCT(DCF!$D$20:$M$20,(1+G$29)^(-DCF!$D$24:$M$24))+DCF!$M$20*(1+$B32)/(G$29-$B32)/(1+G$29)^(DCF!$M$24+0.5)+cash-debt)/shares -> 16.84835
B33: =g+(1)*$C$6 -> 0.04 | C33: =(SUMPRODUCT(DCF!$D$20:$M$20,(1+C$29)^(-DCF!$D$24:$M$24))+DCF!$M$20*(1+$B33)/(C$29-$B33)/(1+C$29)^(DCF!$M$24+0.5)+cash-debt)/shares -> 31.695264 | D33: =(SUMPRODUCT(DCF!$D$20:$M$20,(1+D$29)^(-DCF!$D$24:$M$24))+DCF!$M$20*(1+$B33)/(D$29-$B33)/(1+D$29)^(DCF!$M$24+0.5)+cash-debt)/shares -> 26.476691 | E33: =(SUMPRODUCT(DCF!$D$20:$M$20,(1+E$29)^(-DCF!$D$24:$M$24))+DCF!$M$20*(1+$B33)/(E$29-$B33)/(1+E$29)^(DCF!$M$24+0.5)+cash-debt)/shares -> 22.619749 | F33: =(SUMPRODUCT(DCF!$D$20:$M$20,(1+F$29)^(-DCF!$D$24:$M$24))+DCF!$M$20*(1+$B33)/(F$29-$B33)/(1+F$29)^(DCF!$M$24+0.5)+cash-debt)/shares -> 19.662238 | G33: =(SUMPRODUCT(DCF!$D$20:$M$20,(1+G$29)^(-DCF!$D$24:$M$24))+DCF!$M$20*(1+$B33)/(G$29-$B33)/(1+G$29)^(DCF!$M$24+0.5)+cash-debt)/shares -> 17.32921
B34: =g+(2)*$C$6 -> 0.045 | C34: =(SUMPRODUCT(DCF!$D$20:$M$20,(1+C$29)^(-DCF!$D$24:$M$24))+DCF!$M$20*(1+$B34)/(C$29-$B34)/(1+C$29)^(DCF!$M$24+0.5)+cash-debt)/shares -> 33.826986 | D34: =(SUMPRODUCT(DCF!$D$20:$M$20,(1+D$29)^(-DCF!$D$24:$M$24))+DCF!$M$20*(1+$B34)/(D$29-$B34)/(1+D$29)^(DCF!$M$24+0.5)+cash-debt)/shares -> 27.895972 | E34: =(SUMPRODUCT(DCF!$D$20:$M$20,(1+E$29)^(-DCF!$D$24:$M$24))+DCF!$M$20*(1+$B34)/(E$29-$B34)/(1+E$29)^(DCF!$M$24+0.5)+cash-debt)/shares -> 23.610048 | F34: =(SUMPRODUCT(DCF!$D$20:$M$20,(1+F$29)^(-DCF!$D$24:$M$24))+DCF!$M$20*(1+$B34)/(F$29-$B34)/(1+F$29)^(DCF!$M$24+0.5)+cash-debt)/shares -> 20.378136 | G34: =(SUMPRODUCT(DCF!$D$20:$M$20,(1+G$29)^(-DCF!$D$24:$M$24))+DCF!$M$20*(1+$B34)/(G$29-$B34)/(1+G$29)^(DCF!$M$24+0.5)+cash-debt)/shares -> 17.861312
B38: Helper: projection per long-run margin (UFCF, US$ mn)
I39: FY2027E | J39: FY2028E | K39: FY2029E | L39: FY2030E | M39: FY2031E | N39: FY2032E | O39: FY2033E | P39: FY2034E | Q39: FY2035E | R39: FY2036E
B40: =B10 -> 0.2 | I40: =(DCF!D7*((m27+($B40-m27)*MIN(1,(DCF!D$6-1)/ramp))-DCF!D11))-MAX(0,(DCF!D7*((m27+($B40-m27)*MIN(1,(DCF!D$6-1)/ramp))-DCF!D11)))*tax+DCF!D7*(da-capex)+(DCF!D7-DCF!C7)*nwc -> -142 | J40: =(DCF!E7*((m27+($B40-m27)*MIN(1,(DCF!E$6-1)/ramp))-DCF!E11))-MAX(0,(DCF!E7*((m27+($B40-m27)*MIN(1,(DCF!E$6-1)/ramp))-DCF!E11)))*tax+DCF!E7*(da-capex)+(DCF!E7-DCF!D7)*nwc -> -96.12 | K40: =(DCF!F7*((m27+($B40-m27)*MIN(1,(DCF!F$6-1)/ramp))-DCF!F11))-MAX(0,(DCF!F7*((m27+($B40-m27)*MIN(1,(DCF!F$6-1)/ramp))-DCF!F11)))*tax+DCF!F7*(da-capex)+(DCF!F7-DCF!E7)*nwc -> -27.93888 | L40: =(DCF!G7*((m27+($B40-m27)*MIN(1,(DCF!G$6-1)/ramp))-DCF!G11))-MAX(0,(DCF!G7*((m27+($B40-m27)*MIN(1,(DCF!G$6-1)/ramp))-DCF!G11)))*tax+DCF!G7*(da-capex)+(DCF!G7-DCF!F7)*nwc -> 66.238214 | M40: =(DCF!H7*((m27+($B40-m27)*MIN(1,(DCF!H$6-1)/ramp))-DCF!H11))-MAX(0,(DCF!H7*((m27+($B40-m27)*MIN(1,(DCF!H$6-1)/ramp))-DCF!H11)))*tax+DCF!H7*(da-capex)+(DCF!H7-DCF!G7)*nwc -> 178.95497 | N40: =(DCF!I7*((m27+($B40-m27)*MIN(1,(DCF!I$6-1)/ramp))-DCF!I11))-MAX(0,(DCF!I7*((m27+($B40-m27)*MIN(1,(DCF!I$6-1)/ramp))-DCF!I11)))*tax+DCF!I7*(da-capex)+(DCF!I7-DCF!H7)*nwc -> 294.39387 | O40: =(DCF!J7*((m27+($B40-m27)*MIN(1,(DCF!J$6-1)/ramp))-DCF!J11))-MAX(0,(DCF!J7*((m27+($B40-m27)*MIN(1,(DCF!J$6-1)/ramp))-DCF!J11)))*tax+DCF!J7*(da-capex)+(DCF!J7-DCF!I7)*nwc -> 426.35195 | P40: =(DCF!K7*((m27+($B40-m27)*MIN(1,(DCF!K$6-1)/ramp))-DCF!K11))-MAX(0,(DCF!K7*((m27+($B40-m27)*MIN(1,(DCF!K$6-1)/ramp))-DCF!K11)))*tax+DCF!K7*(da-capex)+(DCF!K7-DCF!J7)*nwc -> 433.58212 | ... R40: =(DCF!M7*((m27+($B40-m27)*MIN(1,(DCF!M$6-1)/ramp))-DCF!M11))-MAX(0,(DCF!M7*((m27+($B40-m27)*MIN(1,(DCF!M$6-1)/ramp))-DCF!M11)))*tax+DCF!M7*(da-capex)+(DCF!M7-DCF!L7)*nwc -> 435.56732
B41: =B11 -> 0.24 | I41: =(DCF!D7*((m27+($B41-m27)*MIN(1,(DCF!D$6-1)/ramp))-DCF!D11))-MAX(0,(DCF!D7*((m27+($B41-m27)*MIN(1,(DCF!D$6-1)/ramp))-DCF!D11)))*tax+DCF!D7*(da-capex)+(DCF!D7-DCF!C7)*nwc -> -142 | J41: =(DCF!E7*((m27+($B41-m27)*MIN(1,(DCF!E$6-1)/ramp))-DCF!E11))-MAX(0,(DCF!E7*((m27+($B41-m27)*MIN(1,(DCF!E$6-1)/ramp))-DCF!E11)))*tax+DCF!E7*(da-capex)+(DCF!E7-DCF!D7)*nwc -> -83.304 | K41: =(DCF!F7*((m27+($B41-m27)*MIN(1,(DCF!F$6-1)/ramp))-DCF!F11))-MAX(0,(DCF!F7*((m27+($B41-m27)*MIN(1,(DCF!F$6-1)/ramp))-DCF!F11)))*tax+DCF!F7*(da-capex)+(DCF!F7-DCF!E7)*nwc -> 2.30688 | L41: =(DCF!G7*((m27+($B41-m27)*MIN(1,(DCF!G$6-1)/ramp))-DCF!G11))-MAX(0,(DCF!G7*((m27+($B41-m27)*MIN(1,(DCF!G$6-1)/ramp))-DCF!G11)))*tax+DCF!G7*(da-capex)+(DCF!G7-DCF!F7)*nwc -> 118.86584 | M41: =(DCF!H7*((m27+($B41-m27)*MIN(1,(DCF!H$6-1)/ramp))-DCF!H11))-MAX(0,(DCF!H7*((m27+($B41-m27)*MIN(1,(DCF!H$6-1)/ramp))-DCF!H11)))*tax+DCF!H7*(da-capex)+(DCF!H7-DCF!G7)*nwc -> 242.15022 | N41: =(DCF!I7*((m27+($B41-m27)*MIN(1,(DCF!I$6-1)/ramp))-DCF!I11))-MAX(0,(DCF!I7*((m27+($B41-m27)*MIN(1,(DCF!I$6-1)/ramp))-DCF!I11)))*tax+DCF!I7*(da-capex)+(DCF!I7-DCF!H7)*nwc -> 382.86722 | O41: =(DCF!J7*((m27+($B41-m27)*MIN(1,(DCF!J$6-1)/ramp))-DCF!J11))-MAX(0,(DCF!J7*((m27+($B41-m27)*MIN(1,(DCF!J$6-1)/ramp))-DCF!J11)))*tax+DCF!J7*(da-capex)+(DCF!J7-DCF!I7)*nwc -> 543.13677 | P41: =(DCF!K7*((m27+($B41-m27)*MIN(1,(DCF!K$6-1)/ramp))-DCF!K11))-MAX(0,(DCF!K7*((m27+($B41-m27)*MIN(1,(DCF!K$6-1)/ramp))-DCF!K11)))*tax+DCF!K7*(da-capex)+(DCF!K7-DCF!J7)*nwc -> 559.70973 | ... R41: =(DCF!M7*((m27+($B41-m27)*MIN(1,(DCF!M$6-1)/ramp))-DCF!M11))-MAX(0,(DCF!M7*((m27+($B41-m27)*MIN(1,(DCF!M$6-1)/ramp))-DCF!M11)))*tax+DCF!M7*(da-capex)+(DCF!M7-DCF!L7)*nwc -> 575.94734
B42: =B12 -> 0.28 | I42: =(DCF!D7*((m27+($B42-m27)*MIN(1,(DCF!D$6-1)/ramp))-DCF!D11))-MAX(0,(DCF!D7*((m27+($B42-m27)*MIN(1,(DCF!D$6-1)/ramp))-DCF!D11)))*tax+DCF!D7*(da-capex)+(DCF!D7-DCF!C7)*nwc -> -142 | J42: =(DCF!E7*((m27+($B42-m27)*MIN(1,(DCF!E$6-1)/ramp))-DCF!E11))-MAX(0,(DCF!E7*((m27+($B42-m27)*MIN(1,(DCF!E$6-1)/ramp))-DCF!E11)))*tax+DCF!E7*(da-capex)+(DCF!E7-DCF!D7)*nwc -> -70.488 | K42: =(DCF!F7*((m27+($B42-m27)*MIN(1,(DCF!F$6-1)/ramp))-DCF!F11))-MAX(0,(DCF!F7*((m27+($B42-m27)*MIN(1,(DCF!F$6-1)/ramp))-DCF!F11)))*tax+DCF!F7*(da-capex)+(DCF!F7-DCF!E7)*nwc -> 32.55264 | L42: =(DCF!G7*((m27+($B42-m27)*MIN(1,(DCF!G$6-1)/ramp))-DCF!G11))-MAX(0,(DCF!G7*((m27+($B42-m27)*MIN(1,(DCF!G$6-1)/ramp))-DCF!G11)))*tax+DCF!G7*(da-capex)+(DCF!G7-DCF!F7)*nwc -> 165.96756 | M42: =(DCF!H7*((m27+($B42-m27)*MIN(1,(DCF!H$6-1)/ramp))-DCF!H11))-MAX(0,(DCF!H7*((m27+($B42-m27)*MIN(1,(DCF!H$6-1)/ramp))-DCF!H11)))*tax+DCF!H7*(da-capex)+(DCF!H7-DCF!G7)*nwc -> 305.34547 | N42: =(DCF!I7*((m27+($B42-m27)*MIN(1,(DCF!I$6-1)/ramp))-DCF!I11))-MAX(0,(DCF!I7*((m27+($B42-m27)*MIN(1,(DCF!I$6-1)/ramp))-DCF!I11)))*tax+DCF!I7*(da-capex)+(DCF!I7-DCF!H7)*nwc -> 471.34056 | O42: =(DCF!J7*((m27+($B42-m27)*MIN(1,(DCF!J$6-1)/ramp))-DCF!J11))-MAX(0,(DCF!J7*((m27+($B42-m27)*MIN(1,(DCF!J$6-1)/ramp))-DCF!J11)))*tax+DCF!J7*(da-capex)+(DCF!J7-DCF!I7)*nwc -> 659.92159 | P42: =(DCF!K7*((m27+($B42-m27)*MIN(1,(DCF!K$6-1)/ramp))-DCF!K11))-MAX(0,(DCF!K7*((m27+($B42-m27)*MIN(1,(DCF!K$6-1)/ramp))-DCF!K11)))*tax+DCF!K7*(da-capex)+(DCF!K7-DCF!J7)*nwc -> 685.83733 | ... R42: =(DCF!M7*((m27+($B42-m27)*MIN(1,(DCF!M$6-1)/ramp))-DCF!M11))-MAX(0,(DCF!M7*((m27+($B42-m27)*MIN(1,(DCF!M$6-1)/ramp))-DCF!M11)))*tax+DCF!M7*(da-capex)+(DCF!M7-DCF!L7)*nwc -> 716.32737
B43: =B13 -> 0.32 | I43: =(DCF!D7*((m27+($B43-m27)*MIN(1,(DCF!D$6-1)/ramp))-DCF!D11))-MAX(0,(DCF!D7*((m27+($B43-m27)*MIN(1,(DCF!D$6-1)/ramp))-DCF!D11)))*tax+DCF!D7*(da-capex)+(DCF!D7-DCF!C7)*nwc -> -142 | J43: =(DCF!E7*((m27+($B43-m27)*MIN(1,(DCF!E$6-1)/ramp))-DCF!E11))-MAX(0,(DCF!E7*((m27+($B43-m27)*MIN(1,(DCF!E$6-1)/ramp))-DCF!E11)))*tax+DCF!E7*(da-capex)+(DCF!E7-DCF!D7)*nwc -> -57.672 | K43: =(DCF!F7*((m27+($B43-m27)*MIN(1,(DCF!F$6-1)/ramp))-DCF!F11))-MAX(0,(DCF!F7*((m27+($B43-m27)*MIN(1,(DCF!F$6-1)/ramp))-DCF!F11)))*tax+DCF!F7*(da-capex)+(DCF!F7-DCF!E7)*nwc -> 62.7984 | L43: =(DCF!G7*((m27+($B43-m27)*MIN(1,(DCF!G$6-1)/ramp))-DCF!G11))-MAX(0,(DCF!G7*((m27+($B43-m27)*MIN(1,(DCF!G$6-1)/ramp))-DCF!G11)))*tax+DCF!G7*(da-capex)+(DCF!G7-DCF!F7)*nwc -> 207.54338 | M43: =(DCF!H7*((m27+($B43-m27)*MIN(1,(DCF!H$6-1)/ramp))-DCF!H11))-MAX(0,(DCF!H7*((m27+($B43-m27)*MIN(1,(DCF!H$6-1)/ramp))-DCF!H11)))*tax+DCF!H7*(da-capex)+(DCF!H7-DCF!G7)*nwc -> 368.54071 | N43: =(DCF!I7*((m27+($B43-m27)*MIN(1,(DCF!I$6-1)/ramp))-DCF!I11))-MAX(0,(DCF!I7*((m27+($B43-m27)*MIN(1,(DCF!I$6-1)/ramp))-DCF!I11)))*tax+DCF!I7*(da-capex)+(DCF!I7-DCF!H7)*nwc -> 559.81391 | O43: =(DCF!J7*((m27+($B43-m27)*MIN(1,(DCF!J$6-1)/ramp))-DCF!J11))-MAX(0,(DCF!J7*((m27+($B43-m27)*MIN(1,(DCF!J$6-1)/ramp))-DCF!J11)))*tax+DCF!J7*(da-capex)+(DCF!J7-DCF!I7)*nwc -> 776.70641 | P43: =(DCF!K7*((m27+($B43-m27)*MIN(1,(DCF!K$6-1)/ramp))-DCF!K11))-MAX(0,(DCF!K7*((m27+($B43-m27)*MIN(1,(DCF!K$6-1)/ramp))-DCF!K11)))*tax+DCF!K7*(da-capex)+(DCF!K7-DCF!J7)*nwc -> 811.96494 | ... R43: =(DCF!M7*((m27+($B43-m27)*MIN(1,(DCF!M$6-1)/ramp))-DCF!M11))-MAX(0,(DCF!M7*((m27+($B43-m27)*MIN(1,(DCF!M$6-1)/ramp))-DCF!M11)))*tax+DCF!M7*(da-capex)+(DCF!M7-DCF!L7)*nwc -> 856.70739
B44: =B14 -> 0.36 | I44: =(DCF!D7*((m27+($B44-m27)*MIN(1,(DCF!D$6-1)/ramp))-DCF!D11))-MAX(0,(DCF!D7*((m27+($B44-m27)*MIN(1,(DCF!D$6-1)/ramp))-DCF!D11)))*tax+DCF!D7*(da-capex)+(DCF!D7-DCF!C7)*nwc -> -142 | J44: =(DCF!E7*((m27+($B44-m27)*MIN(1,(DCF!E$6-1)/ramp))-DCF!E11))-MAX(0,(DCF!E7*((m27+($B44-m27)*MIN(1,(DCF!E$6-1)/ramp))-DCF!E11)))*tax+DCF!E7*(da-capex)+(DCF!E7-DCF!D7)*nwc -> -44.856 | K44: =(DCF!F7*((m27+($B44-m27)*MIN(1,(DCF!F$6-1)/ramp))-DCF!F11))-MAX(0,(DCF!F7*((m27+($B44-m27)*MIN(1,(DCF!F$6-1)/ramp))-DCF!F11)))*tax+DCF!F7*(da-capex)+(DCF!F7-DCF!E7)*nwc -> 93.04416 | L44: =(DCF!G7*((m27+($B44-m27)*MIN(1,(DCF!G$6-1)/ramp))-DCF!G11))-MAX(0,(DCF!G7*((m27+($B44-m27)*MIN(1,(DCF!G$6-1)/ramp))-DCF!G11)))*tax+DCF!G7*(da-capex)+(DCF!G7-DCF!F7)*nwc -> 249.1192 | M44: =(DCF!H7*((m27+($B44-m27)*MIN(1,(DCF!H$6-1)/ramp))-DCF!H11))-MAX(0,(DCF!H7*((m27+($B44-m27)*MIN(1,(DCF!H$6-1)/ramp))-DCF!H11)))*tax+DCF!H7*(da-capex)+(DCF!H7-DCF!G7)*nwc -> 431.73596 | N44: =(DCF!I7*((m27+($B44-m27)*MIN(1,(DCF!I$6-1)/ramp))-DCF!I11))-MAX(0,(DCF!I7*((m27+($B44-m27)*MIN(1,(DCF!I$6-1)/ramp))-DCF!I11)))*tax+DCF!I7*(da-capex)+(DCF!I7-DCF!H7)*nwc -> 648.28726 | O44: =(DCF!J7*((m27+($B44-m27)*MIN(1,(DCF!J$6-1)/ramp))-DCF!J11))-MAX(0,(DCF!J7*((m27+($B44-m27)*MIN(1,(DCF!J$6-1)/ramp))-DCF!J11)))*tax+DCF!J7*(da-capex)+(DCF!J7-DCF!I7)*nwc -> 893.49123 | P44: =(DCF!K7*((m27+($B44-m27)*MIN(1,(DCF!K$6-1)/ramp))-DCF!K11))-MAX(0,(DCF!K7*((m27+($B44-m27)*MIN(1,(DCF!K$6-1)/ramp))-DCF!K11)))*tax+DCF!K7*(da-capex)+(DCF!K7-DCF!J7)*nwc -> 938.09255 | ... R44: =(DCF!M7*((m27+($B44-m27)*MIN(1,(DCF!M$6-1)/ramp))-DCF!M11))-MAX(0,(DCF!M7*((m27+($B44-m27)*MIN(1,(DCF!M$6-1)/ramp))-DCF!M11)))*tax+DCF!M7*(da-capex)+(DCF!M7-DCF!L7)*nwc -> 997.08742

Sheet Multiples
B1: Trading multiples: EV / NTM revenue
B2: NTM revenue = FY2027E (live scenario; base = guidance midpoint). Bands are inputs on the Inputs sheet.
B4: NTM revenue ($mn) | C4: =DCF!D7 -> 1602
B5: Current EV / NTM revenue | C5: =mkt_ev_ntm -> 7.4828589
B6: EV / NTM revenue at DCF value | C6: =ev_ntm_dcf -> 2.809198
B8: Band | C8: EV / NTM rev | D8: Implied EV | E8: (+) Cash | F8: (−) Notes | G8: Equity value | H8: Per share ($) | I8: vs. price
B9: =Inputs!B47 -> Bear | C9: =Inputs!C47 -> 4 | D9: =C9*$C$4 -> 6408 | E9: =cash -> 1675.8 | F9: =-debt -> -1130.7 | G9: =D9+E9+F9 -> 6953.1 | H9: =G9/shares -> 29.970259 | I9: =H9/price-1 -> -0.44520069
B10: =Inputs!B48 -> Low | C10: =Inputs!C48 -> 6 | D10: =C10*$C$4 -> 9612 | E10: =cash -> 1675.8 | F10: =-debt -> -1130.7 | G10: =D10+E10+F10 -> 10157.1 | H10: =G10/shares -> 43.780603 | I10: =H10/price-1 -> -0.18954825
B11: =Inputs!B49 -> Base | C11: =Inputs!C49 -> 8.5 | D11: =C11*$C$4 -> 13617 | E11: =cash -> 1675.8 | F11: =-debt -> -1130.7 | G11: =D11+E11+F11 -> 14162.1 | H11: =G11/shares -> 61.043534 | I11: =H11/price-1 -> 0.1300173
B12: =Inputs!B50 -> High | C12: =Inputs!C50 -> 12 | D12: =C12*$C$4 -> 19224 | E12: =cash -> 1675.8 | F12: =-debt -> -1130.7 | G12: =D12+E12+F12 -> 19769.1 | H12: =G12/shares -> 85.211638 | I12: =H12/price-1 -> 0.57740907
B13: =Inputs!B51 -> Bull | C13: =Inputs!C51 -> 16 | D13: =C13*$C$4 -> 25632 | E13: =cash -> 1675.8 | F13: =-debt -> -1130.7 | G13: =D13+E13+F13 -> 26177.1 | H13: =G13/shares -> 112.83233 | I13: =H13/price-1 -> 1.088714
B15: Compare the current multiple (C5) and the multiple implied by the DCF (C6) with the bands.
