Workbook

Sheet Cover
B1: Apple Inc. (NASDAQ: AAPL) — DCF valuation
B2: Unlevered DCF with Base / Bull / Bear scenarios, perpetuity-growth and exit-multiple terminal values, reverse DCF. Not investment advice.
B4: Prepared by | C4: Jung Ryul Lee
B5: Data as of | C5: Market data 2 Oct 2026 close; balance sheet 27 Jun 2026 (Q3 FY2026 10-Q)
B6: Units | C6: US$ millions except per share
B8: What this model does
B9: Rebuilds FY2023–9M FY2026 from Apple's filings and bridges to FY2026E with a Q4 estimate from management guidance.
B10: Forecasts products and services separately (growth, gross margin) for FY2027E–FY2031E under three scenarios.
B11: Values the unlevered free cash flow two ways and asks what the share price implies (reverse DCF).
B13: Key outputs (live links)
B14: Scenario | C14: =Summary!C5 -> Base
B15: Value per share — perpetuity growth ($) | C15: =Summary!C12 -> 151.35218
B16: Value per share — exit multiple ($) | C16: =Summary!C13 -> 233.80195
B17: Blended value per share ($) | C17: =Summary!C14 -> 192.57706
B18: Share price, 2 Oct 2026 ($) | C18: =Summary!C15 -> 333.69
B19: Upside / (downside), blended | C19: =Summary!C16 -> -0.42288633
B20: WACC | C20: =Summary!C6 -> 0.099181852
B21: Market-implied perpetuity growth (reverse DCF) | C21: =Summary!C18 -> 0.072573915
B22: Sensitivity checks (should be 0) | C22: =Sensitivity!C32+Sensitivity!C33 -> 0
B24: Contents
B25: Summary | C25: Outputs, colour legend, how to use, sources
B26: Historical | C26: FY2023A–FY2025A, 9M FY2026A and the Q4 FY2026E bridge
B27: Assumptions | C27: Scenario switch (C3) and Base / Bull / Bear drivers with rationale
B28: WACC | C28: CAPM, cost of debt, diluted shares, net cash
B29: DCF | C29: FCFF build, mid-year discounting, two terminal values, equity bridge, reverse DCF
B30: Sensitivity | C30: Value and upside across WACC × g and WACC × exit multiple, with checks
B32: Colour code
B33: 1,234 Blue text: hard-coded input
B34: 1,234 Black text: formula
B35: 1,234 Green text: link to another sheet
B36: Shaded yellow: key assumption to flex
B37: Shaded green: key output
B39: Method notes and limitations
B40: • Q4 FY2026 is an estimate from guidance; Apple reports FY2026 around the end of October 2026 — overwrite Assumptions rows 53–62 then.
B41: • Stock-based compensation is treated as a real cost (not added back to free cash flow).
B42: • Explicit cash flows use mid-year timing from the valuation date; the terminal value is discounted from end-FY2031.
B43: • At the 2 Oct 2026 price the market implies ~7% perpetual growth at this WACC: the gap to the DCF is the market's growth expectation.
B45: Review log (changes in this published version)
... B50: Built from public information for training and portfolio purposes. Not investment advice and not a recommendation to buy or sell any security. Figures marked approximate should be checked against the original filings.

Sheet Summary
A1: Apple Inc. (NASDAQ: AAPL) — DCF valuation
A2: Prepared 5 Oct 2026. USD millions except per-share data.
A4: Output | C4: Value
A5: Scenario | C5: =Assumptions!D3 -> Base
A6: WACC | C6: =WACC!C33 -> 0.099181852
A7: Terminal growth | C7: =DCF!C31 -> 0.03
A8: Exit EV/EBITDA multiple | C8: =DCF!C32 -> 20
A10: Enterprise value — perpetuity growth ($mm) | C10: =DCF!C46 -> 2157789.4
A11: Enterprise value — exit multiple ($mm) | C11: =DCF!D46 -> 3367123.9
A12: Value per share — perpetuity growth ($) | C12: =DCF!C51 -> 151.35218
A13: Value per share — exit multiple ($) | C13: =DCF!D51 -> 233.80195
A14: Blended value per share (50/50) ($) | C14: =AVERAGE(C12:C13) -> 192.57706
A15: Current share price, 2 Oct 2026 ($) | C15: =WACC!C14 -> 333.69
A16: Upside / (downside) — blended | C16: =C14/C15-1 -> -0.42288633
A18: Market-implied perpetuity growth (reverse DCF) | C18: =DCF!C61 -> 0.072573915
A19: FY2026E revenue ($mm) | C19: =Historical!H7 -> 477069.6
A20: FY2031E revenue ($mm) | C20: =DCF!H9 -> 613838.04
A21: FY2031E EBIT margin | C21: =DCF!H18 -> 0.33398887
A23: Colour legend
A24: Blue text | C24: Hard-coded input — edit these
A25: Black text | C25: Formula
A26: Green text | C26: Link from another tab
A27: Light-yellow fill | C27: Key assumption
A28: Grey fill | C28: Estimate (Q4 FY2026E bridge)
A29: Green fill | C29: Key output
A31: How to use
A32: Switch Base / Bull / Bear in Assumptions!C3. Edit WACC inputs on the WACC tab and terminal inputs in DCF!C31:C32.
A33: Q4 FY2026E is an estimate from guidance; when Apple reports (~29 Oct 2026), overwrite the Q4 drivers on Assumptions (rows 53–62).
A34: SBC is treated as a real cost (not added back). Terminal value is discounted from end-FY2031; explicit cash flows use mid-year timing.
A36: Sources
A37: Apple Q4 FY2025 8-K Ex. 99.1 — https://www.sec.gov/Archives/edgar/data/320193/000032019325000077/a8-kex991q4202509272025.htm
A38: Apple Q3 FY2026 8-K Ex. 99.1 — https://www.sec.gov/Archives/edgar/data/320193/000032019326000018/a8-kex991q3202606272026.htm
A39: Apple FY2025 Form 10-K — https://s2.q4cdn.com/470004039/files/doc_financials/2025/ar/_10-K-2025-As-Filed.pdf
A40: Q3 FY2026 call guidance (rev +9–11%, GM 47–48%, opex $19.1–19.4B) — https://www.fool.com/earnings/call-transcripts/2026/08/07/apple-aapl-q3-2026-earnings-call-transcript/
A41: AAPL price & beta — https://www.cnbc.com/quotes/AAPL ; 10Y UST 5.28% (2 Oct 2026) — https://www.cnbc.com/2026/10/02/treasury-yields-bonds-nonfarm-payrolls.html

Sheet Historical
A1: Apple Inc. (AAPL) — Historical financials & FY2026E bridge
A2: USD millions, fiscal years end late September. FY2026 = 9M reported actuals + Q4 estimate from management guidance (FY2026 results due ~29 Oct 2026).
A4: USD mm | B4: FY2023A | C4: FY2024A | D4: FY2025A | E4: Q4 FY2025A | F4: 9M FY2026A | G4: Q4 FY2026E | H4: FY2026E
A5: Products revenue | B5: 298085 | C5: 294866 | D5: 307003 | E5: 73716 | F5: 272629 | G5: =G7-G6 -> 81087.6 | H5: =F5+G5 -> 353716.6
A6: Services revenue | B6: 85200 | C6: 96169 | D6: 109158 | E6: 28750 | F6: 91728 | G6: =E6*(1+Assumptions!$C$54) -> 31625 | H6: =F6+G6 -> 123353
A7: Total revenue | B7: =B5+B6 -> 383285 | C7: =C5+C6 -> 391035 | D7: =D5+D6 -> 416161 | E7: =E5+E6 -> 102466 | F7: =F5+F6 -> 364357 | G7: =E7*(1+Assumptions!$C$53) -> 112712.6 | H7: =H5+H6 -> 477069.6
A8: Products cost of sales | B8: 189282 | C8: 185233 | D8: 194116 | E8: 47019 | F8: 163810 | G8: =G10-G9 -> 51425.99 | H8: =F8+G8 -> 215235.99
A9: Services cost of sales | B9: 24855 | C9: 25119 | D9: 26844 | E9: 7106 | F9: 21765 | G9: =G6*(1-Assumptions!$C$56) -> 7748.125 | H9: =F9+G9 -> 29513.125
A10: Total cost of sales | B10: =B8+B9 -> 214137 | C10: =C8+C9 -> 210352 | D10: =D8+D9 -> 220960 | E10: =E8+E9 -> 54125 | F10: =F8+F9 -> 185575 | G10: =G7*(1-Assumptions!$C$55) -> 59174.115 | H10: =H8+H9 -> 244749.11
A11: Products gross profit | B11: =B5-B8 -> 108803 | C11: =C5-C8 -> 109633 | D11: =D5-D8 -> 112887 | E11: =E5-E8 -> 26697 | F11: =F5-F8 -> 108819 | G11: =G5-G8 -> 29661.61 | H11: =H5-H8 -> 138480.61
A12: Services gross profit | B12: =B6-B9 -> 60345 | C12: =C6-C9 -> 71050 | D12: =D6-D9 -> 82314 | E12: =E6-E9 -> 21644 | F12: =F6-F9 -> 69963 | G12: =G6-G9 -> 23876.875 | H12: =H6-H9 -> 93839.875
A13: Gross profit | B13: =B7-B10 -> 169148 | C13: =C7-C10 -> 180683 | D13: =D7-D10 -> 195201 | E13: =E7-E10 -> 48341 | F13: =F7-F10 -> 178782 | G13: =G7-G10 -> 53538.485 | H13: =H7-H10 -> 232320.48
A14: Research & development | B14: 29915 | C14: 31370 | D14: 34550 | E14: 8866 | F14: 34035 | G14: =Assumptions!$C$57*F14/F16 -> 11626.863 | H14: =F14+G14 -> 45661.863
A15: Selling, general & administrative | B15: 24932 | C15: 26097 | D15: 27601 | E15: 7048 | F15: 22315 | G15: =Assumptions!$C$57-G14 -> 7623.1366 | H15: =F15+G15 -> 29938.137
A16: Total operating expenses | B16: =B14+B15 -> 54847 | C16: =C14+C15 -> 57467 | D16: =D14+D15 -> 62151 | E16: =E14+E15 -> 15914 | F16: =F14+F15 -> 56350 | G16: =G14+G15 -> 19250 | H16: =H14+H15 -> 75600
A17: Operating income (EBIT) | B17: =B13-B16 -> 114301 | C17: =C13-C16 -> 123216 | D17: =D13-D16 -> 133050 | E17: =E13-E16 -> 32427 | F17: =F13-F16 -> 122432 | G17: =G13-G16 -> 34288.485 | H17: =H13-H16 -> 156720.48
A18: Other income/(expense), net | B18: -565 | C18: 269 | D18: -321 | E18: 377 | F18: 670 | G18: =Assumptions!$C$58 -> 0 | H18: =F18+G18 -> 670
A19: Pre-tax income | B19: =B17+B18 -> 113736 | C19: =C17+C18 -> 123485 | D19: =D17+D18 -> 132729 | E19: =E17+E18 -> 32804 | F19: =F17+F18 -> 123102 | G19: =G17+G18 -> 34288.485 | H19: =H17+H18 -> 157390.48
A20: Provision for income taxes | B20: 16741 | C20: 29749 | D20: 20719 | E20: 5338 | F20: 21638 | G20: =G19*Assumptions!$C$59 -> 6000.4849 | H20: =F20+G20 -> 27638.485
A21: Net income | B21: =B19-B20 -> 96995 | C21: =C19-C20 -> 93736 | D21: =D19-D20 -> 112010 | E21: =E19-E20 -> 27466 | F21: =F19-F20 -> 101464 | G21: =G19-G20 -> 28288 | H21: =H19-H20 -> 129752
A23: Depreciation & amortization | B23: 11519 | C23: 11445 | D23: 11698 | E23: n/a | F23: 9973 | G23: =Assumptions!$C$60 -> 3400 | H23: =F23+G23 -> 13373
A24: Share-based compensation | B24: 10833 | C24: 11688 | D24: 12863 | E24: n/a | F24: 10523 | G24: =Assumptions!$C$61 -> 3500 | H24: =F24+G24 -> 14023
A25: Capital expenditures | B25: 10959 | C25: 9447 | D25: 12715 | E25: 3242 | F25: 6799 | G25: =Assumptions!$C$62 -> 3500 | H25: =F25+G25 -> 10299
A26: Cash from operations | B26: 110543 | C26: 118254 | D26: 111482 | E26: n/a | F26: 116996 | G26: n/a | H26: n/a
A28: Ratios
A29: Total revenue growth (YoY) | C29: =C7/B7-1 -> 0.020219941 | D29: =D7/C7-1 -> 0.064255118 | E29: =E7/94930-1 -> 0.07938481 | F29: =F7/(D7-E7)-1 -> 0.16150082 | G29: =G7/E7-1 -> 0.1 | H29: =H7/D7-1 -> 0.14635826
A30: Products revenue growth | C30: =C5/B5-1 -> -0.010798933 | D30: =D5/C5-1 -> 0.04116107 | E30: =E5/69958-1 -> 0.053717945 | F30: =F5/(D5-E5)-1 -> 0.16864206 | G30: =G5/E5-1 -> 0.1 | H30: =H5/D5-1 -> 0.15216008
A31: Services revenue growth | C31: =C6/B6-1 -> 0.12874413 | D31: =D6/C6-1 -> 0.13506431 | E31: =E6/24972-1 -> 0.15128944 | F31: =F6/(D6-E6)-1 -> 0.14078201 | G31: =G6/E6-1 -> 0.1 | H31: =H6/D6-1 -> 0.13004086
A32: Products gross margin | B32: =B11/B5 -> 0.36500663 | C32: =C11/C5 -> 0.37180618 | D32: =D11/D5 -> 0.3677065 | E32: =E11/E5 -> 0.36216018 | F32: =F11/F5 -> 0.39914683 | G32: =G11/G5 -> 0.36579711 | H32: =H11/H5 -> 0.39150159
A33: Services gross margin | B33: =B12/B6 -> 0.70827465 | C33: =C12/C6 -> 0.73880356 | D33: =D12/D6 -> 0.75408124 | E33: =E12/E6 -> 0.75283478 | F33: =F12/F6 -> 0.7627224 | G33: =G12/G6 -> 0.755 | H33: =H12/H6 -> 0.76074254
A34: Gross margin | B34: =B13/B7 -> 0.4413113 | C34: =C13/C7 -> 0.4620635 | D34: =D13/D7 -> 0.46905164 | E34: =E13/E7 -> 0.471776 | F34: =F13/F7 -> 0.4906781 | G34: =G13/G7 -> 0.475 | H34: =H13/H7 -> 0.48697399
A35: R&D % revenue | B35: =B14/B7 -> 0.078048971 | C35: =C14/C7 -> 0.080222998 | D35: =D14/D7 -> 0.083020754 | E35: =E14/E7 -> 0.086526262 | F35: =F14/F7 -> 0.093411132 | G35: =G14/G7 -> 0.10315496 | H35: =H14/H7 -> 0.095713211
A36: SG&A % revenue | B36: =B15/B7 -> 0.065048202 | C36: =C15/C7 -> 0.066738272 | D36: =D15/D7 -> 0.066322889 | E36: =E15/E7 -> 0.068783792 | F36: =F15/F7 -> 0.061244878 | G36: =G15/G7 -> 0.067633403 | H36: =H15/H7 -> 0.062754233
A37: EBIT margin | B37: =B17/B7 -> 0.29821412 | C37: =C17/C7 -> 0.31510223 | D37: =D17/D7 -> 0.319708 | E37: =E17/E7 -> 0.31646595 | F37: =F17/F7 -> 0.33602209 | G37: =G17/G7 -> 0.30421164 | H37: =H17/H7 -> 0.32850654
A38: Effective tax rate | B38: =B20/B19 -> 0.14719174 | C38: =C20/C19 -> 0.24091185 | D38: =D20/D19 -> 0.15610002 | E38: =E20/E19 -> 0.16272406 | F38: =F20/F19 -> 0.17577294 | G38: =G20/G19 -> 0.175 | H38: =H20/H19 -> 0.17560455
A39: D&A % revenue | B39: =B23/B7 -> 0.030053355 | C39: =C23/C7 -> 0.02926848 | D39: =D23/D7 -> 0.028109313 | F39: =F23/F7 -> 0.027371507 | G39: =G23/G7 -> 0.030165217 | H39: =H23/H7 -> 0.028031549
A40: Capex % revenue | B40: =B25/B7 -> 0.028592301 | C40: =C25/C7 -> 0.024158963 | D40: =D25/D7 -> 0.030553079 | E40: =E25/E7 -> 0.031639763 | F40: =F25/F7 -> 0.01866027 | G40: =G25/G7 -> 0.031052429 | H40: =H25/H7 -> 0.021588045
A41: SBC % revenue | B41: =B24/B7 -> 0.028263564 | C41: =C24/C7 -> 0.029889908 | D41: =D24/D7 -> 0.030908711 | F41: =F24/F7 -> 0.028881015 | G41: =G24/G7 -> 0.031052429 | H41: =H24/H7 -> 0.029394034
A42: Services % of revenue | B42: =B6/B7 -> 0.2222889 | C42: =C6/C7 -> 0.24593451 | D42: =D6/D7 -> 0.26229752 | E42: =E6/E7 -> 0.28058088 | F42: =F6/F7 -> 0.25175309 | G42: =G6/G7 -> 0.28058088 | H42: =H6/H7 -> 0.25856395
A44: Notes & sources
...

Sheet Assumptions
A1: Forecast assumptions — FY2027E to FY2031E
A2: Blue = input. Change the scenario number in C3; every 'Live' row (and the whole model) follows it.
A3: Scenario (1 = Base, 2 = Bull, 3 = Bear) | C3: 1 | D3: =CHOOSE($C$3,"Base","Bull","Bear") -> Base
A5: Driver | C5: Case | D5: FY2027E | E5: FY2028E | F5: FY2029E | G5: FY2030E | H5: FY2031E | I5: Rationale
A6: Products revenue growth | C6: Base | D6: 0.05 | E6: 0.04 | F6: 0.035 | G6: 0.03 | H6: 0.03 | I6: FY2026E products ~+15% on the iPhone 17 cycle; base assumes normalisation toward installed-base growth plus pricing. Bear: post-supercycle digestion.
C7: Bull | D7: 0.08 | E7: 0.06 | F7: 0.05 | G7: 0.045 | H7: 0.04
C8: Bear | D8: 0.01 | E8: 0.02 | F8: 0.02 | G8: 0.02 | H8: 0.02
C9: Live | D9: =CHOOSE($C$3,D6,D7,D8) -> 0.05 | E9: =CHOOSE($C$3,E6,E7,E8) -> 0.04 | F9: =CHOOSE($C$3,F6,F7,F8) -> 0.035 | G9: =CHOOSE($C$3,G6,G7,G8) -> 0.03 | H9: =CHOOSE($C$3,H6,H7,H8) -> 0.03
A11: Services revenue growth | C11: Base | D11: 0.11 | E11: 0.1 | F11: 0.09 | G11: 0.08 | H11: 0.07 | I11: Services grew 13.5% in FY2025 and ~12% in Q3 FY2026. Bear reflects App Store rule changes / search-deal risk.
C12: Bull | D12: 0.13 | E12: 0.12 | F12: 0.11 | G12: 0.1 | H12: 0.09
C13: Bear | D13: 0.08 | E13: 0.07 | F13: 0.06 | G13: 0.05 | H13: 0.05
C14: Live | D14: =CHOOSE($C$3,D11,D12,D13) -> 0.11 | E14: =CHOOSE($C$3,E11,E12,E13) -> 0.1 | F14: =CHOOSE($C$3,F11,F12,F13) -> 0.09 | G14: =CHOOSE($C$3,G11,G12,G13) -> 0.08 | H14: =CHOOSE($C$3,H11,H12,H13) -> 0.07
A16: Products gross margin | C16: Base | D16: 0.36 | E16: 0.365 | F16: 0.37 | G16: 0.37 | H16: 0.37 | I16: FY2025 36.8%. Mgmt flagged memory-cost inflation compressing margin into Sep-26 qtr; tariff refunds are non-recurring.
C17: Bull | D17: 0.375 | E17: 0.38 | F17: 0.38 | G17: 0.385 | H17: 0.385
C18: Bear | D18: 0.345 | E18: 0.35 | F18: 0.355 | G18: 0.355 | H18: 0.355
C19: Live | D19: =CHOOSE($C$3,D16,D17,D18) -> 0.36 | E19: =CHOOSE($C$3,E16,E17,E18) -> 0.365 | F19: =CHOOSE($C$3,F16,F17,F18) -> 0.37 | G19: =CHOOSE($C$3,G16,G17,G18) -> 0.37 | H19: =CHOOSE($C$3,H16,H17,H18) -> 0.37
A21: Services gross margin | C21: Base | D21: 0.755 | E21: 0.755 | F21: 0.755 | G21: 0.755 | H21: 0.755 | I21: FY2025 75.4%; 9M FY2026 76.3%.
C22: Bull | D22: 0.765 | E22: 0.765 | F22: 0.765 | G22: 0.765 | H22: 0.765
C23: Bear | D23: 0.735 | E23: 0.735 | F23: 0.735 | G23: 0.735 | H23: 0.735
C24: Live | D24: =CHOOSE($C$3,D21,D22,D23) -> 0.755 | E24: =CHOOSE($C$3,E21,E22,E23) -> 0.755 | F24: =CHOOSE($C$3,F21,F22,F23) -> 0.755 | G24: =CHOOSE($C$3,G21,G22,G23) -> 0.755 | H24: =CHOOSE($C$3,H21,H22,H23) -> 0.755
A26: R&D % revenue | C26: Base | D26: 0.095 | E26: 0.095 | F26: 0.095 | G26: 0.095 | H26: 0.095 | I26: FY2025 8.3%, FY2026E ~9.6% (AI investment; R&D +32% YoY in 9M FY2026).
C27: Bull | D27: 0.09 | E27: 0.09 | F27: 0.09 | G27: 0.09 | H27: 0.09
C28: Bear | D28: 0.1 | E28: 0.1 | F28: 0.1 | G28: 0.1 | H28: 0.1
C29: Live | D29: =CHOOSE($C$3,D26,D27,D28) -> 0.095 | E29: =CHOOSE($C$3,E26,E27,E28) -> 0.095 | F29: =CHOOSE($C$3,F26,F27,F28) -> 0.095 | G29: =CHOOSE($C$3,G26,G27,G28) -> 0.095 | H29: =CHOOSE($C$3,H26,H27,H28) -> 0.095
A31: SG&A % revenue | C31: Base | D31: 0.06 | E31: 0.06 | F31: 0.06 | G31: 0.06 | H31: 0.06 | I31: FY2025 6.6%; FY2026E ~6.2% on operating leverage.
C32: Bull | D32: 0.058 | E32: 0.058 | F32: 0.058 | G32: 0.058 | H32: 0.058
C33: Bear | D33: 0.063 | E33: 0.063 | F33: 0.063 | G33: 0.063 | H33: 0.063
C34: Live | D34: =CHOOSE($C$3,D31,D32,D33) -> 0.06 | E34: =CHOOSE($C$3,E31,E32,E33) -> 0.06 | F34: =CHOOSE($C$3,F31,F32,F33) -> 0.06 | G34: =CHOOSE($C$3,G31,G32,G33) -> 0.06 | H34: =CHOOSE($C$3,H31,H32,H33) -> 0.06
A36: Effective tax rate | C36: Base | D36: 0.17 | E36: 0.17 | F36: 0.17 | G36: 0.17 | H36: 0.17 | I36: FY2025 15.6%, 9M FY2026 17.6%. Bear allows for global minimum tax / US tax changes.
C37: Bull | D37: 0.16 | E37: 0.16 | F37: 0.16 | G37: 0.16 | H37: 0.16
C38: Bear | D38: 0.19 | E38: 0.19 | F38: 0.19 | G38: 0.19 | H38: 0.19
C39: Live | D39: =CHOOSE($C$3,D36,D37,D38) -> 0.17 | E39: =CHOOSE($C$3,E36,E37,E38) -> 0.17 | F39: =CHOOSE($C$3,F36,F37,F38) -> 0.17 | G39: =CHOOSE($C$3,G36,G37,G38) -> 0.17 | H39: =CHOOSE($C$3,H36,H37,H38) -> 0.17
A41: Capex % revenue | C41: Base | D41: 0.03 | E41: 0.03 | F41: 0.03 | G41: 0.03 | H41: 0.03 | I41: FY2025 3.1%. Bear assumes heavier AI/data-centre build.
C42: Bull | D42: 0.028 | E42: 0.028 | F42: 0.028 | G42: 0.028 | H42: 0.028
C43: Bear | D43: 0.035 | E43: 0.035 | F43: 0.035 | G43: 0.035 | H43: 0.035
C44: Live | D44: =CHOOSE($C$3,D41,D42,D43) -> 0.03 | E44: =CHOOSE($C$3,E41,E42,E43) -> 0.03 | F44: =CHOOSE($C$3,F41,F42,F43) -> 0.03 | G44: =CHOOSE($C$3,G41,G42,G43) -> 0.03 | H44: =CHOOSE($C$3,H41,H42,H43) -> 0.03
A46: Scenario-independent drivers
A47: D&A % revenue | D47: 0.028 | E47: 0.028 | F47: 0.028 | G47: 0.028 | H47: 0.028 | I47: FY2023–25 averaged ~2.9%.
A48: Net working capital investment % of Δrevenue | D48: 0.02 | E48: 0.02 | F48: 0.02 | G48: 0.02 | H48: 0.02 | I48: Apple runs negative NWC; a small positive % keeps cash conversion conservative. Set 0% to assume growth is self-funding.
A51: Q4 FY2026E bridge (Sep-2026 quarter, not yet reported)
...

Sheet WACC
A1: Discount rate & capital structure
A2: Market data as of 2 Oct 2026 close; balance sheet as of 27 Jun 2026 (latest 10-Q).
A3: Item | C3: Value | D3: Source / note
A4: Risk-free rate (10Y UST) | C4: 0.0528 | D4: US Treasury 10Y par yield, 2 Oct 2026 (5.28%) — highest area since 2002.
A5: Equity beta | C5: 1.05 | D5: Published betas range 0.83 (TradingView) to 1.08 (CNBC); 1.05 assumed. Adjust as needed.
A6: Equity risk premium | C6: 0.045 | D6: Assumption.
A7: Cost of equity | C7: =C4+C5*C6 -> 0.10005 | D7: CAPM
A9: Credit spread over UST | C9: 0.006 | D9: Assumption for AA+ / Aaa-rated issuer.
A10: Pre-tax cost of debt | C10: =C4+C9 -> 0.0588
A11: Tax rate | C11: =Assumptions!D39 -> 0.17 | D11: FY2027E live-scenario tax rate
A12: After-tax cost of debt | C12: =C10*(1-C11) -> 0.048804
A14: Share price ($) | C14: 333.69 | D14: AAPL close 2 Oct 2026 (Nasdaq).
A15: Basic shares outstanding (mm) | C15: 14608.963 | D15: Balance sheet, 27 Jun 2026: 14,608,963k shares.
A16: Dilutive securities (mm) | C16: 58.566 | D16: Q3 FY2026 diluted less basic weighted shares (14,714.7 – 14,656.1).
A17: Diluted shares (mm) | C17: =C15+C16 -> 14667.529
A18: Market capitalisation ($mm) | C18: =C14*C17 -> 4894407.8
A20: Commercial paper | C20: 1997 | D20: 10-Q balance sheet, 27 Jun 2026.
A21: Term debt — current | C21: 11007 | D21: 10-Q balance sheet, 27 Jun 2026.
A22: Term debt — non-current | C22: 71340 | D22: 10-Q balance sheet, 27 Jun 2026.
A23: Total debt | C23: =SUM(C20:C22) -> 84344
A25: Cash & cash equivalents | C25: 39544 | D25: 10-Q balance sheet, 27 Jun 2026.
A26: Marketable securities — current | C26: 22855 | D26: 10-Q balance sheet, 27 Jun 2026.
A27: Marketable securities — non-current | C27: 84118 | D27: 10-Q balance sheet, 27 Jun 2026.
A28: Total cash & investments | C28: =SUM(C25:C27) -> 146517
A29: Net cash / (net debt) | C29: =C28-C23 -> 62173 | D29: Positive = net cash.
A31: Equity weight | C31: =C18/(C18+C23) -> 0.98305921 | D31: Market-value weights
A32: Debt weight | C32: =C23/(C18+C23) -> 0.016940792
A33: WACC | C33: =C31*C7+C32*C12 -> 0.099181852

Sheet DCF
A1: Unlevered free cash flow DCF
A2: USD millions except per-share. FY2026E is the base year (reported 9M + Q4E); explicit forecast FY2027E–FY2031E.
A4: USD mm | C4: FY2026E | D4: FY2027E | E4: FY2028E | F4: FY2029E | G4: FY2030E | H4: FY2031E
A5: Fiscal year end | C5: 46291 | D5: 46655 | E5: 47026 | F5: 47390 | G5: 47754 | H5: 48118
A7: Products revenue | C7: =Historical!H5 -> 353716.6 | D7: =C7*(1+Assumptions!D9) -> 371402.43 | E7: =D7*(1+Assumptions!E9) -> 386258.53 | F7: =E7*(1+Assumptions!F9) -> 399777.58 | G7: =F7*(1+Assumptions!G9) -> 411770.9 | H7: =G7*(1+Assumptions!H9) -> 424124.03
A8: Services revenue | C8: =Historical!H6 -> 123353 | D8: =C8*(1+Assumptions!D14) -> 136921.83 | E8: =D8*(1+Assumptions!E14) -> 150614.01 | F8: =E8*(1+Assumptions!F14) -> 164169.27 | G8: =F8*(1+Assumptions!G14) -> 177302.82 | H8: =G8*(1+Assumptions!H14) -> 189714.01
A9: Total revenue | C9: =C7+C8 -> 477069.6 | D9: =D7+D8 -> 508324.26 | E9: =E7+E8 -> 536872.54 | F9: =F7+F8 -> 563946.85 | G9: =G7+G8 -> 589073.72 | H9: =H7+H8 -> 613838.04
A10: Growth % | C10: =Historical!H29 -> 0.14635826 | D10: =D9/C9-1 -> 0.065513837 | E10: =E9/D9-1 -> 0.056161554 | F10: =F9/E9-1 -> 0.050429679 | G10: =G9/F9-1 -> 0.044555385 | H10: =H9/G9-1 -> 0.042039431
A11: Products gross profit | C11: =Historical!H11 -> 138480.61 | D11: =D7*Assumptions!D19 -> 133704.87 | E11: =E7*Assumptions!E19 -> 140984.36 | F11: =F7*Assumptions!F19 -> 147917.7 | G11: =G7*Assumptions!G19 -> 152355.23 | H11: =H7*Assumptions!H19 -> 156925.89
A12: Services gross profit | C12: =Historical!H12 -> 93839.875 | D12: =D8*Assumptions!D24 -> 103375.98 | E12: =E8*Assumptions!E24 -> 113713.58 | F12: =F8*Assumptions!F24 -> 123947.8 | G12: =G8*Assumptions!G24 -> 133863.63 | H12: =H8*Assumptions!H24 -> 143234.08
A13: Gross profit | C13: =C11+C12 -> 232320.48 | D13: =D11+D12 -> 237080.86 | E13: =E11+E12 -> 254697.94 | F13: =F11+F12 -> 271865.5 | G13: =G11+G12 -> 286218.86 | H13: =H11+H12 -> 300159.97
A14: Gross margin % | C14: =C13/C9 -> 0.48697399 | D14: =D13/D9 -> 0.46639689 | E14: =E13/E9 -> 0.47441045 | F14: =F13/F9 -> 0.48207647 | G14: =G13/G9 -> 0.48587953 | H14: =H13/H9 -> 0.48898887
A15: Research & development | C15: =Historical!H14 -> 45661.863 | D15: =D9*Assumptions!D29 -> 48290.805 | E15: =E9*Assumptions!E29 -> 51002.891 | F15: =F9*Assumptions!F29 -> 53574.951 | G15: =G9*Assumptions!G29 -> 55962.003 | H15: =H9*Assumptions!H29 -> 58314.614
A16: SG&A | C16: =Historical!H15 -> 29938.137 | D16: =D9*Assumptions!D34 -> 30499.456 | E16: =E9*Assumptions!E34 -> 32212.352 | F16: =F9*Assumptions!F34 -> 33836.811 | G16: =G9*Assumptions!G34 -> 35344.423 | H16: =H9*Assumptions!H34 -> 36830.283
A17: EBIT | C17: =C13-C15-C16 -> 156720.48 | D17: =D13-D15-D16 -> 158290.6 | E17: =E13-E15-E16 -> 171482.7 | F17: =F13-F15-F16 -> 184453.74 | G17: =G13-G15-G16 -> 194912.43 | H17: =H13-H15-H16 -> 205015.07
A18: EBIT margin % | C18: =C17/C9 -> 0.32850654 | D18: =D17/D9 -> 0.31139689 | E18: =E17/E9 -> 0.31941045 | F18: =F17/F9 -> 0.32707647 | G18: =G17/G9 -> 0.33087953 | H18: =H17/H9 -> 0.33398887
A19: Taxes on EBIT | D19: =D17*Assumptions!D39 -> 26909.401 | E19: =E17*Assumptions!E39 -> 29152.059 | F19: =F17*Assumptions!F39 -> 31357.136 | G19: =G17*Assumptions!G39 -> 33135.114 | H19: =H17*Assumptions!H39 -> 34852.563
A20: NOPAT | D20: =D17-D19 -> 131381.19 | E20: =E17-E19 -> 142330.64 | F20: =F17-F19 -> 153096.61 | G20: =G17-G19 -> 161777.32 | H20: =H17-H19 -> 170162.51
A21: (+) D&A | C21: =Historical!H23 -> 13373 | D21: =D9*Assumptions!D47 -> 14233.079 | E21: =E9*Assumptions!E47 -> 15032.431 | F21: =F9*Assumptions!F47 -> 15790.512 | G21: =G9*Assumptions!G47 -> 16494.064 | H21: =H9*Assumptions!H47 -> 17187.465
A22: (–) Capex | C22: =Historical!H25 -> 10299 | D22: =D9*Assumptions!D44 -> 15249.728 | E22: =E9*Assumptions!E44 -> 16106.176 | F22: =F9*Assumptions!F44 -> 16918.405 | G22: =G9*Assumptions!G44 -> 17672.212 | H22: =H9*Assumptions!H44 -> 18415.141
A23: (–) Increase in NWC | D23: =(D9-C9)*Assumptions!D48 -> 625.0932 | E23: =(E9-D9)*Assumptions!E48 -> 570.9656 | F23: =(F9-E9)*Assumptions!F48 -> 541.48619 | G23: =(G9-F9)*Assumptions!G48 -> 502.53738 | H23: =(H9-G9)*Assumptions!H48 -> 495.28648
A24: Unlevered free cash flow | D24: =D20+D21-D22-D23 -> 129739.45 | E24: =E20+E21-E22-E23 -> 140685.93 | F24: =F20+F21-F22-F23 -> 151427.23 | G24: =G20+G21-G22-G23 -> 160096.64 | H24: =H20+H21-H22-H23 -> 168439.55
A25: UFCF margin % | D25: =D24/D9 -> 0.25522971 | E25: =E24/E9 -> 0.26204717 | F25: =F24/F9 -> 0.2685133 | G25: =G24/G9 -> 0.27177691 | H25: =H24/H9 -> 0.27440389
A26: Memo: EBITDA | C26: =C17+C21 -> 170093.48 | D26: =D17+D21 -> 172523.68 | E26: =E17+E21 -> 186515.13 | F26: =F17+F21 -> 200244.26 | G26: =G17+G21 -> 211406.5 | H26: =H17+H21 -> 222202.54
A28: Valuation inputs
A29: Valuation date | C29: 46300
A30: Mid-year convention (1 = on, 0 = off) | C30: 1
A31: Terminal growth rate | C31: 0.03
A32: Exit EV / EBITDA multiple (FY2031E) | C32: 20
A33: WACC | C33: =WACC!C33 -> 0.099181852
A35: Years from valuation date to FY end | D35: =(D5-$C$29)/365.25 -> 0.97193703 | E35: =(E5-$C$29)/365.25 -> 1.9876797 | F35: =(F5-$C$29)/365.25 -> 2.9842574 | G35: =(G5-$C$29)/365.25 -> 3.980835 | H35: =(H5-$C$29)/365.25 -> 4.9774127
A36: Discount period | D36: =D35-0.5*$C$30 -> 0.47193703 | E36: =E35-0.5*$C$30 -> 1.4876797 | F36: =F35-0.5*$C$30 -> 2.4842574 | G36: =G35-0.5*$C$30 -> 3.480835 | H36: =H35-0.5*$C$30 -> 4.4774127
A37: Discount factor | D37: =1/(1+$C$33)^D36 -> 0.95635197 | E37: =1/(1+$C$33)^E36 -> 0.8687637 | F37: =1/(1+$C$33)^F36 -> 0.79062887 | G37: =1/(1+$C$33)^G36 -> 0.71952133 | H37: =1/(1+$C$33)^H36 -> 0.65480906
A38: PV of UFCF | D38: =D24*D37 -> 124076.58 | E38: =E24*E37 -> 122222.83 | F38: =F24*F37 -> 119722.74 | G38: =G24*G37 -> 115192.94 | H38: =H24*H37 -> 110295.74
A40: Valuation
C41: Perpetuity growth | D41: Exit multiple
A42: Sum of PV of UFCF (FY2027E–31E) | C42: =SUM(D38:H38) -> 591510.83 | D42: =SUM(D38:H38) -> 591510.83
A43: Terminal value at FY2031E | C43: =H24*(1+C31)/(C33-C31) -> 2507778.1 | D43: =H26*C32 -> 4444050.8
A44: Discount factor for TV (end FY2031E) | C44: =1/(1+C33)^H35 -> 0.62456825 | D44: =1/(1+C33)^H35 -> 0.62456825
A45: PV of terminal value | C45: =C43*C44 -> 1566278.6 | D45: =D43*D44 -> 2775613
...

Sheet Sensitivity
A1: Sensitivity analysis — implied value per share ($)
A2: Every cell re-runs the DCF with that WACC / terminal assumption (no data tables needed). Centre cell = base case.
A3: WACC step | C3: 0.005
A4: Terminal growth step | C4: 0.005
A5: Exit multiple step | C5: 2
A7: 1) Perpetuity-growth method: value per share
B8: WACC ↓ / terminal g → | C8: =DCF!$C$31+(-2)*$C$4 -> 0.02 | D8: =DCF!$C$31+(-1)*$C$4 -> 0.025 | E8: =DCF!$C$31+(0)*$C$4 -> 0.03 | F8: =DCF!$C$31+(1)*$C$4 -> 0.035 | G8: =DCF!$C$31+(2)*$C$4 -> 0.04
B9: =WACC!$C$33+(-2)*$C$3 -> 0.089181852 | C9: =(SUMPRODUCT(DCF!$D$24:$H$24,(1+$B9)^(-DCF!$D$36:$H$36))+DCF!$H$24*(1+C$8)/($B9-C$8)*(1+$B9)^(-DCF!$H$35)+WACC!$C$29)/WACC!$C$17 -> 156.14307 | D9: =(SUMPRODUCT(DCF!$D$24:$H$24,(1+$B9)^(-DCF!$D$36:$H$36))+DCF!$H$24*(1+D$8)/($B9-D$8)*(1+$B9)^(-DCF!$H$35)+WACC!$C$29)/WACC!$C$17 -> 165.34945 | E9: =(SUMPRODUCT(DCF!$D$24:$H$24,(1+$B9)^(-DCF!$D$36:$H$36))+DCF!$H$24*(1+E$8)/($B9-E$8)*(1+$B9)^(-DCF!$H$35)+WACC!$C$29)/WACC!$C$17 -> 176.11145 | F9: =(SUMPRODUCT(DCF!$D$24:$H$24,(1+$B9)^(-DCF!$D$36:$H$36))+DCF!$H$24*(1+F$8)/($B9-F$8)*(1+$B9)^(-DCF!$H$35)+WACC!$C$29)/WACC!$C$17 -> 188.85971 | G9: =(SUMPRODUCT(DCF!$D$24:$H$24,(1+$B9)^(-DCF!$D$36:$H$36))+DCF!$H$24*(1+G$8)/($B9-G$8)*(1+$B9)^(-DCF!$H$35)+WACC!$C$29)/WACC!$C$17 -> 204.20005
B10: =WACC!$C$33+(-1)*$C$3 -> 0.094181852 | C10: =(SUMPRODUCT(DCF!$D$24:$H$24,(1+$B10)^(-DCF!$D$36:$H$36))+DCF!$H$24*(1+C$8)/($B10-C$8)*(1+$B10)^(-DCF!$H$35)+WACC!$C$29)/WACC!$C$17 -> 145.89998 | D10: =(SUMPRODUCT(DCF!$D$24:$H$24,(1+$B10)^(-DCF!$D$36:$H$36))+DCF!$H$24*(1+D$8)/($B10-D$8)*(1+$B10)^(-DCF!$H$35)+WACC!$C$29)/WACC!$C$17 -> 153.72152 | E10: =(SUMPRODUCT(DCF!$D$24:$H$24,(1+$B10)^(-DCF!$D$36:$H$36))+DCF!$H$24*(1+E$8)/($B10-E$8)*(1+$B10)^(-DCF!$H$35)+WACC!$C$29)/WACC!$C$17 -> 162.76171 | F10: =(SUMPRODUCT(DCF!$D$24:$H$24,(1+$B10)^(-DCF!$D$36:$H$36))+DCF!$H$24*(1+F$8)/($B10-F$8)*(1+$B10)^(-DCF!$H$35)+WACC!$C$29)/WACC!$C$17 -> 173.32943 | G10: =(SUMPRODUCT(DCF!$D$24:$H$24,(1+$B10)^(-DCF!$D$36:$H$36))+DCF!$H$24*(1+G$8)/($B10-G$8)*(1+$B10)^(-DCF!$H$35)+WACC!$C$29)/WACC!$C$17 -> 185.84756
B11: =WACC!$C$33+(0)*$C$3 -> 0.099181852 | C11: =(SUMPRODUCT(DCF!$D$24:$H$24,(1+$B11)^(-DCF!$D$36:$H$36))+DCF!$H$24*(1+C$8)/($B11-C$8)*(1+$B11)^(-DCF!$H$35)+WACC!$C$29)/WACC!$C$17 -> 136.96026 | D11: =(SUMPRODUCT(DCF!$D$24:$H$24,(1+$B11)^(-DCF!$D$36:$H$36))+DCF!$H$24*(1+D$8)/($B11-D$8)*(1+$B11)^(-DCF!$H$35)+WACC!$C$29)/WACC!$C$17 -> 143.67119 | E11: =(SUMPRODUCT(DCF!$D$24:$H$24,(1+$B11)^(-DCF!$D$36:$H$36))+DCF!$H$24*(1+E$8)/($B11-E$8)*(1+$B11)^(-DCF!$H$35)+WACC!$C$29)/WACC!$C$17 -> 151.35218 | F11: =(SUMPRODUCT(DCF!$D$24:$H$24,(1+$B11)^(-DCF!$D$36:$H$36))+DCF!$H$24*(1+F$8)/($B11-F$8)*(1+$B11)^(-DCF!$H$35)+WACC!$C$29)/WACC!$C$17 -> 160.22991 | G11: =(SUMPRODUCT(DCF!$D$24:$H$24,(1+$B11)^(-DCF!$D$36:$H$36))+DCF!$H$24*(1+G$8)/($B11-G$8)*(1+$B11)^(-DCF!$H$35)+WACC!$C$29)/WACC!$C$17 -> 170.60772
B12: =WACC!$C$33+(1)*$C$3 -> 0.10418185 | C12: =(SUMPRODUCT(DCF!$D$24:$H$24,(1+$B12)^(-DCF!$D$36:$H$36))+DCF!$H$24*(1+C$8)/($B12-C$8)*(1+$B12)^(-DCF!$H$35)+WACC!$C$29)/WACC!$C$17 -> 129.09127 | D12: =(SUMPRODUCT(DCF!$D$24:$H$24,(1+$B12)^(-DCF!$D$36:$H$36))+DCF!$H$24*(1+D$8)/($B12-D$8)*(1+$B12)^(-DCF!$H$35)+WACC!$C$29)/WACC!$C$17 -> 134.89922 | E12: =(SUMPRODUCT(DCF!$D$24:$H$24,(1+$B12)^(-DCF!$D$36:$H$36))+DCF!$H$24*(1+E$8)/($B12-E$8)*(1+$B12)^(-DCF!$H$35)+WACC!$C$29)/WACC!$C$17 -> 141.4901 | F12: =(SUMPRODUCT(DCF!$D$24:$H$24,(1+$B12)^(-DCF!$D$36:$H$36))+DCF!$H$24*(1+F$8)/($B12-F$8)*(1+$B12)^(-DCF!$H$35)+WACC!$C$29)/WACC!$C$17 -> 149.03368 | G12: =(SUMPRODUCT(DCF!$D$24:$H$24,(1+$B12)^(-DCF!$D$36:$H$36))+DCF!$H$24*(1+G$8)/($B12-G$8)*(1+$B12)^(-DCF!$H$35)+WACC!$C$29)/WACC!$C$17 -> 157.75259
B13: =WACC!$C$33+(2)*$C$3 -> 0.10918185 | C13: =(SUMPRODUCT(DCF!$D$24:$H$24,(1+$B13)^(-DCF!$D$36:$H$36))+DCF!$H$24*(1+C$8)/($B13-C$8)*(1+$B13)^(-DCF!$H$35)+WACC!$C$29)/WACC!$C$17 -> 122.11259 | D13: =(SUMPRODUCT(DCF!$D$24:$H$24,(1+$B13)^(-DCF!$D$36:$H$36))+DCF!$H$24*(1+D$8)/($B13-D$8)*(1+$B13)^(-DCF!$H$35)+WACC!$C$29)/WACC!$C$17 -> 127.17745 | E13: =(SUMPRODUCT(DCF!$D$24:$H$24,(1+$B13)^(-DCF!$D$36:$H$36))+DCF!$H$24*(1+E$8)/($B13-E$8)*(1+$B13)^(-DCF!$H$35)+WACC!$C$29)/WACC!$C$17 -> 132.88197 | F13: =(SUMPRODUCT(DCF!$D$24:$H$24,(1+$B13)^(-DCF!$D$36:$H$36))+DCF!$H$24*(1+F$8)/($B13-F$8)*(1+$B13)^(-DCF!$H$35)+WACC!$C$29)/WACC!$C$17 -> 139.35547 | G13: =(SUMPRODUCT(DCF!$D$24:$H$24,(1+$B13)^(-DCF!$D$36:$H$36))+DCF!$H$24*(1+G$8)/($B13-G$8)*(1+$B13)^(-DCF!$H$35)+WACC!$C$29)/WACC!$C$17 -> 146.76469
A15: 2) Perpetuity-growth method: upside / (downside) vs current price
B16: WACC ↓ / terminal g → | C16: =DCF!$C$31+(-2)*$C$4 -> 0.02 | D16: =DCF!$C$31+(-1)*$C$4 -> 0.025 | E16: =DCF!$C$31+(0)*$C$4 -> 0.03 | F16: =DCF!$C$31+(1)*$C$4 -> 0.035 | G16: =DCF!$C$31+(2)*$C$4 -> 0.04
B17: =WACC!$C$33+(-2)*$C$3 -> 0.089181852 | C17: =((SUMPRODUCT(DCF!$D$24:$H$24,(1+$B17)^(-DCF!$D$36:$H$36))+DCF!$H$24*(1+C$16)/($B17-C$16)*(1+$B17)^(-DCF!$H$35)+WACC!$C$29)/WACC!$C$17)/WACC!$C$14-1 -> -0.53207147 | D17: =((SUMPRODUCT(DCF!$D$24:$H$24,(1+$B17)^(-DCF!$D$36:$H$36))+DCF!$H$24*(1+D$16)/($B17-D$16)*(1+$B17)^(-DCF!$H$35)+WACC!$C$29)/WACC!$C$17)/WACC!$C$14-1 -> -0.50448184 | E17: =((SUMPRODUCT(DCF!$D$24:$H$24,(1+$B17)^(-DCF!$D$36:$H$36))+DCF!$H$24*(1+E$16)/($B17-E$16)*(1+$B17)^(-DCF!$H$35)+WACC!$C$29)/WACC!$C$17)/WACC!$C$14-1 -> -0.47223037 | F17: =((SUMPRODUCT(DCF!$D$24:$H$24,(1+$B17)^(-DCF!$D$36:$H$36))+DCF!$H$24*(1+F$16)/($B17-F$16)*(1+$B17)^(-DCF!$H$35)+WACC!$C$29)/WACC!$C$17)/WACC!$C$14-1 -> -0.43402645 | G17: =((SUMPRODUCT(DCF!$D$24:$H$24,(1+$B17)^(-DCF!$D$36:$H$36))+DCF!$H$24*(1+G$16)/($B17-G$16)*(1+$B17)^(-DCF!$H$35)+WACC!$C$29)/WACC!$C$17)/WACC!$C$14-1 -> -0.38805464
B18: =WACC!$C$33+(-1)*$C$3 -> 0.094181852 | C18: =((SUMPRODUCT(DCF!$D$24:$H$24,(1+$B18)^(-DCF!$D$36:$H$36))+DCF!$H$24*(1+C$16)/($B18-C$16)*(1+$B18)^(-DCF!$H$35)+WACC!$C$29)/WACC!$C$17)/WACC!$C$14-1 -> -0.5627679 | D18: =((SUMPRODUCT(DCF!$D$24:$H$24,(1+$B18)^(-DCF!$D$36:$H$36))+DCF!$H$24*(1+D$16)/($B18-D$16)*(1+$B18)^(-DCF!$H$35)+WACC!$C$29)/WACC!$C$17)/WACC!$C$14-1 -> -0.53932836 | E18: =((SUMPRODUCT(DCF!$D$24:$H$24,(1+$B18)^(-DCF!$D$36:$H$36))+DCF!$H$24*(1+E$16)/($B18-E$16)*(1+$B18)^(-DCF!$H$35)+WACC!$C$29)/WACC!$C$17)/WACC!$C$14-1 -> -0.51223678 | F18: =((SUMPRODUCT(DCF!$D$24:$H$24,(1+$B18)^(-DCF!$D$36:$H$36))+DCF!$H$24*(1+F$16)/($B18-F$16)*(1+$B18)^(-DCF!$H$35)+WACC!$C$29)/WACC!$C$17)/WACC!$C$14-1 -> -0.48056751 | G18: =((SUMPRODUCT(DCF!$D$24:$H$24,(1+$B18)^(-DCF!$D$36:$H$36))+DCF!$H$24*(1+G$16)/($B18-G$16)*(1+$B18)^(-DCF!$H$35)+WACC!$C$29)/WACC!$C$17)/WACC!$C$14-1 -> -0.44305325
B19: =WACC!$C$33+(0)*$C$3 -> 0.099181852 | C19: =((SUMPRODUCT(DCF!$D$24:$H$24,(1+$B19)^(-DCF!$D$36:$H$36))+DCF!$H$24*(1+C$16)/($B19-C$16)*(1+$B19)^(-DCF!$H$35)+WACC!$C$29)/WACC!$C$17)/WACC!$C$14-1 -> -0.5895584 | D19: =((SUMPRODUCT(DCF!$D$24:$H$24,(1+$B19)^(-DCF!$D$36:$H$36))+DCF!$H$24*(1+D$16)/($B19-D$16)*(1+$B19)^(-DCF!$H$35)+WACC!$C$29)/WACC!$C$17)/WACC!$C$14-1 -> -0.56944711 | E19: =((SUMPRODUCT(DCF!$D$24:$H$24,(1+$B19)^(-DCF!$D$36:$H$36))+DCF!$H$24*(1+E$16)/($B19-E$16)*(1+$B19)^(-DCF!$H$35)+WACC!$C$29)/WACC!$C$17)/WACC!$C$14-1 -> -0.54642879 | F19: =((SUMPRODUCT(DCF!$D$24:$H$24,(1+$B19)^(-DCF!$D$36:$H$36))+DCF!$H$24*(1+F$16)/($B19-F$16)*(1+$B19)^(-DCF!$H$35)+WACC!$C$29)/WACC!$C$17)/WACC!$C$14-1 -> -0.51982406 | G19: =((SUMPRODUCT(DCF!$D$24:$H$24,(1+$B19)^(-DCF!$D$36:$H$36))+DCF!$H$24*(1+G$16)/($B19-G$16)*(1+$B19)^(-DCF!$H$35)+WACC!$C$29)/WACC!$C$17)/WACC!$C$14-1 -> -0.4887239
B20: =WACC!$C$33+(1)*$C$3 -> 0.10418185 | C20: =((SUMPRODUCT(DCF!$D$24:$H$24,(1+$B20)^(-DCF!$D$36:$H$36))+DCF!$H$24*(1+C$16)/($B20-C$16)*(1+$B20)^(-DCF!$H$35)+WACC!$C$29)/WACC!$C$17)/WACC!$C$14-1 -> -0.61314012 | D20: =((SUMPRODUCT(DCF!$D$24:$H$24,(1+$B20)^(-DCF!$D$36:$H$36))+DCF!$H$24*(1+D$16)/($B20-D$16)*(1+$B20)^(-DCF!$H$35)+WACC!$C$29)/WACC!$C$17)/WACC!$C$14-1 -> -0.5957349 | E20: =((SUMPRODUCT(DCF!$D$24:$H$24,(1+$B20)^(-DCF!$D$36:$H$36))+DCF!$H$24*(1+E$16)/($B20-E$16)*(1+$B20)^(-DCF!$H$35)+WACC!$C$29)/WACC!$C$17)/WACC!$C$14-1 -> -0.57598339 | F20: =((SUMPRODUCT(DCF!$D$24:$H$24,(1+$B20)^(-DCF!$D$36:$H$36))+DCF!$H$24*(1+F$16)/($B20-F$16)*(1+$B20)^(-DCF!$H$35)+WACC!$C$29)/WACC!$C$17)/WACC!$C$14-1 -> -0.55337686 | G20: =((SUMPRODUCT(DCF!$D$24:$H$24,(1+$B20)^(-DCF!$D$36:$H$36))+DCF!$H$24*(1+G$16)/($B20-G$16)*(1+$B20)^(-DCF!$H$35)+WACC!$C$29)/WACC!$C$17)/WACC!$C$14-1 -> -0.52724807
B21: =WACC!$C$33+(2)*$C$3 -> 0.10918185 | C21: =((SUMPRODUCT(DCF!$D$24:$H$24,(1+$B21)^(-DCF!$D$36:$H$36))+DCF!$H$24*(1+C$16)/($B21-C$16)*(1+$B21)^(-DCF!$H$35)+WACC!$C$29)/WACC!$C$17)/WACC!$C$14-1 -> -0.63405378 | D21: =((SUMPRODUCT(DCF!$D$24:$H$24,(1+$B21)^(-DCF!$D$36:$H$36))+DCF!$H$24*(1+D$16)/($B21-D$16)*(1+$B21)^(-DCF!$H$35)+WACC!$C$29)/WACC!$C$17)/WACC!$C$14-1 -> -0.61887544 | E21: =((SUMPRODUCT(DCF!$D$24:$H$24,(1+$B21)^(-DCF!$D$36:$H$36))+DCF!$H$24*(1+E$16)/($B21-E$16)*(1+$B21)^(-DCF!$H$35)+WACC!$C$29)/WACC!$C$17)/WACC!$C$14-1 -> -0.6017802 | F21: =((SUMPRODUCT(DCF!$D$24:$H$24,(1+$B21)^(-DCF!$D$36:$H$36))+DCF!$H$24*(1+F$16)/($B21-F$16)*(1+$B21)^(-DCF!$H$35)+WACC!$C$29)/WACC!$C$17)/WACC!$C$14-1 -> -0.58238045 | G21: =((SUMPRODUCT(DCF!$D$24:$H$24,(1+$B21)^(-DCF!$D$36:$H$36))+DCF!$H$24*(1+G$16)/($B21-G$16)*(1+$B21)^(-DCF!$H$35)+WACC!$C$29)/WACC!$C$17)/WACC!$C$14-1 -> -0.56017654
A23: 3) Exit-multiple method: value per share
B24: WACC ↓ / EV/EBITDA → | C24: =DCF!$C$32+(-2)*$C$5 -> 16 | D24: =DCF!$C$32+(-1)*$C$5 -> 18 | E24: =DCF!$C$32+(0)*$C$5 -> 20 | F24: =DCF!$C$32+(1)*$C$5 -> 22 | G24: =DCF!$C$32+(2)*$C$5 -> 24
B25: =WACC!$C$33+(-2)*$C$3 -> 0.089181852 | C25: =(SUMPRODUCT(DCF!$D$24:$H$24,(1+$B25)^(-DCF!$D$36:$H$36))+DCF!$H$26*C$24*(1+$B25)^(-DCF!$H$35)+WACC!$C$29)/WACC!$C$17 -> 203.90664 | D25: =(SUMPRODUCT(DCF!$D$24:$H$24,(1+$B25)^(-DCF!$D$36:$H$36))+DCF!$H$26*D$24*(1+$B25)^(-DCF!$H$35)+WACC!$C$29)/WACC!$C$17 -> 223.71088 | E25: =(SUMPRODUCT(DCF!$D$24:$H$24,(1+$B25)^(-DCF!$D$36:$H$36))+DCF!$H$26*E$24*(1+$B25)^(-DCF!$H$35)+WACC!$C$29)/WACC!$C$17 -> 243.51511 | F25: =(SUMPRODUCT(DCF!$D$24:$H$24,(1+$B25)^(-DCF!$D$36:$H$36))+DCF!$H$26*F$24*(1+$B25)^(-DCF!$H$35)+WACC!$C$29)/WACC!$C$17 -> 263.31935 | G25: =(SUMPRODUCT(DCF!$D$24:$H$24,(1+$B25)^(-DCF!$D$36:$H$36))+DCF!$H$26*G$24*(1+$B25)^(-DCF!$H$35)+WACC!$C$29)/WACC!$C$17 -> 283.12358
B26: =WACC!$C$33+(-1)*$C$3 -> 0.094181852 | C26: =(SUMPRODUCT(DCF!$D$24:$H$24,(1+$B26)^(-DCF!$D$36:$H$36))+DCF!$H$26*C$24*(1+$B26)^(-DCF!$H$35)+WACC!$C$29)/WACC!$C$17 -> 199.87827 | D26: =(SUMPRODUCT(DCF!$D$24:$H$24,(1+$B26)^(-DCF!$D$36:$H$36))+DCF!$H$26*D$24*(1+$B26)^(-DCF!$H$35)+WACC!$C$29)/WACC!$C$17 -> 219.23613 | E26: =(SUMPRODUCT(DCF!$D$24:$H$24,(1+$B26)^(-DCF!$D$36:$H$36))+DCF!$H$26*E$24*(1+$B26)^(-DCF!$H$35)+WACC!$C$29)/WACC!$C$17 -> 238.594 | F26: =(SUMPRODUCT(DCF!$D$24:$H$24,(1+$B26)^(-DCF!$D$36:$H$36))+DCF!$H$26*F$24*(1+$B26)^(-DCF!$H$35)+WACC!$C$29)/WACC!$C$17 -> 257.95186 | G26: =(SUMPRODUCT(DCF!$D$24:$H$24,(1+$B26)^(-DCF!$D$36:$H$36))+DCF!$H$26*G$24*(1+$B26)^(-DCF!$H$35)+WACC!$C$29)/WACC!$C$17 -> 277.30973
B27: =WACC!$C$33+(0)*$C$3 -> 0.099181852 | C27: =(SUMPRODUCT(DCF!$D$24:$H$24,(1+$B27)^(-DCF!$D$36:$H$36))+DCF!$H$26*C$24*(1+$B27)^(-DCF!$H$35)+WACC!$C$29)/WACC!$C$17 -> 195.9549 | D27: =(SUMPRODUCT(DCF!$D$24:$H$24,(1+$B27)^(-DCF!$D$36:$H$36))+DCF!$H$26*D$24*(1+$B27)^(-DCF!$H$35)+WACC!$C$29)/WACC!$C$17 -> 214.87843 | E27: =(SUMPRODUCT(DCF!$D$24:$H$24,(1+$B27)^(-DCF!$D$36:$H$36))+DCF!$H$26*E$24*(1+$B27)^(-DCF!$H$35)+WACC!$C$29)/WACC!$C$17 -> 233.80195 | F27: =(SUMPRODUCT(DCF!$D$24:$H$24,(1+$B27)^(-DCF!$D$36:$H$36))+DCF!$H$26*F$24*(1+$B27)^(-DCF!$H$35)+WACC!$C$29)/WACC!$C$17 -> 252.72547 | G27: =(SUMPRODUCT(DCF!$D$24:$H$24,(1+$B27)^(-DCF!$D$36:$H$36))+DCF!$H$26*G$24*(1+$B27)^(-DCF!$H$35)+WACC!$C$29)/WACC!$C$17 -> 271.64899
B28: =WACC!$C$33+(1)*$C$3 -> 0.10418185 | C28: =(SUMPRODUCT(DCF!$D$24:$H$24,(1+$B28)^(-DCF!$D$36:$H$36))+DCF!$H$26*C$24*(1+$B28)^(-DCF!$H$35)+WACC!$C$29)/WACC!$C$17 -> 192.13332 | D28: =(SUMPRODUCT(DCF!$D$24:$H$24,(1+$B28)^(-DCF!$D$36:$H$36))+DCF!$H$26*D$24*(1+$B28)^(-DCF!$H$35)+WACC!$C$29)/WACC!$C$17 -> 210.63415 | E28: =(SUMPRODUCT(DCF!$D$24:$H$24,(1+$B28)^(-DCF!$D$36:$H$36))+DCF!$H$26*E$24*(1+$B28)^(-DCF!$H$35)+WACC!$C$29)/WACC!$C$17 -> 229.13498 | F28: =(SUMPRODUCT(DCF!$D$24:$H$24,(1+$B28)^(-DCF!$D$36:$H$36))+DCF!$H$26*F$24*(1+$B28)^(-DCF!$H$35)+WACC!$C$29)/WACC!$C$17 -> 247.63581 | G28: =(SUMPRODUCT(DCF!$D$24:$H$24,(1+$B28)^(-DCF!$D$36:$H$36))+DCF!$H$26*G$24*(1+$B28)^(-DCF!$H$35)+WACC!$C$29)/WACC!$C$17 -> 266.13664
B29: =WACC!$C$33+(2)*$C$3 -> 0.10918185 | C29: =(SUMPRODUCT(DCF!$D$24:$H$24,(1+$B29)^(-DCF!$D$36:$H$36))+DCF!$H$26*C$24*(1+$B29)^(-DCF!$H$35)+WACC!$C$29)/WACC!$C$17 -> 188.4104 | D29: =(SUMPRODUCT(DCF!$D$24:$H$24,(1+$B29)^(-DCF!$D$36:$H$36))+DCF!$H$26*D$24*(1+$B29)^(-DCF!$H$35)+WACC!$C$29)/WACC!$C$17 -> 206.49983 | E29: =(SUMPRODUCT(DCF!$D$24:$H$24,(1+$B29)^(-DCF!$D$36:$H$36))+DCF!$H$26*E$24*(1+$B29)^(-DCF!$H$35)+WACC!$C$29)/WACC!$C$17 -> 224.58925 | F29: =(SUMPRODUCT(DCF!$D$24:$H$24,(1+$B29)^(-DCF!$D$36:$H$36))+DCF!$H$26*F$24*(1+$B29)^(-DCF!$H$35)+WACC!$C$29)/WACC!$C$17 -> 242.67868 | G29: =(SUMPRODUCT(DCF!$D$24:$H$24,(1+$B29)^(-DCF!$D$36:$H$36))+DCF!$H$26*G$24*(1+$B29)^(-DCF!$H$35)+WACC!$C$29)/WACC!$C$17 -> 260.7681
A31: Check: centre of table 1 should equal DCF!C51, and centre of table 3 should equal DCF!D51.
A32: Table 1 centre – DCF!C51 | C32: =E11-DCF!C51 -> 0
A33: Table 3 centre – DCF!D51 | C33: =E27-DCF!D51 -> 0
