Workbook

Sheet Cover
B1: Hedged US–Korea–Japan portfolio — DCF valuations of 18 stocks
B2: Every DCF-able stock considered for the portfolio, valued on one set of market assumptions. Prices 22–28 Sep 2026. Not investment advice.
B4: Prepared by | C4: Jung Ryul Lee
B5: Data as of | C5: Prices 22–28 Sep 2026
B6: Units | C6: Local currency; US models in US$ bn, KR/JP in trillions
B8: What this model does
B9: Six US large caps with hand-built 10-year FCFF DCFs (revenue × fading FCF margin, WACC, Gordon terminal value).
B10: Four US income stocks with FCFE / AFFO models (perpetuity or two-stage), discounted at the cost of equity.
B11: Six Korean and one Japanese stock with a systematic 10-year model: discounted earnings (payout = 1 − g/ROE) blended 50/50 with discounted FCF, with guard-rails on beta, growth and ROE.
B12: Summary ranks the names against a 15% upside hurdle used in the portfolio selection.
B14: Key outputs (live links)
B15: Stocks valued | C15: =COUNTA(Summary!B7:B15)+COUNTA(Summary!B18:B26) -> 18
B16: Clear the 15% hurdle | C16: =COUNTIF(Summary!J7:J26,"Yes") -> 14
B17: Held names: median upside | C17: =MEDIAN(Summary!I7:I15) -> 0.61356587
B18: Not-held names: median upside | C18: =MEDIAN(Summary!I18:I26) -> 0.19384446
B19: US risk-free / ERP | C19: =TEXT(Assumptions!B5,"0.00%")&" / "&TEXT(Assumptions!C5,"0.0%") -> 5.23% / 4.5%
B20: Korea risk-free / ERP | C20: =TEXT(Assumptions!B6,"0.00%")&" / "&TEXT(Assumptions!C6,"0.0%") -> 4.41% / 5.5%
B21: Japan risk-free / ERP | C21: =TEXT(Assumptions!B7,"0.00%")&" / "&TEXT(Assumptions!C7,"0.0%") -> 3.07% / 5.0%
B23: Contents
B24: Summary | C24: All 18 valuations: method, discount rate, price, value, upside, hurdle test, weight
B25: Assumptions | C25: Risk-free rates, equity risk premia and terminal growth by market; guard-rails
B26: UNH | C26: 10-yr FCFF DCF
B27: ADBE | C27: 10-yr FCFF DCF
B28: CRM | C28: 10-yr FCFF DCF
B29: MSFT | C29: 10-yr FCFF DCF
B30: GOOGL | C30: 10-yr FCFF DCF
B31: JNJ | C31: 10-yr FCFF DCF
B32: CI | C32: Two-stage FCFE
B33: VICI | C33: Two-stage AFFO
B34: T | C34: FCFE perpetuity
B35: VZ | C35: FCFE perpetuity
... B43: Astellas | C43: Systematic model
B45: Colour code
B46: 1,234 Blue text: hard-coded input
B47: 1,234 Black text: formula
B48: 1,234 Green text: link to another sheet
B49: Shaded yellow: key assumption to flex
B50: Shaded green: key output
B52: Method notes and limitations
B53: • The systematic Korean/Japanese models are a screening tool, not a full company model: they use data-feed consensus and statistics, so large upsides mostly reflect low P/E multiples rather than company-specific forecasts.
...

Sheet Summary
A1: DCF valuations: every stock valued with a discounted-cash-flow model
A2: Hedged US–Korea–Japan Multi-Asset Portfolio · Jung Ryul Lee · Prices 22–28 Sep 2026 · For discussion only, not investment advice
A3: Colour code: blue = hardcoded input · black = formula · green = link to another sheet · yellow fill = key assumption. Change any input and the whole workbook recalculates.
A5: Company | B5: Ticker / code | C5: Market | D5: Model | E5: Discount rate | F5: Rate type | G5: Price | H5: DCF value / share | I5: Upside | J5: Clears 15% hurdle? | K5: Held? | L5: Portfolio weight
A6: Held in the portfolio
A7: AT&T | B7: T | C7: US | D7: FCFE perpetuity | E7: =T!B10 -> 0.07255 | F7: Cost of equity | G7: =T!B19 -> 25.38 | H7: =T!B18 -> 35.493482 | I7: =H7/G7-1 -> 0.39848236 | J7: =IF(I7>=Assumptions!$B$13,"Yes","No") -> Yes | K7: Yes | L7: 0.02
A8: Cigna Group | B8: CI | C8: US | D8: Two-stage FCFE | E8: =CI!B10 -> 0.0838 | F8: Cost of equity | G8: =CI!B29 -> 274.47 | H8: =CI!B28 -> 425.44302 | I8: =H8/G8-1 -> 0.5500529 | J8: =IF(I8>=Assumptions!$B$13,"Yes","No") -> Yes | K8: Yes | L8: 0.0175
A9: VICI Properties | B9: VICI | C9: US | D9: Two-stage AFFO discount | E9: =VICI!B10 -> 0.0928 | F9: Cost of equity | G9: =VICI!B29 -> 23.71 | H9: =VICI!B28 -> 33.50607 | I9: =H9/G9-1 -> 0.41316196 | J9: =IF(I9>=Assumptions!$B$13,"Yes","No") -> Yes | K9: Yes | L9: 0.0125
A10: KT Corp | B10: 030200 | C10: KR | D10: Systematic 10-yr earnings/FCF | E10: =KT!B17 -> 0.0881 | F10: Cost of equity | G10: =KT!B45 -> 53400 | H10: =KT!B44 -> 86167.554 | I10: =H10/G10-1 -> 0.61362462 | J10: =IF(I10>=Assumptions!$B$13,"Yes","No") -> Yes | K10: Yes | L10: 0.025
A11: LG Uplus | B11: 032640 | C11: KR | D11: Systematic 10-yr earnings/FCF | E11: ='LG Uplus'!B17 -> 0.0881 | F11: Cost of equity | G11: ='LG Uplus'!B45 -> 15020 | H11: ='LG Uplus'!B44 -> 26836.271 | I11: =H11/G11-1 -> 0.78670244 | J11: =IF(I11>=Assumptions!$B$13,"Yes","No") -> Yes | K11: Yes | L11: 0.025
A12: Krafton | B12: 259960 | C12: KR | D12: Systematic 10-yr earnings/FCF | E12: =Krafton!B17 -> 0.0881 | F12: Cost of equity | G12: =Krafton!B45 -> 200000 | H12: =Krafton!B44 -> 395321.77 | I12: =H12/G12-1 -> 0.97660884 | J12: =IF(I12>=Assumptions!$B$13,"Yes","No") -> Yes | K12: Yes | L12: 0.025
A13: Hankook Tire & Technology | B13: 161390 | C13: KR | D13: Systematic 10-yr earnings/FCF | E13: ='Hankook Tire'!B17 -> 0.0881 | F13: Cost of equity | G13: ='Hankook Tire'!B45 -> 63500 | H13: ='Hankook Tire'!B44 -> 102461.43 | I13: =H13/G13-1 -> 0.61356587 | J13: =IF(I13>=Assumptions!$B$13,"Yes","No") -> Yes | K13: Yes | L13: 0.025
A14: Coway | B14: 021240 | C14: KR | D14: Systematic 10-yr earnings/FCF | E14: =Coway!B17 -> 0.0881 | F14: Cost of equity | G14: =Coway!B45 -> 95200 | H14: =Coway!B44 -> 170910.16 | I14: =H14/G14-1 -> 0.7952748 | J14: =IF(I14>=Assumptions!$B$13,"Yes","No") -> Yes | K14: Yes | L14: 0.025
A15: Astellas Pharma | B15: 4503 | C15: JP | D15: Systematic 10-yr earnings/FCF | E15: =Astellas!B17 -> 0.0707 | F15: Cost of equity | G15: =Astellas!B45 -> 2399 | H15: =Astellas!B44 -> 3695.7116 | I15: =H15/G15-1 -> 0.54052171 | J15: =IF(I15>=Assumptions!$B$13,"Yes","No") -> Yes | K15: Yes | L15: 0.0225
A17: Valued with a DCF but not held
A18: UnitedHealth Group | B18: UNH | C18: US | D18: 10-yr FCFF DCF | E18: =UNH!B15 -> 0.081691 | F18: WACC | G18: =UNH!B43 -> 376.59 | H18: =UNH!B42 -> 572.01294 | I18: =H18/G18-1 -> 0.51892758 | J18: =IF(I18>=Assumptions!$B$13,"Yes","No") -> Yes | K18: No | L18: 0
A19: Adobe | B19: ADBE | C19: US | D19: 10-yr FCFF DCF | E19: =ADBE!B15 -> 0.1018 | F19: WACC | G19: =ADBE!B43 -> 240.69 | H19: =ADBE!B42 -> 309.39542 | I19: =H19/G19-1 -> 0.2854519 | J19: =IF(I19>=Assumptions!$B$13,"Yes","No") -> Yes | K19: No | L19: 0
A20: Salesforce | B20: CRM | C20: US | D20: 10-yr FCFF DCF | E20: =CRM!B15 -> 0.0988 | F20: WACC | G20: =CRM!B43 -> 234.02 | H20: =CRM!B42 -> 255.45789 | I20: =H20/G20-1 -> 0.091607094 | J20: =IF(I20>=Assumptions!$B$13,"Yes","No") -> No | K20: No | L20: 0
A21: Microsoft | B21: MSFT | C21: US | D21: 10-yr FCFF DCF | E21: =MSFT!B15 -> 0.0953 | F21: WACC | G21: =MSFT!B43 -> 516.17 | H21: =MSFT!B42 -> 392.89659 | I21: =H21/G21-1 -> -0.23882327 | J21: =IF(I21>=Assumptions!$B$13,"Yes","No") -> No | K21: No | L21: 0
A22: Alphabet | B22: GOOGL | C22: US | D22: 10-yr FCFF DCF | E22: =GOOGL!B15 -> 0.10205 | F22: WACC | G22: =GOOGL!B43 -> 343.92 | H22: =GOOGL!B42 -> 241.28157 | I22: =H22/G22-1 -> -0.29843694 | J22: =IF(I22>=Assumptions!$B$13,"Yes","No") -> No | K22: No | L22: 0
A23: Johnson & Johnson | B23: JNJ | C23: US | D23: 10-yr FCFF DCF | E23: =JNJ!B15 -> 0.07505 | F23: WACC | G23: =JNJ!B43 -> 271.22 | H23: =JNJ!B42 -> 231.4185 | I23: =H23/G23-1 -> -0.14674987 | J23: =IF(I23>=Assumptions!$B$13,"Yes","No") -> No | K23: No | L23: 0
A24: Verizon | B24: VZ | C24: US | D24: FCFE perpetuity | E24: =VZ!B10 -> 0.07255 | F24: Cost of equity | G24: =VZ!B19 -> 47.08 | H24: =VZ!B18 -> 56.206197 | I24: =H24/G24-1 -> 0.19384446 | J24: =IF(I24>=Assumptions!$B$13,"Yes","No") -> Yes | K24: No | L24: 0
A25: Comcast | B25: CMCSA | C25: US | D25: FCFE perpetuity | E25: =CMCSA!B10 -> 0.08605 | F25: Cost of equity | G25: =CMCSA!B19 -> 21.91 | H25: =CMCSA!B18 -> 27.221594 | I25: =H25/G25-1 -> 0.24242786 | J25: =IF(I25>=Assumptions!$B$13,"Yes","No") -> Yes | K25: No | L25: 0
A26: PayPal | B26: PYPL | C26: US | D26: FCFE perpetuity | E26: =PYPL!B10 -> 0.10495 | F26: Cost of equity | G26: =PYPL!B19 -> 55.04 | H26: =PYPL!B18 -> 77.203419 | I26: =H26/G26-1 -> 0.40267839 | J26: =IF(I26>=Assumptions!$B$13,"Yes","No") -> Yes | K26: No | L26: 0
A28: Notes
A29: • Only 9 of the 19 stocks held are valued with a DCF. The other 10 (Woori, IBK, JB Financial, DB Insurance, MS&AD, Sompo, ORIX, KEPCO, KT&G, Hyundai Glovis) use justified P/B = (ROE − g)/(k − g), the standard equity-based method for banks and insurers, where free cash flow is not meaningful. They are in the memo, not in this workbook.
A30: • US hand-built models use prices of 22–26 Sep 2026; the systematic Korean/Japanese models use prices of 22–28 Sep 2026.
A31: • Weights are from the final optimisation and are typed in (blue); they do not update if valuations change. Re-run the optimiser for that.
A32: • The hurdle test (column J) recalculates, but for Korean names the memo counts upside above 60% only up to 60% when setting expected returns.

Sheet Assumptions
A1: Market assumptions (CAPM)
A2: Blue = hardcoded input. Every model sheet links here (green), so changing a cell below re-values every stock in that market.
A4: Market | B4: Risk-free rate | C4: Equity risk premium | D4: Terminal growth | E4: Source / note
A5: US | B5: 0.0523 | C5: 0.045 | D5: 0.03 | E5: US 10-yr Treasury 5.23% (Washington Trust weekly review, 25 Sep 2026); ERP and terminal growth are author assumptions
A6: KR | B6: 0.0441 | C6: 0.055 | D6: 0.025 | E6: Korea 10-yr KTB 4.41% (Trading Economics, Sep 2026); ERP and terminal growth are author assumptions
A7: JP | B7: 0.0307 | C7: 0.05 | D7: 0.015 | E7: JGB 10-yr 3.07% (Trading Economics, 25 Sep 2026); ERP and terminal growth are author assumptions
A9: Beta floor / cap (systematic models) | B9: 0.8 | C9: 1.6 | E9: Data-feed betas are clipped to this range so no stock gets a cost of equity far below its market's
A10: Growth cap (systematic models) | B10: 0.1 | C10: 0.6 | E10: B = max first-stage growth; C = max growth as a multiple of ROE (payout floor 40%)
A11: Growth floor | B11: -0.05
A12: ROE clip for payout (low / high) | B12: 0.08 | C12: 0.3
A13: Hurdle (min. upside to hold) | B13: 0.15

Sheet UNH
A1: UnitedHealth Group (UNH)
A2: 10-year FCFF DCF: revenue × FCF margin, both fading linearly, discounted at WACC; Gordon terminal value
A3: Inputs: company filings and market data as cited in the portfolio memo (not included) (Tickzen, Stock Titan, company guidance); prices 22–26 Sep 2026. $ in billions unless per share.
A5: Inputs
A6: Share price ($) | B6: 376.59
A7: Beta | B7: 0.8
A8: Risk-free rate | B8: =Assumptions!$B$5 -> 0.0523
A9: Equity risk premium | B9: =Assumptions!$C$5 -> 0.045
A10: Cost of equity | B10: =B8+B7*B9 -> 0.0883 | C10: CAPM
A11: Debt weight | B11: 0.15 | C11: Share of capital in debt
A12: Pre-tax cost of debt | B12: 0.056
A13: Tax rate | B13: 0.21
A14: WACC adjustment | B14: 0
A15: WACC | B15: =(1-B11)*B10+B11*B12*(1-B13)+B14 -> 0.081691
A16: Revenue, last 12 months ($bn) | B16: 460
A17: Revenue growth, year 1 | B17: 0.06
A18: Revenue growth, year 10 | B18: 0.04
A19: FCF margin, year 1 | B19: 0.045
A20: FCF margin, year 10 | B20: 0.055
A21: Terminal growth | B21: 0.03 | C21: Stock-specific; see Assumptions for market defaults
A22: Net debt ($bn) | B22: 41.86 | C22: Negative = net cash
A23: Diluted shares (bn) | B23: 0.92814467 | C23: Market cap ÷ price at data date
C24: Rev $460bn; FCF margin repairs only to 5.5% (2019–23 avg ≈7%) after the FY25 medical-cost shock
A26: Projection ($bn)
A27: Year | C27: 1 | D27: 2 | E27: 3 | F27: 4 | G27: 5 | H27: 6 | I27: 7 | J27: 8 | K27: 9 | L27: 10
A28: Revenue growth | C28: =$B$17+($B$18-$B$17)*(C27-1)/9 -> 0.06 | D28: =$B$17+($B$18-$B$17)*(D27-1)/9 -> 0.057777778 | E28: =$B$17+($B$18-$B$17)*(E27-1)/9 -> 0.055555556 | F28: =$B$17+($B$18-$B$17)*(F27-1)/9 -> 0.053333333 | G28: =$B$17+($B$18-$B$17)*(G27-1)/9 -> 0.051111111 | H28: =$B$17+($B$18-$B$17)*(H27-1)/9 -> 0.048888889 | I28: =$B$17+($B$18-$B$17)*(I27-1)/9 -> 0.046666667 | J28: =$B$17+($B$18-$B$17)*(J27-1)/9 -> 0.044444444 | ... L28: =$B$17+($B$18-$B$17)*(L27-1)/9 -> 0.04
A29: FCF margin | C29: =$B$19+($B$20-$B$19)*(C27-1)/9 -> 0.045 | D29: =$B$19+($B$20-$B$19)*(D27-1)/9 -> 0.046111111 | E29: =$B$19+($B$20-$B$19)*(E27-1)/9 -> 0.047222222 | F29: =$B$19+($B$20-$B$19)*(F27-1)/9 -> 0.048333333 | G29: =$B$19+($B$20-$B$19)*(G27-1)/9 -> 0.049444444 | H29: =$B$19+($B$20-$B$19)*(H27-1)/9 -> 0.050555556 | I29: =$B$19+($B$20-$B$19)*(I27-1)/9 -> 0.051666667 | J29: =$B$19+($B$20-$B$19)*(J27-1)/9 -> 0.052777778 | ... L29: =$B$19+($B$20-$B$19)*(L27-1)/9 -> 0.055
A30: Revenue | C30: =$B$16*(1+C28) -> 487.6 | D30: =C30*(1+D28) -> 515.77244 | E30: =D30*(1+E28) -> 544.42647 | F30: =E30*(1+F28) -> 573.46255 | G30: =F30*(1+G28) -> 602.77286 | H30: =G30*(1+H28) -> 632.24175 | I30: =H30*(1+I28) -> 661.74637 | J30: =I30*(1+J28) -> 691.15732 | K30: =J30*(1+K28) -> 720.33951 | L30: =K30*(1+L28) -> 749.15309
A31: Free cash flow to firm | C31: =C30*C29 -> 21.942 | D31: =D30*D29 -> 23.78284 | E31: =E30*E29 -> 25.709028 | F31: =F30*F29 -> 27.717356 | G31: =G30*G29 -> 29.803769 | H31: =H30*H29 -> 31.963333 | I31: =I30*I29 -> 34.190229 | J31: =J30*J29 -> 36.477747 | ... L31: =L30*L29 -> 41.20342
A32: Discount factor | C32: =1/(1+$B$15)^C27 -> 0.92447843 | D32: =1/(1+$B$15)^D27 -> 0.85466037 | E32: =1/(1+$B$15)^E27 -> 0.79011508 | F32: =1/(1+$B$15)^F27 -> 0.73044435 | G32: =1/(1+$B$15)^G27 -> 0.67528005 | H32: =1/(1+$B$15)^H27 -> 0.62428184 | I32: =1/(1+$B$15)^I27 -> 0.5771351 | J32: =1/(1+$B$15)^J27 -> 0.53354895 | ... L32: =1/(1+$B$15)^L27 -> 0.45600314
A33: PV of FCFF | C33: =C31*C32 -> 20.284906 | D33: =D31*D32 -> 20.326251 | E33: =E31*E32 -> 20.313091 | F33: =F31*F32 -> 20.245986 | G33: =G31*G32 -> 20.125891 | H33: =H31*H32 -> 19.954128 | I33: =I31*I32 -> 19.732381 | J33: =J31*J32 -> 19.462664 | ... L33: =L31*L32 -> 18.788889
A35: Valuation
A36: Sum of PV of FCFF, years 1–10 | B36: =SUM(C33:L33) -> 198.38149
A37: Terminal value (year 10) | B37: =L31*(1+B21)/(B15-B21) -> 821.02344
A38: PV of terminal value | B38: =B37*L32 -> 374.38927
A39: Enterprise value | B39: =B36+B38 -> 572.77076
A40: Less: net debt | B40: =B22 -> 41.86
A41: Equity value | B41: =B39-B40 -> 530.91076
A42: Value per share ($) | B42: =B41/B23 -> 572.01294
A43: Share price ($) | B43: =B6 -> 376.59
...

Sheet ADBE
A1: Adobe (ADBE)
A2: 10-year FCFF DCF: revenue × FCF margin, both fading linearly, discounted at WACC; Gordon terminal value
A3: Inputs: company filings and market data as cited in the portfolio memo (not included) (Tickzen, Stock Titan, company guidance); prices 22–26 Sep 2026. $ in billions unless per share.
A5: Inputs
A6: Share price ($) | B6: 240.69
A7: Beta | B7: 1.1
A8: Risk-free rate | B8: =Assumptions!$B$5 -> 0.0523
A9: Equity risk premium | B9: =Assumptions!$C$5 -> 0.045
A10: Cost of equity | B10: =B8+B7*B9 -> 0.1018 | C10: CAPM
A11: Debt weight | B11: 0 | C11: Share of capital in debt
A12: Pre-tax cost of debt | B12: 0
A13: Tax rate | B13: 0
A14: WACC adjustment | B14: 0
A15: WACC | B15: =(1-B11)*B10+B11*B12*(1-B13)+B14 -> 0.1018
A16: Revenue, last 12 months ($bn) | B16: 26.6
A17: Revenue growth, year 1 | B17: 0.08
A18: Revenue growth, year 10 | B18: 0
A19: FCF margin, year 1 | B19: 0.38
A20: FCF margin, year 10 | B20: 0.3
A21: Terminal growth | B21: 0.01 | C21: Stock-specific; see Assumptions for market defaults
A22: Net debt ($bn) | B22: 1.4 | C22: Negative = net cash
A23: Diluted shares (bn) | B23: 0.38895645 | C23: Market cap ÷ price at data date
C24: AI-disruption case: growth fades to 0%, FCF margin compresses 38% → 30%
A26: Projection ($bn)
A27: Year | C27: 1 | D27: 2 | E27: 3 | F27: 4 | G27: 5 | H27: 6 | I27: 7 | J27: 8 | K27: 9 | L27: 10
A28: Revenue growth | C28: =$B$17+($B$18-$B$17)*(C27-1)/9 -> 0.08 | D28: =$B$17+($B$18-$B$17)*(D27-1)/9 -> 0.071111111 | E28: =$B$17+($B$18-$B$17)*(E27-1)/9 -> 0.062222222 | F28: =$B$17+($B$18-$B$17)*(F27-1)/9 -> 0.053333333 | G28: =$B$17+($B$18-$B$17)*(G27-1)/9 -> 0.044444444 | H28: =$B$17+($B$18-$B$17)*(H27-1)/9 -> 0.035555556 | I28: =$B$17+($B$18-$B$17)*(I27-1)/9 -> 0.026666667 | J28: =$B$17+($B$18-$B$17)*(J27-1)/9 -> 0.017777778 | ... L28: =$B$17+($B$18-$B$17)*(L27-1)/9 -> 0
A29: FCF margin | C29: =$B$19+($B$20-$B$19)*(C27-1)/9 -> 0.38 | D29: =$B$19+($B$20-$B$19)*(D27-1)/9 -> 0.37111111 | E29: =$B$19+($B$20-$B$19)*(E27-1)/9 -> 0.36222222 | F29: =$B$19+($B$20-$B$19)*(F27-1)/9 -> 0.35333333 | G29: =$B$19+($B$20-$B$19)*(G27-1)/9 -> 0.34444444 | H29: =$B$19+($B$20-$B$19)*(H27-1)/9 -> 0.33555556 | I29: =$B$19+($B$20-$B$19)*(I27-1)/9 -> 0.32666667 | J29: =$B$19+($B$20-$B$19)*(J27-1)/9 -> 0.31777778 | ... L29: =$B$19+($B$20-$B$19)*(L27-1)/9 -> 0.3
A30: Revenue | C30: =$B$16*(1+C28) -> 28.728 | D30: =C30*(1+D28) -> 30.77088 | E30: =D30*(1+E28) -> 32.685513 | F30: =E30*(1+F28) -> 34.42874 | G30: =F30*(1+G28) -> 35.958906 | H30: =G30*(1+H28) -> 37.237445 | I30: =H30*(1+I28) -> 38.230444 | J30: =I30*(1+J28) -> 38.910096 | K30: =J30*(1+K28) -> 39.255963 | L30: =K30*(1+L28) -> 39.255963
A31: Free cash flow to firm | C31: =C30*C29 -> 10.91664 | D31: =D30*D29 -> 11.419415 | E31: =E30*E29 -> 11.839419 | F31: =F30*F29 -> 12.164821 | G31: =G30*G29 -> 12.385845 | H31: =H30*H29 -> 12.495232 | I31: =I30*I29 -> 12.488612 | J31: =J30*J29 -> 12.364764 | ... L31: =L30*L29 -> 11.776789
A32: Discount factor | C32: =1/(1+$B$15)^C27 -> 0.90760574 | D32: =1/(1+$B$15)^D27 -> 0.82374817 | E32: =1/(1+$B$15)^E27 -> 0.74763857 | F32: =1/(1+$B$15)^F27 -> 0.67856105 | G32: =1/(1+$B$15)^G27 -> 0.6158659 | H32: =1/(1+$B$15)^H27 -> 0.55896343 | I32: =1/(1+$B$15)^I27 -> 0.50731841 | J32: =1/(1+$B$15)^J27 -> 0.4604451 | ... L32: =1/(1+$B$15)^L27 -> 0.37929081
A33: PV of FCFF | C33: =C31*C32 -> 9.9080051 | D33: =D31*D32 -> 9.4067226 | E33: =E31*E32 -> 8.8516062 | F33: =F31*F32 -> 8.254574 | G33: =G31*G32 -> 7.6280199 | H33: =H31*H32 -> 6.9843774 | I33: =I31*I32 -> 6.3357026 | J33: =J31*J32 -> 5.6932949 | ... L33: =L31*L32 -> 4.4668278
A35: Valuation
A36: Sum of PV of FCFF, years 1–10 | B36: =SUM(C33:L33) -> 72.596505
A37: Terminal value (year 10) | B37: =L31*(1+B21)/(B15-B21) -> 129.57034
A38: PV of terminal value | B38: =B37*L32 -> 49.144838
A39: Enterprise value | B39: =B36+B38 -> 121.74134
A40: Less: net debt | B40: =B22 -> 1.4
A41: Equity value | B41: =B39-B40 -> 120.34134
A42: Value per share ($) | B42: =B41/B23 -> 309.39542
A43: Share price ($) | B43: =B6 -> 240.69
...

Sheet CRM
A1: Salesforce (CRM)
A2: 10-year FCFF DCF: revenue × FCF margin, both fading linearly, discounted at WACC; Gordon terminal value
A3: Inputs: company filings and market data as cited in the portfolio memo (not included) (Tickzen, Stock Titan, company guidance); prices 22–26 Sep 2026. $ in billions unless per share.
A5: Inputs
A6: Share price ($) | B6: 234.02
A7: Beta | B7: 1.1
A8: Risk-free rate | B8: =Assumptions!$B$5 -> 0.0523
A9: Equity risk premium | B9: =Assumptions!$C$5 -> 0.045
A10: Cost of equity | B10: =B8+B7*B9 -> 0.1018 | C10: CAPM
A11: Debt weight | B11: 0 | C11: Share of capital in debt
A12: Pre-tax cost of debt | B12: 0
A13: Tax rate | B13: 0
A14: WACC adjustment | B14: -0.003 | C14: Small haircut used for mega-caps with net cash / low leverage
A15: WACC | B15: =(1-B11)*B10+B11*B12*(1-B13)+B14 -> 0.0988
A16: Revenue, last 12 months ($bn) | B16: 45.6
A17: Revenue growth, year 1 | B17: 0.09
A18: Revenue growth, year 10 | B18: 0.02
A19: FCF margin, year 1 | B19: 0.35
A20: FCF margin, year 10 | B20: 0.33
A21: Terminal growth | B21: 0.02 | C21: Stock-specific; see Assumptions for market defaults
A22: Net debt ($bn) | B22: 31 | C22: Negative = net cash
A23: Diluted shares (bn) | B23: 0.90573455 | C23: Market cap ÷ price at data date
C24: Rev $45.6bn TTM; growth 9% → 2%; FCF margin 35% → 33%
A26: Projection ($bn)
A27: Year | C27: 1 | D27: 2 | E27: 3 | F27: 4 | G27: 5 | H27: 6 | I27: 7 | J27: 8 | K27: 9 | L27: 10
A28: Revenue growth | C28: =$B$17+($B$18-$B$17)*(C27-1)/9 -> 0.09 | D28: =$B$17+($B$18-$B$17)*(D27-1)/9 -> 0.082222222 | E28: =$B$17+($B$18-$B$17)*(E27-1)/9 -> 0.074444444 | F28: =$B$17+($B$18-$B$17)*(F27-1)/9 -> 0.066666667 | G28: =$B$17+($B$18-$B$17)*(G27-1)/9 -> 0.058888889 | H28: =$B$17+($B$18-$B$17)*(H27-1)/9 -> 0.051111111 | I28: =$B$17+($B$18-$B$17)*(I27-1)/9 -> 0.043333333 | J28: =$B$17+($B$18-$B$17)*(J27-1)/9 -> 0.035555556 | ... L28: =$B$17+($B$18-$B$17)*(L27-1)/9 -> 0.02
A29: FCF margin | C29: =$B$19+($B$20-$B$19)*(C27-1)/9 -> 0.35 | D29: =$B$19+($B$20-$B$19)*(D27-1)/9 -> 0.34777778 | E29: =$B$19+($B$20-$B$19)*(E27-1)/9 -> 0.34555556 | F29: =$B$19+($B$20-$B$19)*(F27-1)/9 -> 0.34333333 | G29: =$B$19+($B$20-$B$19)*(G27-1)/9 -> 0.34111111 | H29: =$B$19+($B$20-$B$19)*(H27-1)/9 -> 0.33888889 | I29: =$B$19+($B$20-$B$19)*(I27-1)/9 -> 0.33666667 | J29: =$B$19+($B$20-$B$19)*(J27-1)/9 -> 0.33444444 | ... L29: =$B$19+($B$20-$B$19)*(L27-1)/9 -> 0.33
A30: Revenue | C30: =$B$16*(1+C28) -> 49.704 | D30: =C30*(1+D28) -> 53.790773 | E30: =D30*(1+E28) -> 57.795198 | F30: =E30*(1+F28) -> 61.648211 | G30: =F30*(1+G28) -> 65.278605 | H30: =G30*(1+H28) -> 68.615067 | I30: =H30*(1+I28) -> 71.588387 | J30: =I30*(1+J28) -> 74.133752 | K30: =J30*(1+K28) -> 76.193023 | L30: =K30*(1+L28) -> 77.716883
A31: Free cash flow to firm | C31: =C30*C29 -> 17.3964 | D31: =D30*D29 -> 18.707236 | E31: =E30*E29 -> 19.971452 | F31: =F30*F29 -> 21.165886 | G31: =G30*G29 -> 22.267258 | H31: =H30*H29 -> 23.252884 | I31: =I30*I29 -> 24.101424 | J31: =J30*J29 -> 24.793621 | ... L31: =L30*L29 -> 25.646571
A32: Discount factor | C32: =1/(1+$B$15)^C27 -> 0.91008373 | D32: =1/(1+$B$15)^D27 -> 0.82825239 | E32: =1/(1+$B$15)^E27 -> 0.75377902 | F32: =1/(1+$B$15)^F27 -> 0.68600202 | G32: =1/(1+$B$15)^G27 -> 0.62431928 | H32: =1/(1+$B$15)^H27 -> 0.56818282 | I32: =1/(1+$B$15)^I27 -> 0.51709394 | J32: =1/(1+$B$15)^J27 -> 0.47059878 | ... L32: =1/(1+$B$15)^L27 -> 0.38977456
A33: PV of FCFF | C33: =C31*C32 -> 15.832181 | D33: =D31*D32 -> 15.494313 | E33: =E31*E32 -> 15.054061 | F33: =F31*F32 -> 14.51984 | G33: =G31*G32 -> 13.901878 | H33: =H31*H32 -> 13.211889 | I33: =I31*I32 -> 12.4627 | J33: =J31*J32 -> 11.667848 | ... L33: =L31*L32 -> 9.9963812
A35: Valuation
A36: Sum of PV of FCFF, years 1–10 | B36: =SUM(C33:L33) -> 132.98226
A37: Terminal value (year 10) | B37: =L31*(1+B21)/(B15-B21) -> 331.97339
A38: PV of terminal value | B38: =B37*L32 -> 129.39478
A39: Enterprise value | B39: =B36+B38 -> 262.37704
A40: Less: net debt | B40: =B22 -> 31
A41: Equity value | B41: =B39-B40 -> 231.37704
A42: Value per share ($) | B42: =B41/B23 -> 255.45789
A43: Share price ($) | B43: =B6 -> 234.02
...

Sheet MSFT
A1: Microsoft (MSFT)
A2: 10-year FCFF DCF: revenue × FCF margin, both fading linearly, discounted at WACC; Gordon terminal value
A3: Inputs: company filings and market data as cited in the portfolio memo (not included) (Tickzen, Stock Titan, company guidance); prices 22–26 Sep 2026. $ in billions unless per share.
A5: Inputs
A6: Share price ($) | B6: 516.17
A7: Beta | B7: 1
A8: Risk-free rate | B8: =Assumptions!$B$5 -> 0.0523
A9: Equity risk premium | B9: =Assumptions!$C$5 -> 0.045
A10: Cost of equity | B10: =B8+B7*B9 -> 0.0973 | C10: CAPM
A11: Debt weight | B11: 0 | C11: Share of capital in debt
A12: Pre-tax cost of debt | B12: 0
A13: Tax rate | B13: 0
A14: WACC adjustment | B14: -0.002 | C14: Small haircut used for mega-caps with net cash / low leverage
A15: WACC | B15: =(1-B11)*B10+B11*B12*(1-B13)+B14 -> 0.0953
A16: Revenue, last 12 months ($bn) | B16: 331.8
A17: Revenue growth, year 1 | B17: 0.16
A18: Revenue growth, year 10 | B18: 0.04
A19: FCF margin, year 1 | B19: 0.22
A20: FCF margin, year 10 | B20: 0.33
A21: Terminal growth | B21: 0.035 | C21: Stock-specific; see Assumptions for market defaults
A22: Net debt ($bn) | B22: 51.97 | C22: Negative = net cash
A23: Diluted shares (bn) | B23: 7.45 | C23: Market cap ÷ price at data date
C24: Deliberately generous margins (22% → 33%); still below the price
A26: Projection ($bn)
A27: Year | C27: 1 | D27: 2 | E27: 3 | F27: 4 | G27: 5 | H27: 6 | I27: 7 | J27: 8 | K27: 9 | L27: 10
A28: Revenue growth | C28: =$B$17+($B$18-$B$17)*(C27-1)/9 -> 0.16 | D28: =$B$17+($B$18-$B$17)*(D27-1)/9 -> 0.14666667 | E28: =$B$17+($B$18-$B$17)*(E27-1)/9 -> 0.13333333 | F28: =$B$17+($B$18-$B$17)*(F27-1)/9 -> 0.12 | G28: =$B$17+($B$18-$B$17)*(G27-1)/9 -> 0.10666667 | H28: =$B$17+($B$18-$B$17)*(H27-1)/9 -> 0.093333333 | I28: =$B$17+($B$18-$B$17)*(I27-1)/9 -> 0.08 | J28: =$B$17+($B$18-$B$17)*(J27-1)/9 -> 0.066666667 | ... L28: =$B$17+($B$18-$B$17)*(L27-1)/9 -> 0.04
A29: FCF margin | C29: =$B$19+($B$20-$B$19)*(C27-1)/9 -> 0.22 | D29: =$B$19+($B$20-$B$19)*(D27-1)/9 -> 0.23222222 | E29: =$B$19+($B$20-$B$19)*(E27-1)/9 -> 0.24444444 | F29: =$B$19+($B$20-$B$19)*(F27-1)/9 -> 0.25666667 | G29: =$B$19+($B$20-$B$19)*(G27-1)/9 -> 0.26888889 | H29: =$B$19+($B$20-$B$19)*(H27-1)/9 -> 0.28111111 | I29: =$B$19+($B$20-$B$19)*(I27-1)/9 -> 0.29333333 | J29: =$B$19+($B$20-$B$19)*(J27-1)/9 -> 0.30555556 | ... L29: =$B$19+($B$20-$B$19)*(L27-1)/9 -> 0.33
A30: Revenue | C30: =$B$16*(1+C28) -> 384.888 | D30: =C30*(1+D28) -> 441.33824 | E30: =D30*(1+E28) -> 500.18334 | F30: =E30*(1+F28) -> 560.20534 | G30: =F30*(1+G28) -> 619.96058 | H30: =G30*(1+H28) -> 677.82356 | I30: =H30*(1+I28) -> 732.04945 | J30: =I30*(1+J28) -> 780.85274 | K30: =J30*(1+K28) -> 822.49822 | L30: =K30*(1+L28) -> 855.39815
A31: Free cash flow to firm | C31: =C30*C29 -> 84.67536 | D31: =D30*D29 -> 102.48855 | E31: =E30*E29 -> 122.26704 | F31: =F30*F29 -> 143.78604 | G31: =G30*G29 -> 166.70051 | H31: =H30*H29 -> 190.54373 | I31: =I30*I29 -> 214.7345 | J31: =J30*J29 -> 238.59389 | ... L31: =L30*L29 -> 282.28139
A32: Discount factor | C32: =1/(1+$B$15)^C27 -> 0.91299187 | D32: =1/(1+$B$15)^D27 -> 0.83355416 | E32: =1/(1+$B$15)^E27 -> 0.76102818 | F32: =1/(1+$B$15)^F27 -> 0.69481254 | G32: =1/(1+$B$15)^G27 -> 0.63435821 | H32: =1/(1+$B$15)^H27 -> 0.57916389 | I32: =1/(1+$B$15)^I27 -> 0.52877192 | J32: =1/(1+$B$15)^J27 -> 0.48276447 | ... L32: =1/(1+$B$15)^L27 -> 0.40241033
A33: PV of FCFF | C33: =C31*C32 -> 77.307916 | D33: =D31*D32 -> 85.429755 | E33: =E31*E32 -> 93.048661 | F33: =F31*F32 -> 99.904342 | G33: =G31*G32 -> 105.74784 | H33: =H31*H32 -> 110.35605 | I33: =I31*I32 -> 113.54558 | J33: =J31*J32 -> 115.18465 | ... L33: =L31*L32 -> 113.59295
A35: Valuation
A36: Sum of PV of FCFF, years 1–10 | B36: =SUM(C33:L33) -> 1029.3199
A37: Terminal value (year 10) | B37: =L31*(1+B21)/(B15-B21) -> 4845.1283
A38: PV of terminal value | B38: =B37*L32 -> 1949.7297
A39: Enterprise value | B39: =B36+B38 -> 2979.0496
A40: Less: net debt | B40: =B22 -> 51.97
A41: Equity value | B41: =B39-B40 -> 2927.0796
A42: Value per share ($) | B42: =B41/B23 -> 392.89659
A43: Share price ($) | B43: =B6 -> 516.17
...

Sheet GOOGL
A1: Alphabet (GOOGL)
A2: 10-year FCFF DCF: revenue × FCF margin, both fading linearly, discounted at WACC; Gordon terminal value
A3: Inputs: company filings and market data as cited in the portfolio memo (not included) (Tickzen, Stock Titan, company guidance); prices 22–26 Sep 2026. $ in billions unless per share.
A5: Inputs
A6: Share price ($) | B6: 343.92
A7: Beta | B7: 1.15
A8: Risk-free rate | B8: =Assumptions!$B$5 -> 0.0523
A9: Equity risk premium | B9: =Assumptions!$C$5 -> 0.045
A10: Cost of equity | B10: =B8+B7*B9 -> 0.10405 | C10: CAPM
A11: Debt weight | B11: 0 | C11: Share of capital in debt
A12: Pre-tax cost of debt | B12: 0
A13: Tax rate | B13: 0
A14: WACC adjustment | B14: -0.002 | C14: Small haircut used for mega-caps with net cash / low leverage
A15: WACC | B15: =(1-B11)*B10+B11*B12*(1-B13)+B14 -> 0.10205
A16: Revenue, last 12 months ($bn) | B16: 445.9
A17: Revenue growth, year 1 | B17: 0.15
A18: Revenue growth, year 10 | B18: 0.04
A19: FCF margin, year 1 | B19: 0.18
A20: FCF margin, year 10 | B20: 0.27
A21: Terminal growth | B21: 0.035 | C21: Stock-specific; see Assumptions for market defaults
A22: Net debt ($bn) | B22: -121.68 | C22: Negative = net cash
A23: Diluted shares (bn) | B23: 12.06676 | C23: Market cap ÷ price at data date
C24: Deliberately generous margins (18% → 27%); net cash $122bn
A26: Projection ($bn)
A27: Year | C27: 1 | D27: 2 | E27: 3 | F27: 4 | G27: 5 | H27: 6 | I27: 7 | J27: 8 | K27: 9 | L27: 10
A28: Revenue growth | C28: =$B$17+($B$18-$B$17)*(C27-1)/9 -> 0.15 | D28: =$B$17+($B$18-$B$17)*(D27-1)/9 -> 0.13777778 | E28: =$B$17+($B$18-$B$17)*(E27-1)/9 -> 0.12555556 | F28: =$B$17+($B$18-$B$17)*(F27-1)/9 -> 0.11333333 | G28: =$B$17+($B$18-$B$17)*(G27-1)/9 -> 0.10111111 | H28: =$B$17+($B$18-$B$17)*(H27-1)/9 -> 0.088888889 | I28: =$B$17+($B$18-$B$17)*(I27-1)/9 -> 0.076666667 | J28: =$B$17+($B$18-$B$17)*(J27-1)/9 -> 0.064444444 | ... L28: =$B$17+($B$18-$B$17)*(L27-1)/9 -> 0.04
A29: FCF margin | C29: =$B$19+($B$20-$B$19)*(C27-1)/9 -> 0.18 | D29: =$B$19+($B$20-$B$19)*(D27-1)/9 -> 0.19 | E29: =$B$19+($B$20-$B$19)*(E27-1)/9 -> 0.2 | F29: =$B$19+($B$20-$B$19)*(F27-1)/9 -> 0.21 | G29: =$B$19+($B$20-$B$19)*(G27-1)/9 -> 0.22 | H29: =$B$19+($B$20-$B$19)*(H27-1)/9 -> 0.23 | I29: =$B$19+($B$20-$B$19)*(I27-1)/9 -> 0.24 | J29: =$B$19+($B$20-$B$19)*(J27-1)/9 -> 0.25 | ... L29: =$B$19+($B$20-$B$19)*(L27-1)/9 -> 0.27
A30: Revenue | C30: =$B$16*(1+C28) -> 512.785 | D30: =C30*(1+D28) -> 583.43538 | E30: =D30*(1+E28) -> 656.68893 | F30: =E30*(1+F28) -> 731.11368 | G30: =F30*(1+G28) -> 805.03739 | H30: =G30*(1+H28) -> 876.59627 | I30: =H30*(1+I28) -> 943.80199 | J30: =I30*(1+J28) -> 1004.6248 | K30: =J30*(1+K28) -> 1057.0885 | L30: =K30*(1+L28) -> 1099.3721
A31: Free cash flow to firm | C31: =C30*C29 -> 92.3013 | D31: =D30*D29 -> 110.85272 | E31: =E30*E29 -> 131.33779 | F31: =F30*F29 -> 153.53387 | G31: =G30*G29 -> 177.10823 | H31: =H30*H29 -> 201.61714 | I31: =I30*I29 -> 226.51248 | J31: =J30*J29 -> 251.1562 | ... L31: =L30*L29 -> 296.83046
A32: Discount factor | C32: =1/(1+$B$15)^C27 -> 0.90739985 | D32: =1/(1+$B$15)^D27 -> 0.82337448 | E32: =1/(1+$B$15)^E27 -> 0.74712988 | F32: =1/(1+$B$15)^F27 -> 0.67794553 | G32: =1/(1+$B$15)^G27 -> 0.61516767 | H32: =1/(1+$B$15)^H27 -> 0.55820305 | I32: =1/(1+$B$15)^I27 -> 0.50651336 | J32: =1/(1+$B$15)^J27 -> 0.45961015 | ... L32: =1/(1+$B$15)^L27 -> 0.37843127
A33: PV of FCFF | C33: =C31*C32 -> 83.754185 | D33: =D31*D32 -> 91.273302 | E33: =E31*E32 -> 98.126384 | F33: =F31*F32 -> 104.0876 | G33: =G31*G32 -> 108.95126 | H33: =H31*H32 -> 112.5433 | I33: =I31*I32 -> 114.7316 | J33: =J31*J32 -> 115.43394 | ... L33: =L31*L32 -> 112.32993
A35: Valuation
A36: Sum of PV of FCFF, years 1–10 | B36: =SUM(C33:L33) -> 1055.8548
A37: Terminal value (year 10) | B37: =L31*(1+B21)/(B15-B21) -> 4581.9466
A38: PV of terminal value | B38: =B37*L32 -> 1733.9519
A39: Enterprise value | B39: =B36+B38 -> 2789.8067
A40: Less: net debt | B40: =B22 -> -121.68
A41: Equity value | B41: =B39-B40 -> 2911.4867
A42: Value per share ($) | B42: =B41/B23 -> 241.28157
A43: Share price ($) | B43: =B6 -> 343.92
...

Sheet JNJ
A1: Johnson & Johnson (JNJ)
A2: 10-year FCFF DCF: revenue × FCF margin, both fading linearly, discounted at WACC; Gordon terminal value
A3: Inputs: company filings and market data as cited in the portfolio memo (not included) (Tickzen, Stock Titan, company guidance); prices 22–26 Sep 2026. $ in billions unless per share.
A5: Inputs
A6: Share price ($) | B6: 271.22
A7: Beta | B7: 0.55
A8: Risk-free rate | B8: =Assumptions!$B$5 -> 0.0523
A9: Equity risk premium | B9: =Assumptions!$C$5 -> 0.045
A10: Cost of equity | B10: =B8+B7*B9 -> 0.07705 | C10: CAPM
A11: Debt weight | B11: 0 | C11: Share of capital in debt
A12: Pre-tax cost of debt | B12: 0
A13: Tax rate | B13: 0
A14: WACC adjustment | B14: -0.002 | C14: Small haircut used for mega-caps with net cash / low leverage
A15: WACC | B15: =(1-B11)*B10+B11*B12*(1-B13)+B14 -> 0.07505
A16: Revenue, last 12 months ($bn) | B16: 97.8
A17: Revenue growth, year 1 | B17: 0.06
A18: Revenue growth, year 10 | B18: 0.035
A19: FCF margin, year 1 | B19: 0.173
A20: FCF margin, year 10 | B20: 0.21
A21: Terminal growth | B21: 0.035 | C21: Stock-specific; see Assumptions for market defaults
A22: Net debt ($bn) | B22: 28.28 | C22: Negative = net cash
A23: Diluted shares (bn) | B23: 2.3621783 | C23: Market cap ÷ price at data date
C24: Generous margin path (17.3% → 21%)
A26: Projection ($bn)
A27: Year | C27: 1 | D27: 2 | E27: 3 | F27: 4 | G27: 5 | H27: 6 | I27: 7 | J27: 8 | K27: 9 | L27: 10
A28: Revenue growth | C28: =$B$17+($B$18-$B$17)*(C27-1)/9 -> 0.06 | D28: =$B$17+($B$18-$B$17)*(D27-1)/9 -> 0.057222222 | E28: =$B$17+($B$18-$B$17)*(E27-1)/9 -> 0.054444444 | F28: =$B$17+($B$18-$B$17)*(F27-1)/9 -> 0.051666667 | G28: =$B$17+($B$18-$B$17)*(G27-1)/9 -> 0.048888889 | H28: =$B$17+($B$18-$B$17)*(H27-1)/9 -> 0.046111111 | I28: =$B$17+($B$18-$B$17)*(I27-1)/9 -> 0.043333333 | J28: =$B$17+($B$18-$B$17)*(J27-1)/9 -> 0.040555556 | ... L28: =$B$17+($B$18-$B$17)*(L27-1)/9 -> 0.035
A29: FCF margin | C29: =$B$19+($B$20-$B$19)*(C27-1)/9 -> 0.173 | D29: =$B$19+($B$20-$B$19)*(D27-1)/9 -> 0.17711111 | E29: =$B$19+($B$20-$B$19)*(E27-1)/9 -> 0.18122222 | F29: =$B$19+($B$20-$B$19)*(F27-1)/9 -> 0.18533333 | G29: =$B$19+($B$20-$B$19)*(G27-1)/9 -> 0.18944444 | H29: =$B$19+($B$20-$B$19)*(H27-1)/9 -> 0.19355556 | I29: =$B$19+($B$20-$B$19)*(I27-1)/9 -> 0.19766667 | J29: =$B$19+($B$20-$B$19)*(J27-1)/9 -> 0.20177778 | ... L29: =$B$19+($B$20-$B$19)*(L27-1)/9 -> 0.21
A30: Revenue | C30: =$B$16*(1+C28) -> 103.668 | D30: =C30*(1+D28) -> 109.60011 | E30: =D30*(1+E28) -> 115.56723 | F30: =E30*(1+F28) -> 121.5382 | G30: =F30*(1+G28) -> 127.48007 | H30: =G30*(1+H28) -> 133.35832 | I30: =H30*(1+I28) -> 139.13718 | J30: =I30*(1+J28) -> 144.77997 | K30: =J30*(1+K28) -> 150.24943 | L30: =K30*(1+L28) -> 155.50816
A31: Free cash flow to firm | C31: =C30*C29 -> 17.934564 | D31: =D30*D29 -> 19.411398 | E31: =E30*E29 -> 20.94335 | F31: =F30*F29 -> 22.525081 | G31: =G30*G29 -> 24.150391 | H31: =H30*H29 -> 25.812244 | I31: =I30*I29 -> 27.502783 | J31: =J30*J29 -> 29.21338 | ... L31: =L30*L29 -> 32.656714
A32: Discount factor | C32: =1/(1+$B$15)^C27 -> 0.93018929 | D32: =1/(1+$B$15)^D27 -> 0.86525212 | E32: =1/(1+$B$15)^E27 -> 0.80484826 | F32: =1/(1+$B$15)^F27 -> 0.74866123 | G32: =1/(1+$B$15)^G27 -> 0.69639666 | H32: =1/(1+$B$15)^H27 -> 0.64778072 | I32: =1/(1+$B$15)^I27 -> 0.60255869 | J32: =1/(1+$B$15)^J27 -> 0.56049364 | ... L32: =1/(1+$B$15)^L27 -> 0.48496831
A33: PV of FCFF | C33: =C31*C32 -> 16.682539 | D33: =D31*D32 -> 16.795753 | E33: =E31*E32 -> 16.856219 | F33: =F31*F32 -> 16.863655 | G33: =G31*G32 -> 16.818252 | H33: =H31*H32 -> 16.720674 | I33: =I31*I32 -> 16.572041 | J33: =J31*J32 -> 16.373914 | ... L33: =L31*L32 -> 15.837471
A35: Valuation
A36: Sum of PV of FCFF, years 1–10 | B36: =SUM(C33:L33) -> 165.64879
A37: Terminal value (year 10) | B37: =L31*(1+B21)/(B15-B21) -> 843.93755
A38: PV of terminal value | B38: =B37*L32 -> 409.28297
A39: Enterprise value | B39: =B36+B38 -> 574.93176
A40: Less: net debt | B40: =B22 -> 28.28
A41: Equity value | B41: =B39-B40 -> 546.65176
A42: Value per share ($) | B42: =B41/B23 -> 231.4185
A43: Share price ($) | B43: =B6 -> 271.22
...

Sheet CI
A1: Cigna Group (CI)
A2: Two-stage FCFE: +4%/yr for 5 years, then 0% forever (prices PBM reform)
A3: Inputs: company filings and market data as cited in the portfolio memo (not included) (Tickzen, Stock Titan, company guidance); prices 22–26 Sep 2026. $ in billions unless per share.
A5: Inputs
A6: Share price ($) | B6: 274.47
A7: Beta | B7: 0.7
A8: Risk-free rate | B8: =Assumptions!$B$5 -> 0.0523
A9: Equity risk premium | B9: =Assumptions!$C$5 -> 0.045
A10: Cost of equity | B10: =B8+B7*B9 -> 0.0838 | C10: CAPM
A11: Free cash flow to equity, last 12 months ($bn) | B11: 8
A12: Stage-1 growth | B12: 0.04
A13: Stage-1 years | B13: 5
A14: Terminal growth | B14: 0
A15: Shares (bn) | B15: 0.26578497 | C15: Market cap ÷ price at data date
A17: Projection ($bn)
A18: Year | C18: 1 | D18: 2 | E18: 3 | F18: 4 | G18: 5
A19: Cash flow | C19: =$B$11*(1+$B$12) -> 8.32 | D19: =C19*(1+$B$12) -> 8.6528 | E19: =D19*(1+$B$12) -> 8.998912 | F19: =E19*(1+$B$12) -> 9.3588685 | G19: =F19*(1+$B$12) -> 9.7332232
A20: Discount factor | C20: =1/(1+$B$10)^C18 -> 0.92267946 | D20: =1/(1+$B$10)^D18 -> 0.85133739 | E20: =1/(1+$B$10)^E18 -> 0.78551152 | F20: =1/(1+$B$10)^F18 -> 0.72477535 | G20: =1/(1+$B$10)^G18 -> 0.66873533
A21: PV | C21: =C19*C20 -> 7.6766931 | D21: =D19*D20 -> 7.3664522 | E21: =E19*E20 -> 7.0687491 | F21: =F19*F20 -> 6.7830772 | G21: =G19*G20 -> 6.5089502
A23: Valuation
A24: Sum of PV, years 1–5 | B24: =SUM(C21:G21) -> 35.403922
A25: Terminal value (year 5) | B25: =G19*(1+B14)/(B10-B14) -> 116.14825
A26: PV of terminal value | B26: =B25*G20 -> 77.672437
A27: Equity value | B27: =B24+B26 -> 113.07636
A28: Value per share ($) | B28: =B27/B15 -> 425.44302
A29: Share price ($) | B29: =B6 -> 274.47
A30: Upside / (downside) | B30: =B28/B29-1 -> 0.5500529
A31: Price ÷ current cash flow | B31: =B6/(B11/B15) -> 9.11875
A33: Sensitivity: value per share ($)
A34: Cost of equity ↓ / terminal growth → | B34: -0.02 | C34: 0 | D34: 0.02
A35: =B10+(-0.01) -> 0.0738 | B35: =(SUMPRODUCT($C$19:$G$19,1/(1+$A35)^$C$18:$G$18)+$G$19*(1+B$34)/($A35-B$34)/(1+$A35)^5)/$B$15 -> 404.8671 | C35: =(SUMPRODUCT($C$19:$G$19,1/(1+$A35)^$C$18:$G$18)+$G$19*(1+C$34)/($A35-C$34)/(1+$A35)^5)/$B$15 -> 484.44702 | D35: =(SUMPRODUCT($C$19:$G$19,1/(1+$A35)^$C$18:$G$18)+$G$19*(1+D$34)/($A35-D$34)/(1+$A35)^5)/$B$15 -> 623.19415
A36: =B10+(0) -> 0.0838 | B36: =(SUMPRODUCT($C$19:$G$19,1/(1+$A36)^$C$18:$G$18)+$G$19*(1+B$34)/($A36-B$34)/(1+$A36)^5)/$B$15 -> 364.41654 | C36: =(SUMPRODUCT($C$19:$G$19,1/(1+$A36)^$C$18:$G$18)+$G$19*(1+C$34)/($A36-C$34)/(1+$A36)^5)/$B$15 -> 425.44302 | D36: =(SUMPRODUCT($C$19:$G$19,1/(1+$A36)^$C$18:$G$18)+$G$19*(1+D$34)/($A36-D$34)/(1+$A36)^5)/$B$15 -> 524.73061
A37: =B10+(0.01) -> 0.0938 | B37: =(SUMPRODUCT($C$19:$G$19,1/(1+$A37)^$C$18:$G$18)+$G$19*(1+B$34)/($A37-B$34)/(1+$A37)^5)/$B$15 -> 331.12234 | C37: =(SUMPRODUCT($C$19:$G$19,1/(1+$A37)^$C$18:$G$18)+$G$19*(1+C$34)/($A37-C$34)/(1+$A37)^5)/$B$15 -> 379.05809 | D37: =(SUMPRODUCT($C$19:$G$19,1/(1+$A37)^$C$18:$G$18)+$G$19*(1+D$34)/($A37-D$34)/(1+$A37)^5)/$B$15 -> 452.97527

Sheet VICI
A1: VICI Properties (VICI)
A2: Two-stage AFFO discount: organic rent growth only (2% for 5 years, then 1.5%)
A3: Inputs: company filings and market data as cited in the portfolio memo (not included) (Tickzen, Stock Titan, company guidance); prices 22–26 Sep 2026. $ in billions unless per share.
A5: Inputs
A6: Share price ($) | B6: 23.71
A7: Beta | B7: 0.9
A8: Risk-free rate | B8: =Assumptions!$B$5 -> 0.0523
A9: Equity risk premium | B9: =Assumptions!$C$5 -> 0.045
A10: Cost of equity | B10: =B8+B7*B9 -> 0.0928 | C10: CAPM
A11: AFFO per share, forward ($) | B11: 2.5140449
A12: Stage-1 growth | B12: 0.02
A13: Stage-1 years | B13: 5
A14: Terminal growth | B14: 0.015
A15: Per-share model (shares = 1) | B15: 1
A17: Projection ($/share)
A18: Year | C18: 1 | D18: 2 | E18: 3 | F18: 4 | G18: 5
A19: Cash flow | C19: =$B$11*(1+$B$12) -> 2.5643258 | D19: =C19*(1+$B$12) -> 2.6156124 | E19: =D19*(1+$B$12) -> 2.6679246 | F19: =E19*(1+$B$12) -> 2.7212831 | G19: =F19*(1+$B$12) -> 2.7757088
A20: Discount factor | C20: =1/(1+$B$10)^C18 -> 0.91508053 | D20: =1/(1+$B$10)^D18 -> 0.83737237 | E20: =1/(1+$B$10)^E18 -> 0.76626315 | F20: =1/(1+$B$10)^F18 -> 0.70119249 | G20: =1/(1+$B$10)^G18 -> 0.64164759
A21: PV | C21: =C19*C20 -> 2.3465646 | D21: =D19*D20 -> 2.1902415 | E21: =E19*E20 -> 2.0443323 | F21: =F19*F20 -> 1.9081433 | G21: =G19*G20 -> 1.7810268
A23: Valuation
A24: Sum of PV, years 1–5 | B24: =SUM(C21:G21) -> 10.270309
A25: Terminal value (year 5) | B25: =G19*(1+B14)/(B10-B14) -> 36.212653
A26: PV of terminal value | B26: =B25*G20 -> 23.235761
A27: Equity value | B27: =B24+B26 -> 33.50607
A28: Value per share ($) | B28: =B27/B15 -> 33.50607
A29: Share price ($) | B29: =B6 -> 23.71
A30: Upside / (downside) | B30: =B28/B29-1 -> 0.41316196
A31: Price ÷ current cash flow | B31: =B6/(B11/B15) -> 9.4310168
A33: Sensitivity: value per share ($)
A34: Cost of equity ↓ / terminal growth → | B34: 0.005 | C34: 0.015 | D34: 0.025
A35: =B10+(-0.01) -> 0.0828 | B35: =(SUMPRODUCT($C$19:$G$19,1/(1+$A35)^$C$18:$G$18)+$G$19*(1+B$34)/($A35-B$34)/(1+$A35)^5)/$B$15 -> 34.634053 | C35: =(SUMPRODUCT($C$19:$G$19,1/(1+$A35)^$C$18:$G$18)+$G$19*(1+C$34)/($A35-C$34)/(1+$A35)^5)/$B$15 -> 38.46205 | D35: =(SUMPRODUCT($C$19:$G$19,1/(1+$A35)^$C$18:$G$18)+$G$19*(1+D$34)/($A35-D$34)/(1+$A35)^5)/$B$15 -> 43.614614
A36: =B10+(0) -> 0.0928 | B36: =(SUMPRODUCT($C$19:$G$19,1/(1+$A36)^$C$18:$G$18)+$G$19*(1+B$34)/($A36-B$34)/(1+$A36)^5)/$B$15 -> 30.656778 | C36: =(SUMPRODUCT($C$19:$G$19,1/(1+$A36)^$C$18:$G$18)+$G$19*(1+C$34)/($A36-C$34)/(1+$A36)^5)/$B$15 -> 33.50607 | D36: =(SUMPRODUCT($C$19:$G$19,1/(1+$A36)^$C$18:$G$18)+$G$19*(1+D$34)/($A36-D$34)/(1+$A36)^5)/$B$15 -> 37.195862
A37: =B10+(0.01) -> 0.1028 | B37: =(SUMPRODUCT($C$19:$G$19,1/(1+$A37)^$C$18:$G$18)+$G$19*(1+B$34)/($A37-B$34)/(1+$A37)^5)/$B$15 -> 27.493885 | C37: =(SUMPRODUCT($C$19:$G$19,1/(1+$A37)^$C$18:$G$18)+$G$19*(1+C$34)/($A37-C$34)/(1+$A37)^5)/$B$15 -> 29.679399 | D37: =(SUMPRODUCT($C$19:$G$19,1/(1+$A37)^$C$18:$G$18)+$G$19*(1+D$34)/($A37-D$34)/(1+$A37)^5)/$B$15 -> 32.426741

Sheet T
A1: AT&T (T)
A2: FCFE perpetuity: value = FCFE × (1 + g) / (cost of equity − g)
A3: Inputs: company filings and market data as cited in the portfolio memo (not included) (Tickzen, Stock Titan, company guidance); prices 22–26 Sep 2026. $ in billions unless per share.
A5: Inputs
A6: Share price ($) | B6: 25.38
A7: Beta | B7: 0.45
A8: Risk-free rate | B8: =Assumptions!$B$5 -> 0.0523
A9: Equity risk premium | B9: =Assumptions!$C$5 -> 0.045
A10: Cost of equity | B10: =B8+B7*B9 -> 0.07255 | C10: CAPM
A11: Free cash flow to equity ($bn) | B11: 18
A12: Perpetual growth | B12: 0
A13: Shares (bn) | B13: 6.9901497 | C13: Market cap ÷ price at data date
C14: 2026 FCF guidance $18bn+ (~10% yield); valued at zero growth
A16: Valuation
A17: Equity value ($bn) | B17: =B11*(1+B12)/(B10-B12) -> 248.10476
A18: Value per share ($) | B18: =B17/B13 -> 35.493482
A19: Share price ($) | B19: =B6 -> 25.38
A20: Upside / (downside) | B20: =B18/B19-1 -> 0.39848236
A21: FCFE yield at current price | B21: =B11/(B6*B13) -> 0.1014599
A22: Implied growth at current price | B22: =(B10*B6*B13-B11)/(B6*B13+B11) -> -0.026246889
A24: Sensitivity: value per share ($)
A25: Cost of equity ↓ / growth → | B25: -0.01 | C25: 0 | D25: 0.01
A26: =B10+(-0.01) -> 0.06255 | B26: =$B$11*(1+B$25)/($A26-B$25)/$B$13 -> 35.138547 | C26: =$B$11*(1+C$25)/($A26-C$25)/$B$13 -> 41.1679 | D26: =$B$11*(1+D$25)/($A26-D$25)/$B$13 -> 49.491963
A27: =B10+(0) -> 0.07255 | B27: =$B$11*(1+B$25)/($A27-B$25)/$B$13 -> 30.881909 | C27: =$B$11*(1+C$25)/($A27-C$25)/$B$13 -> 35.493482 | D27: =$B$11*(1+D$25)/($A27-D$25)/$B$13 -> 41.579579
A28: =B10+(0.01) -> 0.08255 | B28: =$B$11*(1+B$25)/($A28-B$25)/$B$13 -> 27.545128 | C28: =$B$11*(1+C$25)/($A28-C$25)/$B$13 -> 31.193848 | D28: =$B$11*(1+D$25)/($A28-D$25)/$B$13 -> 35.848417

Sheet VZ
A1: Verizon (VZ)
A2: FCFE perpetuity: value = FCFE × (1 + g) / (cost of equity − g)
A3: Inputs: company filings and market data as cited in the portfolio memo (not included) (Tickzen, Stock Titan, company guidance); prices 22–26 Sep 2026. $ in billions unless per share.
A5: Inputs
A6: Share price ($) | B6: 47.08
A7: Beta | B7: 0.45
A8: Risk-free rate | B8: =Assumptions!$B$5 -> 0.0523
A9: Equity risk premium | B9: =Assumptions!$C$5 -> 0.045
A10: Cost of equity | B10: =B8+B7*B9 -> 0.07255 | C10: CAPM
A11: Free cash flow to equity ($bn) | B11: 18
A12: Perpetual growth | B12: 0
A13: Shares (bn) | B13: 4.4141886 | C13: Market cap ÷ price at data date
C14: FCFE ≈ $18bn (OCF $37.1bn − capex); zero growth
A16: Valuation
A17: Equity value ($bn) | B17: =B11*(1+B12)/(B10-B12) -> 248.10476
A18: Value per share ($) | B18: =B17/B13 -> 56.206197
A19: Share price ($) | B19: =B6 -> 47.08
A20: Upside / (downside) | B20: =B18/B19-1 -> 0.19384446
A21: FCFE yield at current price | B21: =B11/(B6*B13) -> 0.086613415
A22: Implied growth at current price | B22: =(B10*B6*B13-B11)/(B6*B13+B11) -> -0.012942428
A24: Sensitivity: value per share ($)
A25: Cost of equity ↓ / growth → | B25: -0.01 | C25: 0 | D25: 0.01
A26: =B10+(-0.01) -> 0.06255 | B26: =$B$11*(1+B$25)/($A26-B$25)/$B$13 -> 55.644135 | C26: =$B$11*(1+C$25)/($A26-C$25)/$B$13 -> 65.192 | D26: =$B$11*(1+D$25)/($A26-D$25)/$B$13 -> 78.373686
A27: =B10+(0) -> 0.07255 | B27: =$B$11*(1+B$25)/($A27-B$25)/$B$13 -> 48.903477 | C27: =$B$11*(1+C$25)/($A27-C$25)/$B$13 -> 56.206197 | D27: =$B$11*(1+D$25)/($A27-D$25)/$B$13 -> 65.84392
A28: =B10+(0.01) -> 0.08255 | B28: =$B$11*(1+B$25)/($A28-B$25)/$B$13 -> 43.619471 | C28: =$B$11*(1+C$25)/($A28-C$25)/$B$13 -> 49.397451 | D28: =$B$11*(1+D$25)/($A28-D$25)/$B$13 -> 56.768259

Sheet CMCSA
A1: Comcast (CMCSA)
A2: FCFE perpetuity: value = FCFE × (1 + g) / (cost of equity − g)
A3: Inputs: company filings and market data as cited in the portfolio memo (not included) (Tickzen, Stock Titan, company guidance); prices 22–26 Sep 2026. $ in billions unless per share.
A5: Inputs
A6: Share price ($) | B6: 21.91
A7: Beta | B7: 0.75
A8: Risk-free rate | B8: =Assumptions!$B$5 -> 0.0523
A9: Equity risk premium | B9: =Assumptions!$C$5 -> 0.045
A10: Cost of equity | B10: =B8+B7*B9 -> 0.08605 | C10: CAPM
A11: Free cash flow to equity ($bn) | B11: 12.7
A12: Perpetual growth | B12: -0.02
A13: Shares (bn) | B13: 4.3112734 | C13: Market cap ÷ price at data date
C14: FCFE $12.7bn; broadband losses priced as −2%/yr forever
A16: Valuation
A17: Equity value ($bn) | B17: =B11*(1+B12)/(B10-B12) -> 117.35974
A18: Value per share ($) | B18: =B17/B13 -> 27.221594
A19: Share price ($) | B19: =B6 -> 21.91
A20: Upside / (downside) | B20: =B18/B19-1 -> 0.24242786
A21: FCFE yield at current price | B21: =B11/(B6*B13) -> 0.13444844
A22: Implied growth at current price | B22: =(B10*B6*B13-B11)/(B6*B13+B11) -> -0.042662533
A24: Sensitivity: value per share ($)
A25: Cost of equity ↓ / growth → | B25: -0.04 | C25: -0.02 | D25: 0
A26: =B10+(-0.01) -> 0.07605 | B26: =$B$11*(1+B$25)/($A26-B$25)/$B$13 -> 24.368245 | C26: =$B$11*(1+C$25)/($A26-C$25)/$B$13 -> 30.055701 | D26: =$B$11*(1+D$25)/($A26-D$25)/$B$13 -> 38.734588
A27: =B10+(0) -> 0.08605 | B27: =$B$11*(1+B$25)/($A27-B$25)/$B$13 -> 22.435024 | C27: =$B$11*(1+C$25)/($A27-C$25)/$B$13 -> 27.221594 | D27: =$B$11*(1+D$25)/($A27-D$25)/$B$13 -> 34.233183
A28: =B10+(0.01) -> 0.09605 | B28: =$B$11*(1+B$25)/($A28-B$25)/$B$13 -> 20.785996 | C28: =$B$11*(1+C$25)/($A28-C$25)/$B$13 -> 24.875916 | D28: =$B$11*(1+D$25)/($A28-D$25)/$B$13 -> 30.669083

Sheet PYPL
A1: PayPal (PYPL)
A2: FCFE perpetuity: value = FCFE × (1 + g) / (cost of equity − g)
A3: Inputs: company filings and market data as cited in the portfolio memo (not included) (Tickzen, Stock Titan, company guidance); prices 22–26 Sep 2026. $ in billions unless per share.
A5: Inputs
A6: Share price ($) | B6: 55.04
A7: Beta | B7: 1.17
A8: Risk-free rate | B8: =Assumptions!$B$5 -> 0.0523
A9: Equity risk premium | B9: =Assumptions!$C$5 -> 0.045
A10: Cost of equity | B10: =B8+B7*B9 -> 0.10495 | C10: CAPM
A11: Free cash flow to equity ($bn) | B11: 5.6
A12: Perpetual growth | B12: 0.015
A13: Shares (bn) | B13: 0.81849564 | C13: Market cap ÷ price at data date
C14: FY25 FCF $5.6bn (~12% yield); 1.5% growth
A16: Valuation
A17: Equity value ($bn) | B17: =B11*(1+B12)/(B10-B12) -> 63.190661
A18: Value per share ($) | B18: =B17/B13 -> 77.203419
A19: Share price ($) | B19: =B6 -> 55.04
A20: Upside / (downside) | B20: =B18/B19-1 -> 0.40267839
A21: FCFE yield at current price | B21: =B11/(B6*B13) -> 0.12430633
A22: Implied growth at current price | B22: =(B10*B6*B13-B11)/(B6*B13+B11) -> -0.017216239
A24: Sensitivity: value per share ($)
A25: Cost of equity ↓ / growth → | B25: 0 | C25: 0.015 | D25: 0.03
A26: =B10+(-0.01) -> 0.09495 | B26: =$B$11*(1+B$25)/($A26-B$25)/$B$13 -> 72.057085 | C26: =$B$11*(1+C$25)/($A26-C$25)/$B$13 -> 86.859881 | D26: =$B$11*(1+D$25)/($A26-D$25)/$B$13 -> 108.5
A27: =B10+(0) -> 0.10495 | B27: =$B$11*(1+B$25)/($A27-B$25)/$B$13 -> 65.191236 | C27: =$B$11*(1+C$25)/($A27-C$25)/$B$13 -> 77.203419 | D27: =$B$11*(1+D$25)/($A27-D$25)/$B$13 -> 94.02368
A28: =B10+(0.01) -> 0.11495 | B28: =$B$11*(1+B$25)/($A28-B$25)/$B$13 -> 59.519967 | C28: =$B$11*(1+C$25)/($A28-C$25)/$B$13 -> 69.479215 | D28: =$B$11*(1+D$25)/($A28-D$25)/$B$13 -> 82.95556

Sheet KT
A1: KT Corporation (030200 · KRX)
A2: Systematic 10-year model: discounted earnings (payout = 1 − g/ROE) blended 50/50 with discounted free cash flow; growth = ½ consensus + ½ terminal for 5 years, then a 5-year fade
A3: Inputs: Stock Analysis statistics page, 22–28 Sep 2026. Per-share figures in local currency; FCF and market cap in trillions.
A5: Inputs
A6: Share price (KRW) | B6: 53400
A7: Forward P/E | B7: 7.32
A8: Trailing P/E | B8: 9.95
A9: Forward EPS (year 1) | B9: =B6/B7 -> 7295.082
A10: Consensus EPS growth (3-yr) | B10: -0.0116 | C10: Analyst consensus from data feed
A11: ROE (reported) | B11: 0.0715
A12: ROE used in payout | B12: =MAX(Assumptions!$B$12,MIN(Assumptions!$C$12,B11)) -> 0.08 | C12: Clipped 8–30%
A13: Beta (data feed) | B13: 0.09
A14: Beta used | B14: =MAX(Assumptions!$B$9,MIN(Assumptions!$C$9,B13)) -> 0.8 | C14: Clipped to 0.8–1.6
A15: Risk-free rate | B15: =Assumptions!$B$6 -> 0.0441
A16: Equity risk premium | B16: =Assumptions!$C$6 -> 0.055
A17: Cost of equity | B17: =B15+B14*B16 -> 0.0881 | C17: CAPM
A18: Market terminal growth | B18: =Assumptions!$D$6 -> 0.025
A19: Stage-1 growth | B19: =MAX(Assumptions!$B$11,MIN(0.5*B10+0.5*B18,Assumptions!$B$10,Assumptions!$C$10*B12)) -> 0.0067 | C19: Consensus shrunk halfway to terminal, capped
A20: Terminal growth used | B20: =MIN(B18,MAX(B19,0)) -> 0.0067 | C20: Shrinking firms get no market terminal growth
A21: Free cash flow (₩ tn) | B21: 2.18
A22: Market cap (₩ tn) | B22: 12.87
A23: FCF per share | B23: =B21/B22*B6 -> 9045.2214
A24: FCF leg base (capped at EPS) | B24: =MIN(B23,B9) -> 7295.082 | C24: FCF is never credited above earnings
A26: Projection (per share, KRW) | M26: Year 11 feeds the terminal value
A27: Year | C27: 1 | D27: 2 | E27: 3 | F27: 4 | G27: 5 | H27: 6 | I27: 7 | J27: 8 | K27: 9 | L27: 10 | M27: 11
A28: Growth into next year | C28: =$B$19 -> 0.0067 | D28: =$B$19 -> 0.0067 | E28: =$B$19 -> 0.0067 | F28: =$B$19 -> 0.0067 | G28: =$B$19 -> 0.0067 | H28: =$B$19+($B$20-$B$19)*(H27-5)/5 -> 0.0067 | I28: =$B$19+($B$20-$B$19)*(I27-5)/5 -> 0.0067 | J28: =$B$19+($B$20-$B$19)*(J27-5)/5 -> 0.0067 | K28: =$B$19+($B$20-$B$19)*(K27-5)/5 -> 0.0067 | L28: =$B$19+($B$20-$B$19)*(L27-5)/5 -> 0.0067 | M28: =$B$20 -> 0.0067
A29: EPS | C29: =$B$9 -> 7295.082 | D29: =C29*(1+C28) -> 7343.959 | E29: =D29*(1+D28) -> 7393.1635 | F29: =E29*(1+E28) -> 7442.6977 | G29: =F29*(1+F28) -> 7492.5638 | H29: =G29*(1+G28) -> 7542.764 | I29: =H29*(1+H28) -> 7593.3005 | J29: =I29*(1+I28) -> 7644.1756 | K29: =J29*(1+J28) -> 7695.3916 | ... M29: =L29*(1+L28) -> 7798.8553
A30: Payout = 1 − g/ROE | C30: =1-MAX(C28,0)/$B$12 -> 0.91625 | D30: =1-MAX(D28,0)/$B$12 -> 0.91625 | E30: =1-MAX(E28,0)/$B$12 -> 0.91625 | F30: =1-MAX(F28,0)/$B$12 -> 0.91625 | G30: =1-MAX(G28,0)/$B$12 -> 0.91625 | H30: =1-MAX(H28,0)/$B$12 -> 0.91625 | I30: =1-MAX(I28,0)/$B$12 -> 0.91625 | J30: =1-MAX(J28,0)/$B$12 -> 0.91625 | ... L30: =1-MAX(L28,0)/$B$12 -> 0.91625
A31: Distributable earnings | C31: =C29*C30 -> 6684.1189 | D31: =D29*D30 -> 6728.9024 | E31: =E29*E30 -> 6773.9861 | F31: =F29*F30 -> 6819.3718 | G31: =G29*G30 -> 6865.0616 | H31: =H29*H30 -> 6911.0575 | I31: =I29*I30 -> 6957.3616 | J31: =J29*J30 -> 7003.9759 | ... L31: =L29*L30 -> 7098.1436
A32: Discount factor | C32: =1/(1+$B$17)^C27 -> 0.91903318 | D32: =1/(1+$B$17)^D27 -> 0.84462198 | E32: =1/(1+$B$17)^E27 -> 0.77623562 | F32: =1/(1+$B$17)^F27 -> 0.71338629 | G32: =1/(1+$B$17)^G27 -> 0.65562567 | H32: =1/(1+$B$17)^H27 -> 0.60254174 | I32: =1/(1+$B$17)^I27 -> 0.55375585 | J32: =1/(1+$B$17)^J27 -> 0.50892 | ... L32: =1/(1+$B$17)^L27 -> 0.42984502
A33: PV of distributable earnings | C33: =C31*C32 -> 6142.927 | D33: =D31*D32 -> 5683.3789 | E33: =E31*E32 -> 5258.2093 | F33: =F31*F32 -> 4864.8464 | G33: =G31*G32 -> 4500.9106 | H33: =H31*H32 -> 4164.2006 | I33: =I31*I32 -> 3852.6797 | J33: =J31*J32 -> 3564.4634 | ... L33: =L31*L32 -> 3051.1017
A34: FCF per share | C34: =$B$24*(1+$B$19) -> 7343.959 | D34: =C34*(1+C28) -> 7393.1635 | E34: =D34*(1+D28) -> 7442.6977 | F34: =E34*(1+E28) -> 7492.5638 | G34: =F34*(1+F28) -> 7542.764 | H34: =G34*(1+G28) -> 7593.3005 | I34: =H34*(1+H28) -> 7644.1756 | J34: =I34*(1+I28) -> 7695.3916 | K34: =J34*(1+J28) -> 7746.9507 | ... M34: =L34*(1+L28) -> 7851.1076
A35: PV of FCF | C35: =C34*C32 -> 6749.342 | D35: =D34*D32 -> 6244.4284 | E35: =E34*E32 -> 5777.2871 | F35: =F34*F32 -> 5345.0923 | G35: =G34*G32 -> 4945.2297 | H35: =H34*H32 -> 4575.2805 | I35: =I34*I32 -> 4233.007 | J35: =J34*J32 -> 3916.3387 | ... L35: =L34*L32 -> 3352.2991
A37: Valuation (per share)
A38: Earnings leg: PV years 1–10 | B38: =SUM(C33:L33) -> 44380.526
A39: Earnings leg: PV of terminal value | B39: =M29*(1-B20/B12)/(B17-B20)*L32 -> 37733.956
A40: Earnings-model value | B40: =B38+B39 -> 82114.482
A41: FCF leg: PV years 1–10 | B41: =SUM(C35:L35) -> 48761.665
A42: FCF leg: PV of terminal value | B42: =M34/(B17-B20)*L32 -> 41458.962
A43: FCF-model value | B43: =IF(B21>0,B41+B42,0) -> 90220.627
...

Sheet LG Uplus
A1: LG Uplus Corp. (032640 · KRX)
A2: Systematic 10-year model: discounted earnings (payout = 1 − g/ROE) blended 50/50 with discounted free cash flow; growth = ½ consensus + ½ terminal for 5 years, then a 5-year fade
A3: Inputs: Stock Analysis statistics page, 22–28 Sep 2026. Per-share figures in local currency; FCF and market cap in trillions.
A5: Inputs
A6: Share price (KRW) | B6: 15020
A7: Forward P/E | B7: 8.25
A8: Trailing P/E | B8: 11.96
A9: Forward EPS (year 1) | B9: =B6/B7 -> 1820.6061
A10: Consensus EPS growth (3-yr) | B10: 0.1984 | C10: Analyst consensus from data feed
A11: ROE (reported) | B11: 0.0573
A12: ROE used in payout | B12: =MAX(Assumptions!$B$12,MIN(Assumptions!$C$12,B11)) -> 0.08 | C12: Clipped 8–30%
A13: Beta (data feed) | B13: 0.25
A14: Beta used | B14: =MAX(Assumptions!$B$9,MIN(Assumptions!$C$9,B13)) -> 0.8 | C14: Clipped to 0.8–1.6
A15: Risk-free rate | B15: =Assumptions!$B$6 -> 0.0441
A16: Equity risk premium | B16: =Assumptions!$C$6 -> 0.055
A17: Cost of equity | B17: =B15+B14*B16 -> 0.0881 | C17: CAPM
A18: Market terminal growth | B18: =Assumptions!$D$6 -> 0.025
A19: Stage-1 growth | B19: =MAX(Assumptions!$B$11,MIN(0.5*B10+0.5*B18,Assumptions!$B$10,Assumptions!$C$10*B12)) -> 0.048 | C19: Consensus shrunk halfway to terminal, capped
A20: Terminal growth used | B20: =MIN(B18,MAX(B19,0)) -> 0.025 | C20: Shrinking firms get no market terminal growth
A21: Free cash flow (₩ tn) | B21: 1.46
A22: Market cap (₩ tn) | B22: 6.37
A23: FCF per share | B23: =B21/B22*B6 -> 3442.5746
A24: FCF leg base (capped at EPS) | B24: =MIN(B23,B9) -> 1820.6061 | C24: FCF is never credited above earnings
A26: Projection (per share, KRW) | M26: Year 11 feeds the terminal value
A27: Year | C27: 1 | D27: 2 | E27: 3 | F27: 4 | G27: 5 | H27: 6 | I27: 7 | J27: 8 | K27: 9 | L27: 10 | M27: 11
A28: Growth into next year | C28: =$B$19 -> 0.048 | D28: =$B$19 -> 0.048 | E28: =$B$19 -> 0.048 | F28: =$B$19 -> 0.048 | G28: =$B$19 -> 0.048 | H28: =$B$19+($B$20-$B$19)*(H27-5)/5 -> 0.0434 | I28: =$B$19+($B$20-$B$19)*(I27-5)/5 -> 0.0388 | J28: =$B$19+($B$20-$B$19)*(J27-5)/5 -> 0.0342 | K28: =$B$19+($B$20-$B$19)*(K27-5)/5 -> 0.0296 | L28: =$B$19+($B$20-$B$19)*(L27-5)/5 -> 0.025 | M28: =$B$20 -> 0.025
A29: EPS | C29: =$B$9 -> 1820.6061 | D29: =C29*(1+C28) -> 1907.9952 | E29: =D29*(1+D28) -> 1999.5789 | F29: =E29*(1+E28) -> 2095.5587 | G29: =F29*(1+F28) -> 2196.1455 | H29: =G29*(1+G28) -> 2301.5605 | I29: =H29*(1+H28) -> 2401.4482 | J29: =I29*(1+I28) -> 2494.6244 | K29: =J29*(1+J28) -> 2579.9406 | ... M29: =L29*(1+L28) -> 2722.7145
A30: Payout = 1 − g/ROE | C30: =1-MAX(C28,0)/$B$12 -> 0.4 | D30: =1-MAX(D28,0)/$B$12 -> 0.4 | E30: =1-MAX(E28,0)/$B$12 -> 0.4 | F30: =1-MAX(F28,0)/$B$12 -> 0.4 | G30: =1-MAX(G28,0)/$B$12 -> 0.4 | H30: =1-MAX(H28,0)/$B$12 -> 0.4575 | I30: =1-MAX(I28,0)/$B$12 -> 0.515 | J30: =1-MAX(J28,0)/$B$12 -> 0.5725 | ... L30: =1-MAX(L28,0)/$B$12 -> 0.6875
A31: Distributable earnings | C31: =C29*C30 -> 728.24242 | D31: =D29*D30 -> 763.19806 | E31: =E29*E30 -> 799.83157 | F31: =F29*F30 -> 838.22348 | G31: =G29*G30 -> 878.45821 | H31: =H29*H30 -> 1052.9639 | I31: =I29*I30 -> 1236.7458 | J31: =J29*J30 -> 1428.1725 | ... L31: =L29*L30 -> 1826.2109
A32: Discount factor | C32: =1/(1+$B$17)^C27 -> 0.91903318 | D32: =1/(1+$B$17)^D27 -> 0.84462198 | E32: =1/(1+$B$17)^E27 -> 0.77623562 | F32: =1/(1+$B$17)^F27 -> 0.71338629 | G32: =1/(1+$B$17)^G27 -> 0.65562567 | H32: =1/(1+$B$17)^H27 -> 0.60254174 | I32: =1/(1+$B$17)^I27 -> 0.55375585 | J32: =1/(1+$B$17)^J27 -> 0.50892 | ... L32: =1/(1+$B$17)^L27 -> 0.42984502
A33: PV of distributable earnings | C33: =C31*C32 -> 669.27895 | D33: =D31*D32 -> 644.61386 | E33: =E31*E32 -> 620.85775 | F33: =F31*F32 -> 597.97714 | G33: =G31*G32 -> 575.93975 | H33: =H31*H32 -> 634.45472 | I33: =I31*I32 -> 684.85525 | J33: =J31*J32 -> 726.82554 | ... L33: =L31*L32 -> 784.98767
A34: FCF per share | C34: =$B$24*(1+$B$19) -> 1907.9952 | D34: =C34*(1+C28) -> 1999.5789 | E34: =D34*(1+D28) -> 2095.5587 | F34: =E34*(1+E28) -> 2196.1455 | G34: =F34*(1+F28) -> 2301.5605 | H34: =G34*(1+G28) -> 2412.0354 | I34: =H34*(1+H28) -> 2516.7178 | J34: =I34*(1+I28) -> 2614.3664 | K34: =J34*(1+J28) -> 2703.7777 | ... M34: =L34*(1+L28) -> 2853.4048
A35: PV of FCF | C35: =C34*C32 -> 1753.5108 | D35: =D34*D32 -> 1688.8883 | E35: =E34*E32 -> 1626.6473 | F35: =F34*F32 -> 1566.7001 | G35: =G34*G32 -> 1508.9621 | H35: =H34*H32 -> 1453.352 | I35: =I34*I32 -> 1393.6472 | J35: =J34*J32 -> 1330.5033 | ... L35: =L34*L32 -> 1196.6067
A37: Valuation (per share)
A38: Earnings leg: PV years 1–10 | B38: =SUM(C33:L33) -> 6699.9961
A39: Earnings leg: PV of terminal value | B39: =M29*(1-B20/B12)/(B17-B20)*L32 -> 12751.385
A40: Earnings-model value | B40: =B38+B39 -> 19451.381
A41: FCF leg: PV years 1–10 | B41: =SUM(C35:L35) -> 14783.414
A42: FCF leg: PV of terminal value | B42: =M34/(B17-B20)*L32 -> 19437.747
A43: FCF-model value | B43: =IF(B21>0,B41+B42,0) -> 34221.161
...

Sheet Krafton
A1: KRAFTON, Inc. (259960 · KRX)
A2: Systematic 10-year model: discounted earnings (payout = 1 − g/ROE) blended 50/50 with discounted free cash flow; growth = ½ consensus + ½ terminal for 5 years, then a 5-year fade
A3: Inputs: Stock Analysis statistics page, 22–28 Sep 2026. Per-share figures in local currency; FCF and market cap in trillions.
A5: Inputs
A6: Share price (KRW) | B6: 200000
A7: Forward P/E | B7: 8.54
A8: Trailing P/E | B8: 10.61
A9: Forward EPS (year 1) | B9: =B6/B7 -> 23419.204
A10: Consensus EPS growth (3-yr) | B10: 0.1931 | C10: Analyst consensus from data feed
A11: ROE (reported) | B11: 0.1171
A12: ROE used in payout | B12: =MAX(Assumptions!$B$12,MIN(Assumptions!$C$12,B11)) -> 0.1171 | C12: Clipped 8–30%
A13: Beta (data feed) | B13: 0.71
A14: Beta used | B14: =MAX(Assumptions!$B$9,MIN(Assumptions!$C$9,B13)) -> 0.8 | C14: Clipped to 0.8–1.6
A15: Risk-free rate | B15: =Assumptions!$B$6 -> 0.0441
A16: Equity risk premium | B16: =Assumptions!$C$6 -> 0.055
A17: Cost of equity | B17: =B15+B14*B16 -> 0.0881 | C17: CAPM
A18: Market terminal growth | B18: =Assumptions!$D$6 -> 0.025
A19: Stage-1 growth | B19: =MAX(Assumptions!$B$11,MIN(0.5*B10+0.5*B18,Assumptions!$B$10,Assumptions!$C$10*B12)) -> 0.07026 | C19: Consensus shrunk halfway to terminal, capped
A20: Terminal growth used | B20: =MIN(B18,MAX(B19,0)) -> 0.025 | C20: Shrinking firms get no market terminal growth
A21: Free cash flow (₩ tn) | B21: 0.95063
A22: Market cap (₩ tn) | B22: 8.69
A23: FCF per share | B23: =B21/B22*B6 -> 21878.711
A24: FCF leg base (capped at EPS) | B24: =MIN(B23,B9) -> 21878.711 | C24: FCF is never credited above earnings
A26: Projection (per share, KRW) | M26: Year 11 feeds the terminal value
A27: Year | C27: 1 | D27: 2 | E27: 3 | F27: 4 | G27: 5 | H27: 6 | I27: 7 | J27: 8 | K27: 9 | L27: 10 | M27: 11
