Workbook

Sheet Cover
B1: POSCO Holdings (KRX: 005490) — DCF valuation
B2: Five-year FCFF DCF through the steel cycle, sensitivity and reverse DCF. Public information only. Not investment advice.
B4: Prepared by | C4: Jung Ryul Lee
B5: Data as of | C5: Share price 8 Oct 2026; balance sheet 30 Jun 2026; FY2025 actuals
B6: Units | C6: KRW billion unless noted
B8: What this model does
B9: Values POSCO Holdings at a cyclical trough: FY2025 operating margin was 2.7% against a mid-cycle 6-9%.
B10: Margins recover to 7% by 2030 while battery-materials capex fades from 8% to 6% of revenue.
B11: The question is how much of today's price already assumes that recovery (reverse DCF).
B13: Key outputs (live links)
B14: Implied value per share (KRW) | C14: =DCF!B53 -> 510607.18
B15: Share price, 8 Oct 2026 (KRW) | C15: =DCF!B6 -> 309500
B16: Upside / (downside) | C16: =DCF!B7 -> 0.64978088
B17: WACC | C17: =DCF!B19 -> 0.077189716
B18: Terminal value share of EV | C18: =DCF!B54 -> 0.84610344
B19: Implied terminal EV/EBITDA | C19: =DCF!B55 -> 7.0989852
B20: Market-implied perpetuity growth (reverse DCF) | C20: =DCF!B73 -> -0.0019240872
B21: Sensitivity check (should read OK) | C21: =DCF!B67 -> 0
B23: Contents
B24: DCF | C24: Inputs, WACC, FCFF projection, valuation bridge, sensitivity, reverse DCF
B25: Notes & Sources | C25: Base data, assumptions and sources
B27: Colour code
B28: 1,234 Blue text: hard-coded input
B29: 1,234 Black text: formula
B30: 1,234 Green text: link to another sheet
B31: Shaded yellow: key assumption to flex
B32: Shaded green: key output
B34: Method notes and limitations
B35: • The terminal multiple (~7x EBITDA) is above the ~5-6x steel peers trade on: the 7% terminal margin is the key lever.
B36: • WACC uses total debt at book value against market equity; POSCO's equity weight is below 50%, so the WACC is relatively insensitive to the cost of equity.
B37: • End-of-year discounting; FY2026 treated as a full forecast year.
B38: • Holding-company structure: no sum-of-the-parts or listed-subsidiary discount is applied.
B40: Review log (changes in this published version)
... B47: Sources
B48: POSCO Holdings balance sheet (stockanalysis.com) | C48: https://stockanalysis.com/stocks/pkx/financials/balance-sheet/
B49: Share price (Investing.com) | C49: https://hk.investing.com/equities/posco-inc
B50: Treasury share cancellation plan (Korea Times, Feb 2026) | C50: https://www.koreatimes.co.kr/business/20260220/posco-holdings-to-cancel-6351-bil-won-in-treasury-shares-in-2026
B52: Disclaimer
B53: Built from public information for training and portfolio purposes. Not investment advice and not a recommendation to buy or sell any security. Figures marked approximate should be checked against the original filings.

Sheet DCF
A1: POSCO Holdings (KRX: 005490) — Discounted Cash Flow Valuation
A2: Practice valuation built from public data. KRW billion unless noted. Blue = input, yellow = key lever. Share price 8 Oct 2026; balance sheet 30 Jun 2026; FY2025 actuals.
A4: SUMMARY
A5: Implied value per share (KRW) | B5: =B53 -> 510607.18
A6: Current share price (KRW) | B6: 309500
A7: Implied upside / (downside) | B7: =B5/B6-1 -> 0.64978088
A9: WACC ASSUMPTIONS
A10: Risk-free rate (Korea 10Y govt) | B10: 0.0441
A11: Equity risk premium | B11: 0.07
A12: Beta (levered) | B12: 1.2
A13: Cost of equity = rf + β × ERP | B13: =B10+B12*B11 -> 0.1281
A14: Pre-tax cost of debt | B14: 0.05
A15: Tax rate | B15: 0.24
A16: After-tax cost of debt | B16: =B14*(1-B15) -> 0.038
A17: Market value of equity (KRW bn) | B17: =B6*B24/1000 -> 23404.39
A18: Total debt (KRW bn) | B18: 30404
A19: WACC | B19: =(B17/(B17+B18))*B13+(B18/(B17+B18))*B16 -> 0.077189716
A21: OTHER INPUTS
A22: Terminal growth rate (g) | B22: 0.02
A23: Net debt (KRW bn) | B23: 16106
A24: Shares outstanding (million) | B24: 75.62
A25: Δ Net working capital (% of Δ revenue) | B25: 0.05
A26: Non-controlling interests (KRW bn) | B26: 6697.6
A28: PROJECTION (KRW bn) | B28: 2025A | C28: 2026E | D28: 2027E | E28: 2028E | F28: 2029E | G28: 2030E
A29: Revenue growth % | C29: 0.03 | D29: 0.04 | E29: 0.04 | F29: 0.03 | G29: 0.03
A30: Revenue | B30: 69094.9 | C30: =B30*(1+C29) -> 71167.747 | D30: =C30*(1+D29) -> 74014.457 | E30: =D30*(1+E29) -> 76975.035 | F30: =E30*(1+F29) -> 79284.286 | G30: =F30*(1+G29) -> 81662.815
A31: EBIT (operating) margin % | B31: =B32/B30 -> 0.026653197 | C31: 0.04 | D31: 0.05 | E31: 0.06 | F31: 0.065 | G31: 0.07
A32: EBIT (operating income) | B32: 1841.6 | C32: =C30*C31 -> 2846.7099 | D32: =D30*D31 -> 3700.7228 | E32: =E30*E31 -> 4618.5021 | F32: =F30*F31 -> 5153.4786 | G32: =G30*G31 -> 5716.397
A33: NOPAT = EBIT × (1 − tax) | C33: =C32*(1-$B$15) -> 2163.4995 | D33: =D32*(1-$B$15) -> 2812.5494 | E33: =E32*(1-$B$15) -> 3510.0616 | F33: =F32*(1-$B$15) -> 3916.6437 | G33: =G32*(1-$B$15) -> 4344.4617
A34: D&A % of revenue | B34: =B35/B30 -> 0.060406774 | C34: 0.06 | D34: 0.06 | E34: 0.06 | F34: 0.06 | G34: 0.06
A35: Depreciation & amortisation | B35: 4173.8 | C35: =C30*C34 -> 4270.0648 | D35: =D30*D34 -> 4440.8674 | E35: =E30*E34 -> 4618.5021 | F35: =F30*F34 -> 4757.0572 | G35: =G30*G34 -> 4899.7689
A36: Capex % of revenue | B36: =B37/B30 -> 0.08199158 | C36: 0.08 | D36: 0.075 | E36: 0.07 | F36: 0.065 | G36: 0.06
A37: Capital expenditure | B37: 5665.2 | C37: =C30*C36 -> 5693.4198 | D37: =D30*D36 -> 5551.0843 | E37: =E30*E36 -> 5388.2525 | F37: =F30*F36 -> 5153.4786 | G37: =G30*G36 -> 4899.7689
A38: Δ Net working capital | C38: =(C30-B30)*$B$25 -> 103.64235 | D38: =(D30-C30)*$B$25 -> 142.33549 | E38: =(E30-D30)*$B$25 -> 148.02891 | F38: =(F30-E30)*$B$25 -> 115.46255 | G38: =(G30-F30)*$B$25 -> 118.92643
A39: Free cash flow to firm (FCFF) | C39: =C33+C35-C37-C38 -> 636.50222 | D39: =D33+D35-D37-D38 -> 1559.997 | E39: =E33+E35-E37-E38 -> 2592.2823 | F39: =F33+F35-F37-F38 -> 3404.7598 | G39: =G33+G35-G37-G38 -> 4225.5353
A40: Discount period (yrs) | C40: 1 | D40: 2 | E40: 3 | F40: 4 | G40: 5
A41: Discount factor | C41: =1/(1+$B$19)^C40 -> 0.92834158 | D41: =1/(1+$B$19)^D40 -> 0.86181808 | E41: =1/(1+$B$19)^E40 -> 0.80006156 | F41: =1/(1+$B$19)^F40 -> 0.74273041 | G41: =1/(1+$B$19)^G40 -> 0.68950752
A42: PV of FCFF | C42: =C39*C41 -> 590.89147 | D42: =D39*D41 -> 1344.4336 | E42: =E39*E41 -> 2073.9854 | F42: =F39*F41 -> 2528.8186 | G42: =G39*G41 -> 2913.5384
A45: VALUATION (KRW bn)
A46: Sum of PV of forecast FCFF | B46: =SUM(C42:G42) -> 9451.6675
...

Sheet Notes & Sources
A1: POSCO Holdings DCF — base data & sources
A3: Item | B3: Value used | C3: Source / note
A4: FY2025 revenue | B4: KRW 69,094.9 bn | C4: stockanalysis.com PKX income statement; company FY2025 results (~KRW 69.1tn, -4.9% YoY).
A5: FY2025 operating income | B5: KRW 1,841.6 bn | C5: stockanalysis.com — 2.67% operating margin, a cyclical trough vs mid-cycle 6-9%.
A6: FY2025 net income | B6: KRW 657.7 bn | C6: stockanalysis.com.
A7: FY2025 D&A | B7: KRW 4,173.8 bn | C7: stockanalysis.com cash flow statement (~6% of revenue).
A8: FY2025 capex | B8: KRW 5,665.2 bn | C8: stockanalysis.com — elevated (~8.2% of rev) by battery-materials investment.
A9: Total debt (Jun-2026) | B9: KRW 30,404 bn | C9: stockanalysis.com balance sheet.
A10: Cash & equivalents (Jun-2026) | B10: KRW 14,298 bn | C10: stockanalysis.com balance sheet.
A11: Net debt (Jun-2026) | B11: KRW 16,106 bn | C11: Total debt minus cash.
A12: Shares outstanding | B12: 75.62 million | C12: Excl. treasury shares (stockanalysis.com, Jun 2026); 6% of issued shares cancelled 2024-26.
A13: Share price | B13: KRW 309,500 | C13: 8 Oct 2026 (Investing.com, delayed quote).
A14: Non-controlling interests (Jun-2026) | B14: KRW 6,697.6 bn | C14: stockanalysis.com balance sheet; deducted in the equity bridge.
A15: KEY ASSUMPTIONS
A16: Revenue growth | B16: 3% / 4% / 4% / 3% / 3% | C16: Modest recovery from the steel down-cycle plus battery-materials growth.
A17: EBIT margin path | B17: 4% → 7% | C17: Margin recovery toward mid-cycle as steel margins normalise and lithium/battery turns profitable (Q2-2026 inflection).
A18: Tax rate | B18: 24% | C18: Korea effective corporate rate (assumption).
A19: D&A | B19: 6% of revenue | C19: In line with FY2025.
A20: Capex | B20: 8% → 6% of revenue | C20: Declines as the battery investment cycle matures.
A21: Terminal growth | B21: 2.0% | C21: Long-run inflation/GDP.
A22: WACC | B22: ~7.8% | C22: rf 4.41% (Korea 10Y KTB, late Sep 2026) + β 1.20 × ERP 7.0% for Ke; Kd 5% pre-tax; market weights.
A24: IMPORTANT | C24: Practice model on public information, not investment advice. Every blue/yellow cell is an assumption to challenge.
