Workbook

Sheet Cover
B1: Coway (021240 · KRX) — Systematic 10-yr earnings/FCF valuation
B2: One of 18 stocks valued for a hedged US–Korea–Japan portfolio. Prices 22–28 Sep 2026. Not investment advice.
B4: Prepared by | C4: Jung Ryul Lee
B5: Data as of | C5: Prices 22–28 Sep 2026
B6: Units | C6: KRW per share; FCF and market cap in trillions
B8: What this model does
B9: Systematic 10-year model: discounted distributable earnings (payout = 1 − g/ROE) blended 50/50 with discounted FCF.
B10: Growth = half consensus, half terminal for five years, then a five-year fade; beta, growth and ROE are bounded.
B11: Built as a consistent screen across Korean/Japanese names from data-feed statistics, not a full company model.
B13: Key outputs (live links)
B14: Value per share | C14: =DCF!B44 -> 170910.16
B15: Share price | C15: =DCF!B45 -> 95200
B16: Upside / (downside) | C16: =DCF!B46 -> 0.7952748
B17: Cost of equity | C17: =DCF!B17 -> 0.0881
B18: Clears the portfolio's 15% hurdle | C18: =IF(DCF!B46>=Assumptions!B13,"Yes","No") -> Yes
B19: Held in the portfolio | C19: Yes
B21: Contents
B22: DCF | C22: Inputs, projection, valuation and sensitivity
B23: Assumptions | C23: Shared market inputs: risk-free rate, equity risk premium, terminal growth; model guard-rails
B25: Colour code
B26: 1,234 Blue text: hard-coded input
B27: 1,234 Black text: formula
B28: 1,234 Green text: link to another sheet
B29: Shaded yellow: key assumption to flex
B30: Shaded green: key output
B32: Method notes and limitations
B33: • Inputs come from company filings and market-data pages cited in the portfolio memo (not included).
B34: • Market inputs are shared with the other 17 models so valuations are comparable across stocks.
B36: Disclaimer
B37: Built from public information for training and portfolio purposes. Not investment advice and not a recommendation to buy or sell any security. Figures marked approximate should be checked against the original filings.

Sheet DCF
A1: COWAY Co., Ltd. (021240 · KRX)
A2: Systematic 10-year model: discounted earnings (payout = 1 − g/ROE) blended 50/50 with discounted free cash flow; growth = ½ consensus + ½ terminal for 5 years, then a 5-year fade
A3: Inputs: Stock Analysis statistics page, 22–28 Sep 2026. Per-share figures in local currency; FCF and market cap in trillions.
A5: Inputs
A6: Share price (KRW) | B6: 95200
A7: Forward P/E | B7: 9.08
A8: Trailing P/E | B8: 9.86
A9: Forward EPS (year 1) | B9: =B6/B7 -> 10484.581
A10: Consensus EPS growth (3-yr) | B10: 0.1198 | C10: Analyst consensus from data feed
A11: ROE (reported) | B11: 0.1932
A12: ROE used in payout | B12: =MAX(Assumptions!$B$12,MIN(Assumptions!$C$12,B11)) -> 0.1932 | C12: Clipped 8–30%
A13: Beta (data feed) | B13: 0.64
A14: Beta used | B14: =MAX(Assumptions!$B$9,MIN(Assumptions!$C$9,B13)) -> 0.8 | C14: Clipped to 0.8–1.6
A15: Risk-free rate | B15: =Assumptions!$B$6 -> 0.0441
A16: Equity risk premium | B16: =Assumptions!$C$6 -> 0.055
A17: Cost of equity | B17: =B15+B14*B16 -> 0.0881 | C17: CAPM
A18: Market terminal growth | B18: =Assumptions!$D$6 -> 0.025
A19: Stage-1 growth | B19: =MAX(Assumptions!$B$11,MIN(0.5*B10+0.5*B18,Assumptions!$B$10,Assumptions!$C$10*B12)) -> 0.0724 | C19: Consensus shrunk halfway to terminal, capped
A20: Terminal growth used | B20: =MIN(B18,MAX(B19,0)) -> 0.025 | C20: Shrinking firms get no market terminal growth
A21: Free cash flow (₩ tn) | B21: -0.20856
A22: Market cap (₩ tn) | B22: 6.68
A23: FCF per share | B23: =B21/B22*B6 -> -2972.2922
A24: FCF leg base (capped at EPS) | B24: =MIN(B23,B9) -> -2972.2922 | C24: FCF is never credited above earnings
A26: Projection (per share, KRW) | M26: Year 11 feeds the terminal value
A27: Year | C27: 1 | D27: 2 | E27: 3 | F27: 4 | G27: 5 | H27: 6 | I27: 7 | J27: 8 | K27: 9 | L27: 10 | M27: 11
A28: Growth into next year | C28: =$B$19 -> 0.0724 | D28: =$B$19 -> 0.0724 | E28: =$B$19 -> 0.0724 | F28: =$B$19 -> 0.0724 | G28: =$B$19 -> 0.0724 | H28: =$B$19+($B$20-$B$19)*(H27-5)/5 -> 0.06292 | I28: =$B$19+($B$20-$B$19)*(I27-5)/5 -> 0.05344 | J28: =$B$19+($B$20-$B$19)*(J27-5)/5 -> 0.04396 | K28: =$B$19+($B$20-$B$19)*(K27-5)/5 -> 0.03448 | L28: =$B$19+($B$20-$B$19)*(L27-5)/5 -> 0.025 | M28: =$B$20 -> 0.025
A29: EPS | C29: =$B$9 -> 10484.581 | D29: =C29*(1+C28) -> 11243.665 | E29: =D29*(1+D28) -> 12057.707 | F29: =E29*(1+E28) -> 12930.685 | G29: =F29*(1+F28) -> 13866.866 | H29: =G29*(1+G28) -> 14870.827 | I29: =H29*(1+H28) -> 15806.5 | J29: =I29*(1+I28) -> 16651.199 | K29: =J29*(1+J28) -> 17383.186 | ... M29: =L29*(1+L28) -> 18432.122
A30: Payout = 1 − g/ROE | C30: =1-MAX(C28,0)/$B$12 -> 0.6252588 | D30: =1-MAX(D28,0)/$B$12 -> 0.6252588 | E30: =1-MAX(E28,0)/$B$12 -> 0.6252588 | F30: =1-MAX(F28,0)/$B$12 -> 0.6252588 | G30: =1-MAX(G28,0)/$B$12 -> 0.6252588 | H30: =1-MAX(H28,0)/$B$12 -> 0.67432712 | I30: =1-MAX(I28,0)/$B$12 -> 0.72339545 | J30: =1-MAX(J28,0)/$B$12 -> 0.77246377 | ... L30: =1-MAX(L28,0)/$B$12 -> 0.87060041
A31: Distributable earnings | C31: =C29*C30 -> 6555.5768 | D31: =D29*D30 -> 7030.2006 | E31: =E29*E30 -> 7539.1871 | F31: =F29*F30 -> 8085.0243 | G31: =G29*G30 -> 8670.38 | H31: =H29*H30 -> 10027.802 | I31: =I29*I30 -> 11434.35 | J31: =J29*J30 -> 12862.448 | ... L31: =L29*L30 -> 15655.622
A32: Discount factor | C32: =1/(1+$B$17)^C27 -> 0.91903318 | D32: =1/(1+$B$17)^D27 -> 0.84462198 | E32: =1/(1+$B$17)^E27 -> 0.77623562 | F32: =1/(1+$B$17)^F27 -> 0.71338629 | G32: =1/(1+$B$17)^G27 -> 0.65562567 | H32: =1/(1+$B$17)^H27 -> 0.60254174 | I32: =1/(1+$B$17)^I27 -> 0.55375585 | J32: =1/(1+$B$17)^J27 -> 0.50892 | ... L32: =1/(1+$B$17)^L27 -> 0.42984502
A33: PV of distributable earnings | C33: =C31*C32 -> 6024.7926 | D33: =D31*D32 -> 5937.862 | E33: =E31*E32 -> 5852.1856 | F33: =F31*F32 -> 5767.7455 | G33: =G31*G32 -> 5684.5237 | H33: =H31*H32 -> 6042.1693 | I33: =I31*I32 -> 6331.8381 | J33: =J31*J32 -> 6545.957 | ... L33: =L31*L32 -> 6729.4913
A34: FCF per share | C34: =$B$24*(1+$B$19) -> -3187.4862 | D34: =C34*(1+C28) -> -3418.2602 | E34: =D34*(1+D28) -> -3665.7422 | F34: =E34*(1+E28) -> -3931.1419 | G34: =F34*(1+F28) -> -4215.7566 | H34: =G34*(1+G28) -> -4520.9774 | I34: =H34*(1+H28) -> -4805.4373 | J34: =I34*(1+I28) -> -5062.2399 | K34: =J34*(1+J28) -> -5284.7759 | ... M34: =L34*(1+L28) -> -5603.6699
A35: PV of FCF | C35: =C34*C32 -> -2929.4055 | D35: =D34*D32 -> -2887.1377 | E35: =E34*E32 -> -2845.4797 | F35: =F34*F32 -> -2804.4228 | G35: =G34*G32 -> -2763.9583 | H35: =H34*H32 -> -2724.0776 | I35: =I34*I32 -> -2661.039 | J35: =J34*J32 -> -2576.2751 | ... L35: =L34*L32 -> -2349.9606
A37: Valuation (per share)
A38: Earnings leg: PV years 1–10 | B38: =SUM(C33:L33) -> 61595.921
A39: Earnings leg: PV of terminal value | B39: =M29*(1-B20/B12)/(B17-B20)*L32 -> 109314.24
A40: Earnings-model value | B40: =B38+B39 -> 170910.16
A41: FCF leg: PV years 1–10 | B41: =SUM(C35:L35) -> -27013.522
A42: FCF leg: PV of terminal value | B42: =M34/(B17-B20)*L32 -> -38172.893
A43: FCF-model value | B43: =IF(B21>0,B41+B42,0) -> 0
...

Sheet Assumptions
A1: Market assumptions (CAPM)
A2: Blue = hardcoded input. Every model sheet links here (green), so changing a cell below re-values every stock in that market.
A4: Market | B4: Risk-free rate | C4: Equity risk premium | D4: Terminal growth | E4: Source / note
A5: US | B5: 0.0523 | C5: 0.045 | D5: 0.03 | E5: US 10-yr Treasury 5.23% (Washington Trust weekly review, 25 Sep 2026); ERP and terminal growth are author assumptions
A6: KR | B6: 0.0441 | C6: 0.055 | D6: 0.025 | E6: Korea 10-yr KTB 4.41% (Trading Economics, Sep 2026); ERP and terminal growth are author assumptions
A7: JP | B7: 0.0307 | C7: 0.05 | D7: 0.015 | E7: JGB 10-yr 3.07% (Trading Economics, 25 Sep 2026); ERP and terminal growth are author assumptions
A9: Beta floor / cap (systematic models) | B9: 0.8 | C9: 1.6 | E9: Data-feed betas are clipped to this range so no stock gets a cost of equity far below its market's
A10: Growth cap (systematic models) | B10: 0.1 | C10: 0.6 | E10: B = max first-stage growth; C = max growth as a multiple of ROE (payout floor 40%)
A11: Growth floor | B11: -0.05
A12: ROE clip for payout (low / high) | B12: 0.08 | C12: 0.3
A13: Hurdle (min. upside to hold) | B13: 0.15
