Workbook

Sheet Cover
B1: SK hynix / Intel NAND (Solidigm): cross-border M&A practice model
B2: Prepared by Jung Ryul for training purposes. Public information only. Not investment advice.
B4: The deal
B5: Signed 20 Oct 2020: SK hynix buys Intel's NAND and SSD business (excl. Optane) for US$9bn.
B6: Paid in two tranches: US$7bn at first closing (Dec 2021), ~US$1.9bn at final closing (Mar 2025).
B7: Cross-border: Korean buyer, US seller, Chinese fab (Dalian), USD price, KRW-reporting buyer.
B9: Key outputs (live)
B10: Purchase price at signing (KRW bn) | C10: =m_price -> 10247.85
B11: EV / EBIT paid | C11: =m_ev_ebit -> 7.5
B12: Year-1 EPS accretion (base case) | C12: =m_acc -> 0.095831819
B13: Extra KRW cost from the won's fall | C13: =h_fxcost -> 945.995
B14: Saving if hedged at signing (assumed rates) | C14: =h_saving -> 763.65202
B15: Probability-weighted NPV (US$ mn) | C15: =npv_exp -> 7630.2711
B16: 95th-percentile KRW cost, unhedged (KRW bn) | C16: =mc_p95 -> 12104.159
B17: Solidigm cumulative net income 2022-H1 2026 | C17: =Post_Mortem!C10 -> -68
B18: Input checks | C18: =IF(AND(chk_fin="OK",chk_prob="OK"),"OK","CHECK") -> OK
B20: How to use
B21: Summary: one-page deal summary with football field and formula-driven verdicts.
B22: Inputs: change shaded cells (financing, synergies, FX, hedge rates, scenarios, WACC).
B23: Deal_Structure: sources and uses, value of paying later, purchase price allocation, credit metrics.
B24: Model: year-1 accretion/dilution and why (yield vs. cost of funding).
B25: Scenarios and Valuation: bull/base/downturn cash flows, DCF, NPV, ROIC vs. WACC, realised IRR.
B26: Comps: precedent NAND deals and listed peers (approximate inputs flagged).
B27: FX_Hedge and FX_MonteCarlo: cost of the won's fall, forward vs. option, 2,000 simulated paths.
B28: Sensitivity, Post_Mortem, Practice (17 assessment-centre questions).
B29: Colours: blue = input, black = formula, green = link to another sheet, shaded = key assumption.

Sheet Summary
B1: SK hynix / Intel NAND: one-page deal summary
B2: Signed 20 Oct 2020. Live summary of this workbook; inputs on Inputs. Training material, not investment advice.
B4: Transaction | F4: Returns
B5: Headline price (US$ mn) | C5: =price_usd -> 9000 | F5: Year-1 EPS accretion (base financing) | G5: =m_acc -> 0.095831819
B6: Price at signing (KRW bn) | C6: =m_price -> 10247.85 | F6: WACC (USD) | G6: =wacc -> 0.069804
B7: EV / revenue (run-rate) | C7: =m_ev_rev -> 1.6071429 | F7: ROIC year 1, selected scenario | G7: =roic_y1 -> 0.087696
B8: EV / EBIT (run-rate) | C8: =m_ev_ebit -> 7.5 | F8: NPV, selected scenario (US$ mn) | G8: =npv_sel -> 6085.2424
B9: PV of price (deferred tranche, US$ mn) | C9: =ds_pv_price -> 8652.2967 | F9: NPV, probability-weighted (US$ mn) | G9: =npv_exp -> 7630.2711
B10: Goodwill as % of price | C10: =ppa_gw_pct -> 0.083333333 | F10: Realised IRR to today (KRW, illustrative) | G10: =irr_real -> 0.42278246
B11: Pro forma net debt / EBITDA | C11: =cr_pf_lev -> 1.0771245 | F11: Multiple of money (illustrative) | G11: =mom_real -> 4.5126435
B13: FX risk (KRW bn) | F13: Verdict (formula-driven)
B14: Cost at signing spot | C14: =h_krw_sign -> 10133.985 | F14: =IF(m_acc>0,"Accretive in year 1 at base financing ("&TEXT(m_acc,"0.0%")&")","Dilutive in year 1 ("&TEXT(m_acc,"0.0%")&")") -> Accretive in year 1 at base financing (9.6%)
B15: Cost if hedged at signing | C15: =h_krw_hedged -> 10316.328 | F15: =IF(npv_exp>0,"Value-creating on a probability-weighted DCF (+US$"&TEXT(npv_exp,"#,##0")&"mn)","Value-destroying on a probability-weighted DCF (US$"&TEXT(npv_exp,"#,##0")&"mn)") -> Value-creating on a probability-weighted DCF (+US$7,630mn)
B16: Actual cost (unhedged) | C16: =h_krw_actual -> 11079.98 | F16: =IF(npv_bear<0,"Downturn case destroys US$"&TEXT(-npv_bear,"#,##0")&"mn: the cycle is the key risk","Value-creating even in a downturn") -> Downturn case destroys US$5,644mn: the cycle is the key risk
B17: Simulated range, 5th-95th percentile | C17: =TEXT(mc_p5,"#,##0")&" - "&TEXT(mc_p95,"#,##0") -> 8,735 - 12,104 | F17: ="FX: unhedged cost ended at the "&TEXT(mc_actual_pct,"0%")&" percentile of simulated outcomes" -> FX: unhedged cost ended at the 78% percentile of simulated outcomes
B18: Actual outcome percentile | C18: =mc_actual_pct -> 0.783 | F18: =IF(cr_pf_lev<1.5,"Leverage stays modest at "&TEXT(cr_pf_lev,"0.0x"),"Leverage rises to "&TEXT(cr_pf_lev,"0.0x")&": rating pressure") -> Leverage stays modest at 1.1x
B19: Option on tranche 2 at the actual rate | C19: =op_cost_actual -> 2421.3752
B21: Valuation range (US$ bn): football field
B22: Method | C22: Low | D22: High | F22: Chart helper: width
B23: Listed peers, EV / revenue | C23: =trd_lo -> 6.3712575 | D23: =trd_hi -> 14.130841 | F23: =MAX(D23-C23,0.15) -> 7.7595836
B24: Precedent transactions, EV / revenue | C24: =prec_lo -> 12.444444 | D24: =prec_hi -> 19.136691 | F24: =MAX(D24-C24,0.15) -> 6.6922462
B25: DCF, selected scenario, WACC +/- 1% | C25: =ev_wlo/1000 -> 12.238423 | D25: =ev_whi/1000 -> 18.495804 | F25: =MAX(D25-C25,0.15) -> 6.2573815
B26: DCF, downturn to bull | C26: =MIN(sc_ev1,sc_ev2,sc_ev3)/1000 -> 3.0079669 | D26: =MAX(sc_ev1,sc_ev2,sc_ev3)/1000 -> 32.647226 | F26: =MAX(D26-C26,0.15) -> 29.639259
B27: Price paid: PV to headline | C27: =ds_pv_price/1000 -> 8.6522967 | D27: =price_usd/1000 -> 9 | F27: =MAX(D27-C27,0.15) -> 0.34770332
B46: Key risks flagged at signing
B47: NAND price cycle: run-rate earnings were near a cyclical high (realised: KRW 7.3tn losses in 2022-23).
B48: Regulatory: China SAMR approval for the Dalian fab (granted Dec 2021); later US export-control exposure.
B49: Carve-out: Intel segment profits include cost allocations; Intel kept running the fab until the final closing.
B50: FX: a four-year deferred USD payment for a KRW-reporting buyer.
B51: Integration: two-stage closing, US/China workforce, a new US subsidiary (Solidigm).

Sheet Inputs
B1: Inputs
B2: Blue = hard-coded input. Shaded = assumption you should flex. All other sheets are formulas on these cells.
B4: Input | C4: Value | D4: Unit | E4: Source / note
B6: Deal terms
B7: Signing / announcement | C7: 44124 | D7: date | E7: Intel 8-K Ex.99.1, 20 Oct 2020
B8: First closing (SSD business + Dalian fab) | C8: 44559 | D8: date | E8: Closed after China SAMR clearance (22 Dec 2021)
B9: Final closing (NAND IP, R&D, Dalian workforce) | C9: 45743 | D9: date | E9: Intel: ~US$1.9bn received, net of adjustments
B10: Headline purchase price | C10: 9000 | D10: US$ mn | E10: US$7bn at first closing + US$2bn at final closing
B11: Tranche 1 paid | C11: 7000 | D11: US$ mn | E11: First closing
B12: Tranche 2 paid | C12: 1900 | D12: US$ mn | E12: ~US$1.9bn net of adjustments (contracted US$2.0bn)
B14: FX (KRW per USD)
B15: USD/KRW at signing | C15: 1138.65 | D15: KRW | E15: Fed H.10 noon NY, 20 Oct 2020
B16: USD/KRW at first closing | C16: 1185.51 | D16: KRW | E16: Fed H.10, 29 Dec 2021
B17: USD/KRW at final closing | C17: 1463.9 | D17: KRW | E17: Fed H.10, 27 Mar 2025
B18: USD/KRW used to translate target earnings | C18: 1138.65 | D18: KRW | E18: Base = signing rate. Flex to see translation effect
B20: Hedging (covered interest parity)
B21: KRW interest rate for the hedge tenor | C21: 0.013 | D21: % p.a. | E21: ASSUMPTION ~5Y KTB, Oct 2020. Desks would use KRW CRS/IRS
B22: USD interest rate for the hedge tenor | C22: 0.0035 | D22: % p.a. | E22: ASSUMPTION ~5Y UST, Oct 2020
B23: Deal-contingent premium on the forward | C23: 0 | D23: % notional | E23: ASSUMPTION. Banks charge extra when the hedge lapses if the deal fails
B25: Target: Intel NAND business (run-rate)
B26: Revenue | C26: 5600 | D26: US$ mn | E26: 2 x H1 2020 (~US$2.8bn), Intel 8-K. Excludes Optane
B27: Operating income (EBIT) | C27: 1200 | D27: US$ mn | E27: 2 x H1 2020 contribution (~US$0.6bn), Intel 8-K. Segment allocation, not audited standalone
B29: Buyer: SK hynix (2020 base year)
B30: Net income | C30: 4760 | D30: KRW bn | E30: FY2020, ~KRW 4.76tn (Korea JoongAng Daily, 29 Jan 2021)
B31: Shares outstanding | C31: 728 | D31: mn | E31: ~728mn (issued shares; verify on DART)
B32: Share price for any new shares | C32: 83000 | D32: KRW | E32: ASSUMPTION ~Oct 2020 level; used only if stock is issued
B33: Tax rate | C33: 0.275 | D33: % | E33: Korea 2020 top rate 25% + 10% local surtax
B35: Financing (must sum to 100%)
B36: Cash on hand | C36: 0.5 | D36: % | E36: ASSUMPTION. SK hynix used cash and new borrowings
B37: New debt | C37: 0.5 | D37: % | E37: ASSUMPTION
B38: New shares | C38: 0 | D38: % | E38: ASSUMPTION (not used in the actual deal)
B39: Pre-tax cost of new debt | C39: 0.018 | D39: % p.a. | E39: ASSUMPTION ~AA KRW corporate bond, 2020
B40: Interest income forgone on cash | C40: 0.01 | D40: % p.a. | E40: ASSUMPTION ~KRW deposit rate, 2020
B42: Purchase price allocation and synergies
B43: Price allocated to amortisable intangibles | C43: 0.25 | D43: % of price | E43: ASSUMPTION (technology, customer relationships)
B44: Amortisation period | C44: 7 | D44: years | E44: ASSUMPTION
B45: Pre-tax run-rate synergies | C45: 0 | D45: US$ mn | E45: ASSUMPTION. Base case: none
B46: Book value of net assets acquired | C46: 5000 | D46: US$ mn | E46: ASSUMPTION (Dalian fab, inventory, receivables); not disclosed
B47: Fair-value step-up of PP&E (fab) | C47: 1000 | D47: US$ mn | E47: ASSUMPTION. Extra depreciation hits EPS
B48: Remaining life of stepped-up PP&E | C48: 5 | D48: years | E48: ASSUMPTION
...

Sheet Deal_Structure
B1: Deal structure: sources and uses, seller financing, purchase price allocation, credit
B2: US$ mn and KRW bn at the signing rate.
B4: Sources and uses
C5: US$ mn | D5: KRW bn | E5: Note
B6: Uses: purchase price | C6: =price_usd -> 9000 | D6: =C6*fx_ann/1000 -> 10247.85
B7: Uses: transaction fees | C7: =price_usd*fees_pct -> 45 | D7: =C7*fx_ann/1000 -> 51.23925 | E7: Expensed; not in run-rate EPS
B8: Total uses | C8: =su_price+su_fees -> 9045 | D8: =C8*fx_ann/1000 -> 10299.089
B9: Sources: cash on hand | C9: =su_uses*pct_cash -> 4522.5 | D9: =C9*fx_ann/1000 -> 5149.5446
B10: Sources: new debt | C10: =su_uses*pct_debt -> 4522.5 | D10: =C10*fx_ann/1000 -> 5149.5446 | E10: SK hynix raised US$2.5bn of USD bonds in Jan 2021
B11: Sources: new shares | C11: =su_uses*pct_stock -> 0 | D11: =C11*fx_ann/1000 -> 0
B12: Total sources | C12: =su_cash+su_debt+su_stock -> 9045 | D12: =C12*fx_ann/1000 -> 10299.089
B13: Check: sources = uses | C13: =IF(ABS(su_sources-su_uses)<0.01,"OK","CHECK") -> OK
B15: Paying later is seller financing: present value of the price
B16: Tranche 1, years after signing | C16: =(c1_date-ann_date)/365 -> 1.1917808
B17: Tranche 2, years after signing | C17: =(c2_date-ann_date)/365 -> 4.4356164
B18: Discount rate (SK hynix USD cost of debt) | C18: =kd_usd -> 0.0152
B19: PV of tranche 1 (US$ mn) | C19: =t1_usd/(1+ds_r)^ds_y1 -> 6875.2732
B20: PV of tranche 2 (US$ mn) | C20: =t2_usd/(1+ds_r)^ds_y2 -> 1777.0235
B21: PV of the price at signing (US$ mn) | C21: =ds_pv1+ds_pv2 -> 8652.2967 | E21: Includes ~US$100mn of closing adjustments plus the time value of the deferred tranche
B22: Value of paying later vs. headline (US$ mn) | C22: =price_usd-ds_pv_price -> 347.70332
B23: Effective EV / EBIT on a PV basis | C23: =ds_pv_price/tgt_ebit -> 7.2102472
B25: Purchase price allocation (US$ mn)
B26: Purchase price | C26: =price_usd -> 9000
B27: Less: book value of net assets acquired | C27: =-net_assets_usd -> -5000
B28: Excess purchase price | C28: =ppa_price+ppa_book -> 4000
B29: Less: PP&E step-up to fair value | C29: =-ppe_step -> -1000
B30: Less: identifiable intangibles | C30: =-price_usd*intang_pct -> -2250
B31: Goodwill (not amortised; tested for impairment) | C31: =ppa_excess+ppa_step+ppa_intang -> 750 | E31: Simplified: ignores deferred tax on step-ups. Goodwill was later at risk in the 2022-23 downturn.
B32: Goodwill as % of price | C32: =ppa_gw/ppa_price -> 0.083333333
B33: Annual extra depreciation (step-up) | C33: =ppe_step/ppe_life -> 200
B34: Annual amortisation (intangibles) | C34: =price_usd*intang_pct/amort_yrs -> 321.42857
B36: Check: goodwill not negative | C36: =IF(ppa_gw>=0,"OK","CHECK: bargain purchase") -> OK
B38: Credit metrics (KRW bn)
B39: Buyer net debt, standalone | C39: =buyer_nd -> 8800
B40: Buyer EBITDA, standalone | C40: =buyer_ebitda -> 15600
B41: Net debt / EBITDA, standalone | C41: =cr_nd/cr_ebitda -> 0.56410256
B42: Plus: cash used and new debt (both raise net debt) | C42: =(su_cash+su_debt)*fx_ann/1000 -> 10299.089
B43: Plus: target EBITDA (EBIT + D&A) | C43: =(tgt_ebit+tgt_rev*da_pct)*fx_earn/1000 -> 2131.5528
B44: Pro forma net debt | C44: =cr_nd+cr_add -> 19099.089
B45: Pro forma EBITDA | C45: =cr_ebitda+cr_tebitda -> 17731.553
...

Sheet Model
B1: Accretion / dilution, year 1 run-rate
B2: KRW bn unless stated. Earnings translated at fx_earn; price converted at the signing rate.
B5: Purchase price and funding
B6: Purchase price (US$ mn) | C6: =price_usd -> 9000
B7: Purchase price (KRW bn) | C7: =price_usd*fx_ann/1000 -> 10247.85 | E7: At the signing rate
B8: Funded with cash | C8: =m_price*pct_cash -> 5123.925
B9: Funded with new debt | C9: =m_price*pct_debt -> 5123.925
B10: Funded with new shares | C10: =m_price*pct_stock -> 0
B11: New shares issued (mn) | C11: =m_stock*1000/buyer_px -> 0 | E11: KRW bn x 1,000 / KRW per share = mn shares
B13: Target contribution
B14: Target EBIT | C14: =tgt_ebit*fx_earn/1000 -> 1366.38
B15: Synergies (pre-tax) | C15: =syn_usd*fx_earn/1000 -> 0
B16: Less: amortisation of acquired intangibles | C16: =-m_price*intang_pct/amort_yrs -> -365.99464 | E16: Non-cash, but hits reported EPS
B17: Less: depreciation of PP&E step-up | C17: =-ppe_step*fx_ann/1000/ppe_life -> -227.73 | E17: From the purchase price allocation
B18: Less: interest on new debt | C18: =-m_debt*kd -> -92.23065
B19: Less: interest income forgone on cash | C19: =-m_cash*ri -> -51.23925
B20: Pre-tax contribution | C20: =SUM(m_ebit,m_syn,m_amort,m_stepdep,m_int,m_forg) -> 629.18546
B21: Less: tax | C21: =-m_pretax*tax -> -173.026
B22: After-tax contribution | C22: =m_pretax+m_tax -> 456.15946
B24: EPS impact
B25: Buyer standalone net income | C25: =buyer_ni -> 4760
B26: Pro forma net income | C26: =m_ni+m_contrib -> 5216.1595
B27: Standalone shares (mn) | C27: =buyer_sh -> 728
B28: Pro forma shares (mn) | C28: =m_sh+m_newsh -> 728
B29: Standalone EPS (KRW) | C29: =m_ni*1000/m_sh -> 6538.4615
B30: Pro forma EPS (KRW) | C30: =m_pf_ni*1000/m_pf_sh -> 7165.0542
B31: Accretion / (dilution) | C31: =m_pf_eps/m_eps-1 -> 0.095831819
B32: Pre-tax cushion before EPS dilution | C32: =m_pretax-(m_ni*m_pf_sh/m_sh-m_ni)/(1-tax) -> 629.18546 | E32: How far pre-tax contribution can fall before the deal dilutes EPS
B33: Synergies needed to break even (US$ mn) | C33: =MAX(0,-m_cushion)*1000/fx_earn -> 0 | E33: Zero = accretive without synergies
B35: Why: earnings yield vs. cost of funding (after tax)
B36: Target pre-tax earnings yield (EBIT / price) | C36: =m_ebit/m_price -> 0.13333333
B37: Target after-tax yield, after PPA D&A | C37: =(m_ebit+m_amort+m_stepdep)*(1-tax)/m_price -> 0.054662698
B38: After-tax cost of cash | C38: =ri*(1-tax) -> 0.00725
B39: After-tax cost of debt | C39: =kd*(1-tax) -> 0.01305
B40: Cost of stock (buyer earnings yield = 1 / P/E) | C40: =m_eps/buyer_px -> 0.078776645
B41: Blended after-tax cost of funding | C41: =pct_cash*m_c_cash+pct_debt*m_c_debt+pct_stock*m_c_stock -> 0.01015 | E41: Accretive when target after-tax yield > blended cost
B42: Buyer P/E at the assumed share price | C42: =buyer_px/m_eps -> 12.694118
B44: Valuation multiples paid
B45: EV / revenue | C45: =price_usd/tgt_rev -> 1.6071429 | E45: Price treated as enterprise value (asset deal, no debt assumed)
B46: EV / EBIT | C46: =price_usd/tgt_ebit -> 7.5

Sheet Scenarios
B1: Multi-year scenarios for the NAND business (US$ mn unless stated)
B2: Blue rows are scenario assumptions. The downturn case is calibrated loosely to Solidigm's 2022-23 losses; reality then added an AI boom (see reported row).
B4: Year | D4: 2021 | E4: 2022 | F4: 2023 | G4: 2024 | H4: 2025 | I4: 2026
B5: Period t (years after signing, approx.) | D5: 1 | E5: 2 | F5: 3 | G5: 4 | H5: 5 | I5: 6
B7: 1. Bull: steady growth, firm margins
B8: Revenue growth | D8: 0.15 | E8: 0.15 | F8: 0.15 | G8: 0.15 | H8: 0.15 | I8: 0.15
B9: EBIT margin | D9: 0.25 | E9: 0.25 | F9: 0.25 | G9: 0.25 | H9: 0.25 | I9: 0.25
B10: Revenue | D10: =tgt_rev*(1+D8) -> 6440 | E10: =D10*(1+E8) -> 7406 | F10: =E10*(1+F8) -> 8516.9 | G10: =F10*(1+G8) -> 9794.435 | H10: =G10*(1+H8) -> 11263.6 | I10: =H10*(1+I8) -> 12953.14
B11: EBIT | D11: =D10*D9 -> 1610 | E11: =E10*E9 -> 1851.5 | F11: =F10*F9 -> 2129.225 | G11: =G10*G9 -> 2448.6087 | H11: =H10*H9 -> 2815.9001 | I11: =I10*I9 -> 3238.2851
B12: NOPAT | D12: =D11*(1-tax) -> 1167.25 | E12: =E11*(1-tax) -> 1342.3375 | F12: =F11*(1-tax) -> 1543.6881 | G12: =G11*(1-tax) -> 1775.2413 | H12: =H11*(1-tax) -> 2041.5275 | I12: =I11*(1-tax) -> 2347.7567
B13: D&A | D13: =D10*da_pct -> 772.8 | E13: =E10*da_pct -> 888.72 | F13: =F10*da_pct -> 1022.028 | G13: =G10*da_pct -> 1175.3322 | H13: =H10*da_pct -> 1351.632 | I13: =I10*da_pct -> 1554.3768
B14: Capex | D14: =-D10*capex_pct -> -772.8 | E14: =-E10*capex_pct -> -888.72 | F14: =-F10*capex_pct -> -1022.028 | G14: =-G10*capex_pct -> -1175.3322 | H14: =-H10*capex_pct -> -1351.632 | I14: =-I10*capex_pct -> -1554.3768
B15: Change in working capital | D15: =-(D10-tgt_rev)*nwc_pct -> -84 | E15: =-(E10-D10)*nwc_pct -> -96.6 | F15: =-(F10-E10)*nwc_pct -> -111.09 | G15: =-(G10-F10)*nwc_pct -> -127.7535 | H15: =-(H10-G10)*nwc_pct -> -146.91653 | I15: =-(I10-H10)*nwc_pct -> -168.954
B16: Free cash flow | D16: =SUM(D12:D15) -> 1083.25 | E16: =SUM(E12:E15) -> 1245.7375 | F16: =SUM(F12:F15) -> 1432.5981 | G16: =SUM(G12:G15) -> 1647.4878 | H16: =SUM(H12:H15) -> 1894.611 | I16: =SUM(I12:I15) -> 2178.8027 | J16: NOPAT + D&A - capex - change in working capital
B17: Discount factor | D17: =1/(1+wacc)^D$5 -> 0.93475066 | E17: =1/(1+wacc)^E$5 -> 0.8737588 | F17: =1/(1+wacc)^F$5 -> 0.81674662 | G17: =1/(1+wacc)^G$5 -> 0.76345445 | H17: =1/(1+wacc)^H$5 -> 0.71363955 | I17: =1/(1+wacc)^I$5 -> 0.66707505
B18: PV of FCF | D18: =D16*D17 -> 1012.5687 | E18: =E16*E17 -> 1088.4741 | F18: =F16*F17 -> 1170.0697 | G18: =G16*G17 -> 1257.7819 | H18: =H16*H17 -> 1352.0694 | I18: =I16*I17 -> 1453.4249
B19: After-tax contribution to SK hynix (KRW bn) | D19: =(D11*fx_earn/1000+m_amort+m_stepdep+m_int+m_forg)*(1-tax) -> 794.62317 | E19: =(E11*fx_earn/1000+m_amort+m_stepdep+m_int+m_forg)*(1-tax) -> 993.98655 | F19: =(F11*fx_earn/1000+m_amort+m_stepdep+m_int+m_forg)*(1-tax) -> 1223.2544 | G19: =(G11*fx_earn/1000+m_amort+m_stepdep+m_int+m_forg)*(1-tax) -> 1486.9125 | H19: =(H11*fx_earn/1000+m_amort+m_stepdep+m_int+m_forg)*(1-tax) -> 1790.1193 | I19: =(I11*fx_earn/1000+m_amort+m_stepdep+m_int+m_forg)*(1-tax) -> 2138.8071 | J19: Target EBIT less PPA D&A and funding costs, after tax
B20: as % of 2020 SK hynix net income | D20: =D19/buyer_ni -> 0.16693764 | E20: =E19/buyer_ni -> 0.2088207 | F20: =F19/buyer_ni -> 0.25698623 | G20: =G19/buyer_ni -> 0.31237658 | H20: =H19/buyer_ni -> 0.37607548 | I20: =I19/buyer_ni -> 0.44932922
B21: ROIC (NOPAT / price) | D21: =D12/price_usd -> 0.12969444 | E21: =E12/price_usd -> 0.14914861 | F21: =F12/price_usd -> 0.1715209 | G21: =G12/price_usd -> 0.19724904 | H21: =H12/price_usd -> 0.22683639 | I21: =I12/price_usd -> 0.26086185
B22: Terminal: mid-cycle EBIT margin (C) > normalised FCF (H) > PV (I) | C22: 0.2 | H22: =I10*(1+tg)*C22*(1-tax)-I10*tg*nwc_pct -> 1889.8632 | I22: =H22/(wacc-tg)*I17 -> 25312.838 | J22: Cyclicals: value the terminal year at mid-cycle, not at the last forecast year's margin
B23: Enterprise value at signing (US$ mn) | I23: =SUM(D18:I18)+I22 -> 32647.226
B25: 2. Base: modest growth, mid-cycle margins
B26: Revenue growth | D26: 0.08 | E26: 0.05 | F26: 0.05 | G26: 0.05 | H26: 0.05 | I26: 0.05
B27: EBIT margin | D27: 0.18 | E27: 0.15 | F27: 0.15 | G27: 0.15 | H27: 0.15 | I27: 0.15
B28: Revenue | D28: =tgt_rev*(1+D26) -> 6048 | E28: =D28*(1+E26) -> 6350.4 | F28: =E28*(1+F26) -> 6667.92 | G28: =F28*(1+G26) -> 7001.316 | H28: =G28*(1+H26) -> 7351.3818 | I28: =H28*(1+I26) -> 7718.9509
B29: EBIT | D29: =D28*D27 -> 1088.64 | E29: =E28*E27 -> 952.56 | F29: =F28*F27 -> 1000.188 | G29: =G28*G27 -> 1050.1974 | H29: =H28*H27 -> 1102.7073 | I29: =I28*I27 -> 1157.8426
B30: NOPAT | D30: =D29*(1-tax) -> 789.264 | E30: =E29*(1-tax) -> 690.606 | F30: =F29*(1-tax) -> 725.1363 | G30: =G29*(1-tax) -> 761.39311 | H30: =H29*(1-tax) -> 799.46277 | I30: =I29*(1-tax) -> 839.43591
B31: D&A | D31: =D28*da_pct -> 725.76 | E31: =E28*da_pct -> 762.048 | F31: =F28*da_pct -> 800.1504 | G31: =G28*da_pct -> 840.15792 | H31: =H28*da_pct -> 882.16582 | I31: =I28*da_pct -> 926.27411
B32: Capex | D32: =-D28*capex_pct -> -725.76 | E32: =-E28*capex_pct -> -762.048 | F32: =-F28*capex_pct -> -800.1504 | G32: =-G28*capex_pct -> -840.15792 | H32: =-H28*capex_pct -> -882.16582 | I32: =-I28*capex_pct -> -926.27411
B33: Change in working capital | D33: =-(D28-tgt_rev)*nwc_pct -> -44.8 | E33: =-(E28-D28)*nwc_pct -> -30.24 | F33: =-(F28-E28)*nwc_pct -> -31.752 | G33: =-(G28-F28)*nwc_pct -> -33.3396 | H33: =-(H28-G28)*nwc_pct -> -35.00658 | I33: =-(I28-H28)*nwc_pct -> -36.756909
B34: Free cash flow | D34: =SUM(D30:D33) -> 744.464 | E34: =SUM(E30:E33) -> 660.366 | F34: =SUM(F30:F33) -> 693.3843 | G34: =SUM(G30:G33) -> 728.05351 | H34: =SUM(H30:H33) -> 764.45619 | I34: =SUM(I30:I33) -> 802.679 | J34: NOPAT + D&A - capex - change in working capital
B35: Discount factor | D35: =1/(1+wacc)^D$5 -> 0.93475066 | E35: =1/(1+wacc)^E$5 -> 0.8737588 | F35: =1/(1+wacc)^F$5 -> 0.81674662 | G35: =1/(1+wacc)^G$5 -> 0.76345445 | H35: =1/(1+wacc)^H$5 -> 0.71363955 | I35: =1/(1+wacc)^I$5 -> 0.66707505
B36: PV of FCF | D36: =D34*D35 -> 695.88822 | E36: =E34*E35 -> 577.00061 | F36: =F34*F35 -> 566.31929 | G36: =G34*G35 -> 555.8357 | H36: =H34*H35 -> 545.54617 | I36: =I34*I35 -> 535.44713
B37: After-tax contribution to SK hynix (KRW bn) | D37: =(D29*fx_earn/1000+m_amort+m_stepdep+m_int+m_forg)*(1-tax) -> 364.22941 | E37: =(E29*fx_earn/1000+m_amort+m_stepdep+m_int+m_forg)*(1-tax) -> 251.89248 | F37: =(F29*fx_earn/1000+m_amort+m_stepdep+m_int+m_forg)*(1-tax) -> 291.2104 | G37: =(G29*fx_earn/1000+m_amort+m_stepdep+m_int+m_forg)*(1-tax) -> 332.49423 | H37: =(H29*fx_earn/1000+m_amort+m_stepdep+m_int+m_forg)*(1-tax) -> 375.84224 | I37: =(I29*fx_earn/1000+m_amort+m_stepdep+m_int+m_forg)*(1-tax) -> 421.35765 | J37: Target EBIT less PPA D&A and funding costs, after tax
B38: as % of 2020 SK hynix net income | D38: =D37/buyer_ni -> 0.076518784 | E38: =E37/buyer_ni -> 0.052918588 | F38: =F37/buyer_ni -> 0.061178656 | G38: =G37/buyer_ni -> 0.069851728 | H38: =H37/buyer_ni -> 0.078958454 | I38: =I37/buyer_ni -> 0.088520516
B39: ROIC (NOPAT / price) | D39: =D30/price_usd -> 0.087696 | E39: =E30/price_usd -> 0.076734 | F39: =F30/price_usd -> 0.0805707 | G39: =G30/price_usd -> 0.084599235 | H39: =H30/price_usd -> 0.088829197 | I39: =I30/price_usd -> 0.093270657
B40: Terminal: mid-cycle EBIT margin (C) > normalised FCF (H) > PV (I) | C40: 0.15 | H40: =I28*(1+tg)*C40*(1-tax)-I28*tg*nwc_pct -> 840.78673 | I40: =H40/(wacc-tg)*I35 -> 11261.502 | J40: Cyclicals: value the terminal year at mid-cycle, not at the last forecast year's margin
B41: Enterprise value at signing (US$ mn) | I41: =SUM(D36:I36)+I40 -> 14737.539
B43: 3. Downturn: 2022-23 style memory bust, slow recovery
B44: Revenue growth | D44: 0.1 | E44: -0.15 | F44: -0.3 | G44: 0.1 | H44: 0.1 | I44: 0.1
...

Sheet Valuation
B1: Value creation: DCF, NPV, ROIC vs. WACC, realised IRR
B2: US$ mn unless stated. Valuation date: signing (Oct 2020).
B4: Cost of capital (USD)
B5: Cost of equity = rf + beta x ERP + premium | C5: =rf_usd+beta*erp+crp -> 0.0845
B6: After-tax cost of debt | C6: =kd_usd*(1-tax) -> 0.01102
B7: WACC | C7: =(1-wd)*ke+wd*kd_at -> 0.069804
B9: DCF vs. price paid
C10: Bull | D10: Base | E10: Downturn | F10: Probability-weighted
B11: Enterprise value (DCF) | C11: =sc_ev1 -> 32647.226 | D11: =sc_ev2 -> 14737.539 | E11: =sc_ev3 -> 3007.9669 | F11: =SUMPRODUCT(C11:E11,C15:E15) -> 16282.568
B12: PV of price paid | C12: =ds_pv_price -> 8652.2967 | D12: =ds_pv_price -> 8652.2967 | E12: =ds_pv_price -> 8652.2967 | F12: =ds_pv_price -> 8652.2967
B13: NPV to SK hynix | C13: =C11-C12 -> 23994.93 | D13: =D11-D12 -> 6085.2424 | E13: =E11-E12 -> -5644.3298 | F13: =F11-F12 -> 7630.2711
B14: NPV as % of PV price | C14: =C13/C12 -> 2.773244 | D14: =D13/D12 -> 0.7033095 | E14: =E13/E12 -> -0.65235047 | F14: =F13/F12 -> 0.88187812
B15: Probability | C15: =p_bull -> 0.25 | D15: =p_base -> 0.5 | E15: =p_bear -> 0.25
B16: Selected scenario NPV | C16: =CHOOSE(scen,C13,D13,E13) -> 6085.2424
B18: WACC sensitivity, selected scenario (US$ mn)
C19: WACC -1% | D19: Base WACC | E19: WACC +1%
B20: WACC used | C20: =wacc+(-0.01) -> 0.059804 | D20: =wacc+(0) -> 0.069804 | E20: =wacc+(0.01) -> 0.079804
B21: Enterprise value | C21: =SUMPRODUCT(Scenarios!$D$64:$I$64/(1+C20)^Scenarios!$D$5:$I$5)+CHOOSE(scen,sc_tfcf1,sc_tfcf2,sc_tfcf3)/(C20-tg)/(1+C20)^Scenarios!$I$5 -> 18495.804 | D21: =SUMPRODUCT(Scenarios!$D$64:$I$64/(1+D20)^Scenarios!$D$5:$I$5)+CHOOSE(scen,sc_tfcf1,sc_tfcf2,sc_tfcf3)/(D20-tg)/(1+D20)^Scenarios!$I$5 -> 14737.539 | E21: =SUMPRODUCT(Scenarios!$D$64:$I$64/(1+E20)^Scenarios!$D$5:$I$5)+CHOOSE(scen,sc_tfcf1,sc_tfcf2,sc_tfcf3)/(E20-tg)/(1+E20)^Scenarios!$I$5 -> 12238.423
B22: NPV vs. PV price | C22: =C21-ds_pv_price -> 9843.5073 | D22: =D21-ds_pv_price -> 6085.2424 | E22: =E21-ds_pv_price -> 3586.1258
B24: ROIC vs. WACC, selected scenario
B25: Year | C25: 2021 | D25: 2022 | E25: 2023 | F25: 2024 | G25: 2025 | H25: 2026
B26: ROIC (NOPAT / price) | C26: =Scenarios!D66 -> 0.087696 | D26: =Scenarios!E66 -> 0.076734 | E26: =Scenarios!F66 -> 0.0805707 | F26: =Scenarios!G66 -> 0.084599235 | G26: =Scenarios!H66 -> 0.088829197 | H26: =Scenarios!I66 -> 0.093270657
B27: WACC | C27: =wacc -> 0.069804 | D27: =wacc -> 0.069804 | E27: =wacc -> 0.069804 | F27: =wacc -> 0.069804 | G27: =wacc -> 0.069804 | H27: =wacc -> 0.069804
B28: Spread (value created if > 0) | C28: =C26-C27 -> 0.017892 | D28: =D26-D27 -> 0.00693 | E28: =E26-E27 -> 0.0107667 | F28: =F26-F27 -> 0.014795235 | G28: =G26-G27 -> 0.019025197 | H28: =H26-H27 -> 0.023466657
B30: Realised outcome: IRR in KRW to today (illustrative)
B31: Cash flow | C31: Date | D31: KRW bn
B32: Tranche 1 paid | C32: =c1_date -> 44559 | D32: =-FX_Hedge!K5 -> -8298.57 | I32: Excludes Solidigm's interim profits/losses and SK hynix's funding costs. Today's value is reported pre-IPO talk, not a price.
B33: Tranche 2 paid | C33: =c2_date -> 45743 | D33: =-FX_Hedge!K6 -> -2781.41
B34: Value of Solidigm today | C34: =val_date -> 46313 | D34: =val_krw -> 50000
B35: Realised IRR (KRW, XIRR) | D35: =XIRR(D32:D34,C32:C34) -> 0.42278246
B36: Multiple of money (value / KRW paid) | D36: =D34/-(D32+D33) -> 4.5126435
B38: Realised IRR if Solidigm is worth less than reported (KRW bn)
B39: Value today | C39: 15000 | D39: 25000 | E39: 35000 | F39: 50000
B40: Tranche 1 (KRW bn) | C40: =D32 -> -8298.57 | D40: =D32 -> -8298.57 | E40: =D32 -> -8298.57 | F40: =D32 -> -8298.57
B41: Tranche 2 (KRW bn) | C41: =D33 -> -2781.41 | D41: =D33 -> -2781.41 | E41: =D33 -> -2781.41 | F41: =D33 -> -2781.41
B42: Value today (KRW bn) | C42: =C39 -> 15000 | D42: =D39 -> 25000 | E42: =E39 -> 35000 | F42: =F39 -> 50000
B43: Realised IRR | C43: =XIRR(C40:C42,$C$32:$C$34) -> 0.077423649 | D43: =XIRR(D40:D42,$C$32:$C$34) -> 0.21583516 | E43: =XIRR(E40:E42,$C$32:$C$34) -> 0.31326807 | F43: =XIRR(F40:F42,$C$32:$C$34) -> 0.42278246

Sheet Comps
B1: Comparable transactions and trading multiples (EV / revenue)
B2: NAND M&A is rare: only two large precedents. Several inputs are approximate and flagged; verify with CapIQ/Bloomberg before use.
B4: Precedent NAND transactions
B5: Deal | C5: Announced | D5: Value (US$ bn) | E5: Revenue (US$ bn) | F5: Multiple | G5: Basis / note
B6: Western Digital / SanDisk | C6: Oct 2015 | D6: 19 | E6: 5.56 | F6: =D6/E6 -> 3.4172662 | G6: Equity value / FY2015 revenue (WD 8-K; Storage Newsletter). SanDisk held large net cash, so EV/revenue is lower
B7: Bain consortium / Toshiba Memory | C7: Sep 2017 | D7: 18 | E7: 8.1 | F7: =D7/E7 -> 2.2222222 | G7: JPY 2tn price; revenue is an APPROXIMATE proxy (FY2016 Toshiba memory/SSD sales ~JPY 0.9tn). Verify
B8: SK hynix / Intel NAND (this deal) | C8: Oct 2020 | D8: =price_usd/1000 -> 9 | E8: =tgt_rev/1000 -> 5.6 | F8: =D8/E8 -> 1.6071429 | G8: Run-rate revenue (2 x H1 2020)
B10: Listed memory peers around signing (approximate)
B11: Company | C11: Date | D11: EV (US$ bn) | E11: Revenue (US$ bn) | F11: EV / revenue | G11: Note
B12: Micron Technology | C12: Oct 2020 | D12: 54 | E12: 21.4 | F12: =D12/E12 -> 2.5233645 | G12: APPROX: market cap ~US$56bn less net cash; FY2020 revenue US$21.4bn. Verify
B13: Western Digital | C13: Oct 2020 | D13: 19 | E13: 16.7 | F13: =D13/E13 -> 1.1377246 | G13: APPROX: market cap ~US$11bn plus net debt ~US$8bn; FY2020 revenue US$16.7bn. Verify
B15: Implied value of the NAND business (US$ bn, on run-rate revenue)
B16: Method | C16: Low multiple | D16: High multiple | E16: Low value | F16: High value
B17: Precedent transactions (excl. this deal) | C17: =MIN(F6:F7) -> 2.2222222 | D17: =MAX(F6:F7) -> 3.4172662 | E17: =C17*tgt_rev/1000 -> 12.444444 | F17: =D17*tgt_rev/1000 -> 19.136691
B18: Listed peers | C18: =MIN(F12:F13) -> 1.1377246 | D18: =MAX(F12:F13) -> 2.5233645 | E18: =C18*tgt_rev/1000 -> 6.3712575 | F18: =D18*tgt_rev/1000 -> 14.130841
B20: Reading: SK hynix paid ~1.6x revenue, at or below the bottom of both ranges. Precedents were struck at different points in the memory cycle, which limits their comparability.

Sheet FX_Hedge
B1: What the won did to the price, and what a hedge would have done
B2: Forward = spot x ((1 + KRW rate) / (1 + USD rate)) ^ years. KRW bn unless stated.
B4: Tranche | C4: US$ mn | D4: Paid on | E4: Years | F4: Spot at signing | G4: Forward at signing | H4: Spot when paid | I4: KRW at signing spot | J4: KRW if hedged | K4: KRW actually (unhedged) | L4: Hedge saving
B5: 1. First closing | C5: =t1_usd -> 7000 | D5: =c1_date -> 44559 | E5: =(D5-ann_date)/365 -> 1.1917808 | F5: =fx_ann -> 1138.65 | G5: =F5*((1+r_krw)/(1+r_usd))^E5 -> 1151.5084 | H5: =fx_c1 -> 1185.51 | I5: =C5*F5/1000 -> 7970.55 | J5: =C5*G5*(1+dc_prem)/1000 -> 8060.5586 | K5: =C5*H5/1000 -> 8298.57 | L5: =K5-J5 -> 238.01141
B6: 2. Final closing | C6: =t2_usd -> 1900 | D6: =c2_date -> 45743 | E6: =(D6-ann_date)/365 -> 4.4356164 | F6: =fx_ann -> 1138.65 | G6: =F6*((1+r_krw)/(1+r_usd))^E6 -> 1187.247 | H6: =fx_c2 -> 1463.9 | I6: =C6*F6/1000 -> 2163.435 | J6: =C6*G6*(1+dc_prem)/1000 -> 2255.7694 | K6: =C6*H6/1000 -> 2781.41 | L6: =K6-J6 -> 525.64062
B7: Total | C7: =SUM(C5:C6) -> 8900 | I7: =SUM(I5:I6) -> 10133.985 | J7: =SUM(J5:J6) -> 10316.328 | K7: =SUM(K5:K6) -> 11079.98 | L7: =SUM(L5:L6) -> 763.65202
B9: Summary
B10: Extra KRW cost from the won's fall vs. signing | F10: =h_krw_actual-h_krw_sign -> 945.995
B11: as % of the price at signing | F11: =(h_krw_actual-h_krw_sign)/h_krw_sign -> 0.093348767
B12: Effective USD/KRW paid (unhedged) | F12: =h_krw_actual*1000/(t1_usd+t2_usd) -> 1244.9416
B13: Effective USD/KRW if hedged at signing | F13: =h_krw_hedged*1000/(t1_usd+t2_usd) -> 1159.138
B14: Cost of hedging vs. signing spot (forward points) | F14: =h_krw_hedged-h_krw_sign -> 182.34298
B15: Forward premium, tranche 2 (won per $) | F15: =h_fwd2-fx_ann -> 48.597044
B17: Reading: in 2020 KRW rates were above USD rates, so a forward to buy dollars was priced above spot (a cost). The won then fell far more than the forward implied, so the unhedged buyer paid more.
B18: Caveats: hedge rates are assumptions (Inputs). A real deal-contingent forward on a 4-year, regulator-dependent tranche would cost more and might be partly hedged with USD debt instead.
B20: Tranche 2 in KRW bn, by USD/KRW on the payment date
B21: USD/KRW when paid | C21: Unhedged | D21: Hedged at signing | E21: Hedge gain / (loss)
B22: 1000 | C22: =t2_usd*B22/1000 -> 1900 | D22: =t2_usd*h_fwd2*(1+dc_prem)/1000 -> 2255.7694 | E22: =C22-D22 -> -355.76938
B23: 1050 | C23: =t2_usd*B23/1000 -> 1995 | D23: =t2_usd*h_fwd2*(1+dc_prem)/1000 -> 2255.7694 | E23: =C23-D23 -> -260.76938
B24: 1100 | C24: =t2_usd*B24/1000 -> 2090 | D24: =t2_usd*h_fwd2*(1+dc_prem)/1000 -> 2255.7694 | E24: =C24-D24 -> -165.76938
B25: 1150 | C25: =t2_usd*B25/1000 -> 2185 | D25: =t2_usd*h_fwd2*(1+dc_prem)/1000 -> 2255.7694 | E25: =C25-D25 -> -70.769384
B26: 1200 | C26: =t2_usd*B26/1000 -> 2280 | D26: =t2_usd*h_fwd2*(1+dc_prem)/1000 -> 2255.7694 | E26: =C26-D26 -> 24.230616
B27: 1250 | C27: =t2_usd*B27/1000 -> 2375 | D27: =t2_usd*h_fwd2*(1+dc_prem)/1000 -> 2255.7694 | E27: =C27-D27 -> 119.23062
B28: 1300 | C28: =t2_usd*B28/1000 -> 2470 | D28: =t2_usd*h_fwd2*(1+dc_prem)/1000 -> 2255.7694 | E28: =C28-D28 -> 214.23062
B29: 1350 | C29: =t2_usd*B29/1000 -> 2565 | D29: =t2_usd*h_fwd2*(1+dc_prem)/1000 -> 2255.7694 | E29: =C29-D29 -> 309.23062
B30: 1400 | C30: =t2_usd*B30/1000 -> 2660 | D30: =t2_usd*h_fwd2*(1+dc_prem)/1000 -> 2255.7694 | E30: =C30-D30 -> 404.23062
B31: 1450 | C31: =t2_usd*B31/1000 -> 2755 | D31: =t2_usd*h_fwd2*(1+dc_prem)/1000 -> 2255.7694 | E31: =C31-D31 -> 499.23062
B32: 1500 | C32: =t2_usd*B32/1000 -> 2850 | D32: =t2_usd*h_fwd2*(1+dc_prem)/1000 -> 2255.7694 | E32: =C32-D32 -> 594.23062
B33: 1550 | C33: =t2_usd*B33/1000 -> 2945 | D33: =t2_usd*h_fwd2*(1+dc_prem)/1000 -> 2255.7694 | E33: =C33-D33 -> 689.23062
... B35: 1650 | C35: =t2_usd*B35/1000 -> 3135 | D35: =t2_usd*h_fwd2*(1+dc_prem)/1000 -> 2255.7694 | E35: =C35-D35 -> 879.23062
B38: Hedge instruments for tranche 2 compared (KRW bn)
B39: Strike = forward at signing (USD/KRW) | F39: =h_fwd2 -> 1187.247
B40: Years to payment | F40: =E6 -> 4.4356164
B41: Volatility | F41: =fx_vol -> 0.0875
B42: KRW rate (continuous) | F42: =LN(1+r_krw) -> 0.012916225
B43: USD rate (continuous) | F43: =LN(1+r_usd) -> 0.0034938893
B44: d1 | F44: =(LN(fx_ann/op_k)+(op_rd-op_rf+op_vol^2/2)*op_t)/(op_vol*SQRT(op_t)) -> 0.092141452
B45: d2 | F45: =op_d1-op_vol*SQRT(op_t) -> -0.092141452
B46: USD call / KRW put premium (KRW per USD, Garman-Kohlhagen) | F46: =fx_ann*EXP(-op_rf*op_t)*NORMSDIST(op_d1)-op_k*EXP(-op_rd*op_t)*NORMSDIST(op_d2) -> 82.30774
B47: Premium on tranche 2, paid at signing (KRW bn) | F47: =t2_usd*op_prem/1000 -> 156.38471
...

Sheet FX_MonteCarlo
B1: Monte Carlo: what could the deal cost in KRW? (2,000 simulated USD/KRW paths)
B2: Lognormal USD/KRW with forward drift (CIP) and the volatility on Inputs. Uniform draws are fixed values, so results are stable.
B4: Set-up | E4: # | F4: u1 | G4: u2 | H4: z1 | I4: z2 | J4: USD/KRW T1 | K4: USD/KRW T2 | L4: KRW cost (bn)
B5: Spot at signing | C5: =fx_ann -> 1138.65 | E5: 1 | F5: 0.043071 | G5: 0.918339 | H5: =NORMSINV(F5) -> -1.7161095 | I5: =NORMSINV(G5) -> 1.3939854 | J5: =mc_s0*EXP((mc_mu-mc_vol^2/2)*mc_t1+mc_vol*SQRT(mc_t1)*H5) -> 972.95557 | K5: =J5*EXP((mc_mu-mc_vol^2/2)*(mc_t2-mc_t1)+mc_vol*SQRT(mc_t2-mc_t1)*I5) -> 1234.187 | L5: =(t1_usd*J5+t2_usd*K5)/1000 -> 9155.6443
B6: Volatility (annualised) | C6: =fx_vol -> 0.0875 | E6: 2 | F6: 0.32841 | G6: 0.331689 | H6: =NORMSINV(F6) -> -0.44430789 | I6: =NORMSINV(G6) -> -0.4352541 | J6: =mc_s0*EXP((mc_mu-mc_vol^2/2)*mc_t1+mc_vol*SQRT(mc_t1)*H6) -> 1098.6355 | K6: =J6*EXP((mc_mu-mc_vol^2/2)*(mc_t2-mc_t1)+mc_vol*SQRT(mc_t2-mc_t1)*I6) -> 1044.588 | L6: =(t1_usd*J6+t2_usd*K6)/1000 -> 9675.1659
B7: Drift = ln((1 + KRW rate) / (1 + USD rate)) | C7: =LN((1+r_krw)/(1+r_usd)) -> 0.009422336 | E7: 3 | F7: 0.420354 | G7: 0.644136 | H7: =NORMSINV(F7) -> -0.20098795 | I7: =NORMSINV(G7) -> 0.36953633 | J7: =mc_s0*EXP((mc_mu-mc_vol^2/2)*mc_t1+mc_vol*SQRT(mc_t1)*H7) -> 1124.4697 | K7: =J7*EXP((mc_mu-mc_vol^2/2)*(mc_t2-mc_t1)+mc_vol*SQRT(mc_t2-mc_t1)*I7) -> 1213.7256 | L7: =(t1_usd*J7+t2_usd*K7)/1000 -> 10177.366
B8: Years to tranche 1 | C8: =FX_Hedge!E5 -> 1.1917808 | E8: 4 | F8: 0.753109 | G8: 0.283789 | H8: =NORMSINV(F8) -> 0.68430594 | I8: =NORMSINV(G8) -> -0.57162213 | J8: =mc_s0*EXP((mc_mu-mc_vol^2/2)*mc_t1+mc_vol*SQRT(mc_t1)*H8) -> 1223.6976 | K8: =J8*EXP((mc_mu-mc_vol^2/2)*(mc_t2-mc_t1)+mc_vol*SQRT(mc_t2-mc_t1)*I8) -> 1138.7601 | L8: =(t1_usd*J8+t2_usd*K8)/1000 -> 10729.528
B9: Years to tranche 2 | C9: =FX_Hedge!E6 -> 4.4356164 | E9: 5 | F9: 0.175661 | G9: 0.977542 | H9: =NORMSINV(F9) -> -0.93202811 | I9: =NORMSINV(G9) -> 2.0054403 | J9: =mc_s0*EXP((mc_mu-mc_vol^2/2)*mc_t1+mc_vol*SQRT(mc_t1)*H9) -> 1048.6259 | K9: =J9*EXP((mc_mu-mc_vol^2/2)*(mc_t2-mc_t1)+mc_vol*SQRT(mc_t2-mc_t1)*I9) -> 1464.7303 | L9: =(t1_usd*J9+t2_usd*K9)/1000 -> 10123.369
E10: 6 | F10: 0.071456 | G10: 0.596456 | H10: =NORMSINV(F10) -> -1.4650327 | I10: =NORMSINV(G10) -> 0.24418441 | J10: =mc_s0*EXP((mc_mu-mc_vol^2/2)*mc_t1+mc_vol*SQRT(mc_t1)*H10) -> 996.57254 | K10: =J10*EXP((mc_mu-mc_vol^2/2)*(mc_t2-mc_t1)+mc_vol*SQRT(mc_t2-mc_t1)*I10) -> 1054.6354 | L10: =(t1_usd*J10+t2_usd*K10)/1000 -> 8979.8151
B11: Distribution of total KRW cost (KRW bn) | E11: 7 | F11: 0.043197 | G11: 0.081886 | H11: =NORMSINV(F11) -> -1.714734 | I11: =NORMSINV(G11) -> -1.3924968 | J11: =mc_s0*EXP((mc_mu-mc_vol^2/2)*mc_t1+mc_vol*SQRT(mc_t1)*H11) -> 973.08341 | K11: =J11*EXP((mc_mu-mc_vol^2/2)*(mc_t2-mc_t1)+mc_vol*SQRT(mc_t2-mc_t1)*I11) -> 795.65723 | L11: =(t1_usd*J11+t2_usd*K11)/1000 -> 8323.3326
B12: Mean | C12: =AVERAGE($L$5:$L$2004) -> 10308.792 | E12: 8 | F12: 0.101927 | G12: 0.371517 | H12: =NORMSINV(F12) -> -1.2706477 | I12: =NORMSINV(G12) -> -0.3278382 | J12: =mc_s0*EXP((mc_mu-mc_vol^2/2)*mc_t1+mc_vol*SQRT(mc_t1)*H12) -> 1015.2499 | K12: =J12*EXP((mc_mu-mc_vol^2/2)*(mc_t2-mc_t1)+mc_vol*SQRT(mc_t2-mc_t1)*I12) -> 981.78439 | L12: =(t1_usd*J12+t2_usd*K12)/1000 -> 8972.1398
B13: 5th percentile | C13: =PERCENTILE($L$5:$L$2004,0.05) -> 8734.87 | E13: 9 | F13: 0.044003 | G13: 0.755591 | H13: =NORMSINV(F13) -> -1.7060112 | I13: =NORMSINV(G13) -> 0.69219003 | J13: =mc_s0*EXP((mc_mu-mc_vol^2/2)*mc_t1+mc_vol*SQRT(mc_t1)*H13) -> 973.89455 | K13: =J13*EXP((mc_mu-mc_vol^2/2)*(mc_t2-mc_t1)+mc_vol*SQRT(mc_t2-mc_t1)*I13) -> 1106.0321 | L13: =(t1_usd*J13+t2_usd*K13)/1000 -> 8918.7228
B14: Median | C14: =PERCENTILE($L$5:$L$2004,0.5) -> 10243.244 | E14: 10 | F14: 0.83088 | G14: 0.342945 | H14: =NORMSINV(F14) -> 0.95764857 | I14: =NORMSINV(G14) -> -0.4044389 | J14: =mc_s0*EXP((mc_mu-mc_vol^2/2)*mc_t1+mc_vol*SQRT(mc_t1)*H14) -> 1256.0697 | K14: =J14*EXP((mc_mu-mc_vol^2/2)*(mc_t2-mc_t1)+mc_vol*SQRT(mc_t2-mc_t1)*I14) -> 1200.091 | L14: =(t1_usd*J14+t2_usd*K14)/1000 -> 11072.661
B15: 95th percentile | C15: =PERCENTILE($L$5:$L$2004,0.95) -> 12104.159 | E15: 11 | F15: 0.576168 | G15: 0.908594 | H15: =NORMSINV(F15) -> 0.19209984 | I15: =NORMSINV(G15) -> 1.3321467 | J15: =mc_s0*EXP((mc_mu-mc_vol^2/2)*mc_t1+mc_vol*SQRT(mc_t1)*H15) -> 1167.4949 | K15: =J15*EXP((mc_mu-mc_vol^2/2)*(mc_t2-mc_t1)+mc_vol*SQRT(mc_t2-mc_t1)*I15) -> 1466.5963 | L15: =(t1_usd*J15+t2_usd*K15)/1000 -> 10958.997
B16: 99th percentile | C16: =PERCENTILE($L$5:$L$2004,0.99) -> 12889.907 | E16: 12 | F16: 0.778127 | G16: 0.192223 | H16: =NORMSINV(F16) -> 0.76588287 | I16: =NORMSINV(G16) -> -0.86973361 | J16: =mc_s0*EXP((mc_mu-mc_vol^2/2)*mc_t1+mc_vol*SQRT(mc_t1)*H16) -> 1233.2705 | K16: =J16*EXP((mc_mu-mc_vol^2/2)*(mc_t2-mc_t1)+mc_vol*SQRT(mc_t2-mc_t1)*I16) -> 1094.9976 | L16: =(t1_usd*J16+t2_usd*K16)/1000 -> 10713.389
B17: Cost if hedged at signing (FX_Hedge) | C17: =h_krw_hedged -> 10316.328 | E17: 13 | F17: 0.98391 | G17: 0.756221 | H17: =NORMSINV(F17) -> 2.1421676 | I17: =NORMSINV(G17) -> 0.69419807 | J17: =mc_s0*EXP((mc_mu-mc_vol^2/2)*mc_t1+mc_vol*SQRT(mc_t1)*H17) -> 1406.5444 | K17: =J17*EXP((mc_mu-mc_vol^2/2)*(mc_t2-mc_t1)+mc_vol*SQRT(mc_t2-mc_t1)*I17) -> 1597.8892 | L17: =(t1_usd*J17+t2_usd*K17)/1000 -> 12881.8
B18: Probability unhedged costs more than hedged | C18: =COUNTIF($L$5:$L$2004,">"&mc_hedged)/2000 -> 0.475 | E18: 14 | F18: 0.979265 | G18: 0.089597 | H18: =NORMSINV(F18) -> 2.0387999 | I18: =NORMSINV(G18) -> -1.3432408 | J18: =mc_s0*EXP((mc_mu-mc_vol^2/2)*mc_t1+mc_vol*SQRT(mc_t1)*H18) -> 1392.7246 | K18: =J18*EXP((mc_mu-mc_vol^2/2)*(mc_t2-mc_t1)+mc_vol*SQRT(mc_t2-mc_t1)*I18) -> 1147.6576 | L18: =(t1_usd*J18+t2_usd*K18)/1000 -> 11929.621
B19: Actual unhedged cost | C19: =h_krw_actual -> 11079.98 | E19: 15 | F19: 0.124901 | G19: 0.568892 | H19: =NORMSINV(F19) -> -1.1508304 | I19: =NORMSINV(G19) -> 0.17355398 | J19: =mc_s0*EXP((mc_mu-mc_vol^2/2)*mc_t1+mc_vol*SQRT(mc_t1)*H19) -> 1026.9365 | K19: =J19*EXP((mc_mu-mc_vol^2/2)*(mc_t2-mc_t1)+mc_vol*SQRT(mc_t2-mc_t1)*I19) -> 1074.7389 | L19: =(t1_usd*J19+t2_usd*K19)/1000 -> 9230.5592
B20: Percentile of the actual outcome | C20: =PERCENTRANK($L$5:$L$2004,mc_actual) -> 0.783 | E20: 16 | F20: 0.315087 | G20: 0.595767 | H20: =NORMSINV(F20) -> -0.48148196 | I20: =NORMSINV(G20) -> 0.24240547 | J20: =mc_s0*EXP((mc_mu-mc_vol^2/2)*mc_t1+mc_vol*SQRT(mc_t1)*H20) -> 1094.7412 | K20: =J20*EXP((mc_mu-mc_vol^2/2)*(mc_t2-mc_t1)+mc_vol*SQRT(mc_t2-mc_t1)*I20) -> 1158.1989 | L20: =(t1_usd*J20+t2_usd*K20)/1000 -> 9863.7665
B21: 95% worst case vs. hedged (KRW bn at risk) | C21: =mc_p95-mc_hedged -> 1787.8313 | E21: 17 | F21: 0.056064 | G21: 0.553085 | H21: =NORMSINV(F21) -> -1.5887006 | I21: =NORMSINV(G21) -> 0.13345949 | J21: =mc_s0*EXP((mc_mu-mc_vol^2/2)*mc_t1+mc_vol*SQRT(mc_t1)*H21) -> 984.86921 | K21: =J21*EXP((mc_mu-mc_vol^2/2)*(mc_t2-mc_t1)+mc_vol*SQRT(mc_t2-mc_t1)*I21) -> 1024.2213 | L21: =(t1_usd*J21+t2_usd*K21)/1000 -> 8840.1049
E22: 18 | F22: 0.953511 | G22: 0.549659 | H22: =NORMSINV(F22) -> 1.6798937 | I22: =NORMSINV(G22) -> 0.12479986 | J22: =mc_s0*EXP((mc_mu-mc_vol^2/2)*mc_t1+mc_vol*SQRT(mc_t1)*H22) -> 1345.7861 | K22: =J22*EXP((mc_mu-mc_vol^2/2)*(mc_t2-mc_t1)+mc_vol*SQRT(mc_t2-mc_t1)*I22) -> 1397.6505 | L22: =(t1_usd*J22+t2_usd*K22)/1000 -> 12076.038
B23: USD/KRW at the tranche-2 payment | E23: 19 | F23: 0.995334 | G23: 0.166671 | H23: =NORMSINV(F23) -> 2.5996459 | I23: =NORMSINV(G23) -> -0.96740422 | J23: =mc_s0*EXP((mc_mu-mc_vol^2/2)*mc_t1+mc_vol*SQRT(mc_t1)*H23) -> 1469.3725 | K23: =J23*EXP((mc_mu-mc_vol^2/2)*(mc_t2-mc_t1)+mc_vol*SQRT(mc_t2-mc_t1)*I23) -> 1284.7007 | L23: =(t1_usd*J23+t2_usd*K23)/1000 -> 12726.539
B24: 5th percentile | C24: =PERCENTILE($K$5:$K$2004,0.05) -> 869.98718 | E24: 20 | F24: 0.983819 | G24: 0.310973 | H24: =NORMSINV(F24) -> 2.1399105 | I24: =NORMSINV(G24) -> -0.49309424 | J24: =mc_s0*EXP((mc_mu-mc_vol^2/2)*mc_t1+mc_vol*SQRT(mc_t1)*H24) -> 1406.2411 | K24: =J24*EXP((mc_mu-mc_vol^2/2)*(mc_t2-mc_t1)+mc_vol*SQRT(mc_t2-mc_t1)*I24) -> 1324.9288 | L24: =(t1_usd*J24+t2_usd*K24)/1000 -> 12361.053
B25: Median | C25: =PERCENTILE($K$5:$K$2004,0.5) -> 1163.3374 | E25: 21 | F25: 0.947501 | G25: 0.525074 | H25: =NORMSINV(F25) -> 1.6210916 | I25: =NORMSINV(G25) -> 0.062892635 | J25: =mc_s0*EXP((mc_mu-mc_vol^2/2)*mc_t1+mc_vol*SQRT(mc_t1)*H25) -> 1338.2481 | K25: =J25*EXP((mc_mu-mc_vol^2/2)*(mc_t2-mc_t1)+mc_vol*SQRT(mc_t2-mc_t1)*I25) -> 1376.3286 | L25: =(t1_usd*J25+t2_usd*K25)/1000 -> 11982.761
B26: 95th percentile | C26: =PERCENTILE($K$5:$K$2004,0.95) -> 1566.1727 | E26: 22 | F26: 0.022367 | G26: 0.473328 | H26: =NORMSINV(F26) -> -2.0071471 | I26: =NORMSINV(G26) -> -0.066906674 | J26: =mc_s0*EXP((mc_mu-mc_vol^2/2)*mc_t1+mc_vol*SQRT(mc_t1)*H26) -> 946.27927 | K26: =J26*EXP((mc_mu-mc_vol^2/2)*(mc_t2-mc_t1)+mc_vol*SQRT(mc_t2-mc_t1)*I26) -> 953.50093 | L26: =(t1_usd*J26+t2_usd*K26)/1000 -> 8435.6067
B27: Forward at signing | C27: =h_fwd2 -> 1187.247 | E27: 23 | F27: 0.26049 | G27: 0.049748 | H27: =NORMSINV(F27) -> -0.6418355 | I27: =NORMSINV(G27) -> -1.6473019 | J27: =mc_s0*EXP((mc_mu-mc_vol^2/2)*mc_t1+mc_vol*SQRT(mc_t1)*H27) -> 1078.1004 | K27: =J27*EXP((mc_mu-mc_vol^2/2)*(mc_t2-mc_t1)+mc_vol*SQRT(mc_t2-mc_t1)*I27) -> 846.82919 | L27: =(t1_usd*J27+t2_usd*K27)/1000 -> 9155.6783
B28: Actual (27 Mar 2025) | C28: =fx_c2 -> 1463.9 | E28: 24 | F28: 0.79006 | G28: 0.178862 | H28: =NORMSINV(F28) -> 0.80662945 | I28: =NORMSINV(G28) -> -0.91971062 | J28: =mc_s0*EXP((mc_mu-mc_vol^2/2)*mc_t1+mc_vol*SQRT(mc_t1)*H28) -> 1238.08 | K28: =J28*EXP((mc_mu-mc_vol^2/2)*(mc_t2-mc_t1)+mc_vol*SQRT(mc_t2-mc_t1)*I28) -> 1090.644 | L28: =(t1_usd*J28+t2_usd*K28)/1000 -> 10738.784
E29: 25 | F29: 0.379062 | G29: 0.147593 | H29: =NORMSINV(F29) -> -0.30794524 | I29: =NORMSINV(G29) -> -1.0468126 | J29: =mc_s0*EXP((mc_mu-mc_vol^2/2)*mc_t1+mc_vol*SQRT(mc_t1)*H29) -> 1113.0396 | K29: =J29*EXP((mc_mu-mc_vol^2/2)*(mc_t2-mc_t1)+mc_vol*SQRT(mc_t2-mc_t1)*I29) -> 961.04969 | L29: =(t1_usd*J29+t2_usd*K29)/1000 -> 9617.2719
B30: Histogram of total KRW cost | E30: 26 | F30: 0.361323 | G30: 0.903963 | H30: =NORMSINV(F30) -> -0.3549247 | I30: =NORMSINV(G30) -> 1.3044682 | J30: =mc_s0*EXP((mc_mu-mc_vol^2/2)*mc_t1+mc_vol*SQRT(mc_t1)*H30) -> 1108.056 | K30: =J30*EXP((mc_mu-mc_vol^2/2)*(mc_t2-mc_t1)+mc_vol*SQRT(mc_t2-mc_t1)*I30) -> 1385.8714 | L30: =(t1_usd*J30+t2_usd*K30)/1000 -> 10389.547
B31: Bin from (KRW bn) | C31: Count | E31: 27 | F31: 0.124806 | G31: 0.137687 | H31: =NORMSINV(F31) -> -1.1512923 | I31: =NORMSINV(G31) -> -1.0907702 | J31: =mc_s0*EXP((mc_mu-mc_vol^2/2)*mc_t1+mc_vol*SQRT(mc_t1)*H31) -> 1026.8912 | K31: =J31*EXP((mc_mu-mc_vol^2/2)*(mc_t2-mc_t1)+mc_vol*SQRT(mc_t2-mc_t1)*I31) -> 880.54406 | L31: =(t1_usd*J31+t2_usd*K31)/1000 -> 8861.2719
B32: 9000 | C32: =COUNTIFS($L$5:$L$2004,">="&B32,$L$5:$L$2004,"<"&B33) -> 115 | E32: 28 | F32: 0.488534 | G32: 0.777255 | H32: =NORMSINV(F32) -> -0.028744958 | I32: =NORMSINV(G32) -> 0.76295539 | J32: =mc_s0*EXP((mc_mu-mc_vol^2/2)*mc_t1+mc_vol*SQRT(mc_t1)*H32) -> 1143.1237 | K32: =J32*EXP((mc_mu-mc_vol^2/2)*(mc_t2-mc_t1)+mc_vol*SQRT(mc_t2-mc_t1)*I32) -> 1312.7812 | L32: =(t1_usd*J32+t2_usd*K32)/1000 -> 10496.15
B33: 9250 | C33: =COUNTIFS($L$5:$L$2004,">="&B33,$L$5:$L$2004,"<"&B34) -> 138 | E33: 29 | F33: 0.468007 | G33: 0.656599 | H33: =NORMSINV(F33) -> -0.08028071 | I33: =NORMSINV(G33) -> 0.40319878 | J33: =mc_s0*EXP((mc_mu-mc_vol^2/2)*mc_t1+mc_vol*SQRT(mc_t1)*H33) -> 1137.5102 | K33: =J33*EXP((mc_mu-mc_vol^2/2)*(mc_t2-mc_t1)+mc_vol*SQRT(mc_t2-mc_t1)*I33) -> 1234.3319 | L33: =(t1_usd*J33+t2_usd*K33)/1000 -> 10307.802
B34: 9500 | C34: =COUNTIFS($L$5:$L$2004,">="&B34,$L$5:$L$2004,"<"&B35) -> 172 | E34: 30 | F34: 0.964195 | G34: 0.300642 | H34: =NORMSINV(F34) -> 1.8015896 | I34: =NORMSINV(G34) -> -0.52255495 | J34: =mc_s0*EXP((mc_mu-mc_vol^2/2)*mc_t1+mc_vol*SQRT(mc_t1)*H34) -> 1361.5217 | K34: =J34*EXP((mc_mu-mc_vol^2/2)*(mc_t2-mc_t1)+mc_vol*SQRT(mc_t2-mc_t1)*I34) -> 1276.8532 | L34: =(t1_usd*J34+t2_usd*K34)/1000 -> 11956.673
B35: 9750 | C35: =COUNTIFS($L$5:$L$2004,">="&B35,$L$5:$L$2004,"<"&B36) -> 173 | E35: 31 | F35: 0.158331 | G35: 0.683319 | H35: =NORMSINV(F35) -> -1.001341 | I35: =NORMSINV(G35) -> 0.47700017 | J35: =mc_s0*EXP((mc_mu-mc_vol^2/2)*mc_t1+mc_vol*SQRT(mc_t1)*H35) -> 1041.706 | K35: =J35*EXP((mc_mu-mc_vol^2/2)*(mc_t2-mc_t1)+mc_vol*SQRT(mc_t2-mc_t1)*I35) -> 1143.5968 | L35: =(t1_usd*J35+t2_usd*K35)/1000 -> 9464.7756
B36: 10000 | C36: =COUNTIFS($L$5:$L$2004,">="&B36,$L$5:$L$2004,"<"&B37) -> 208 | E36: 32 | F36: 0.800402 | G36: 0.835207 | H36: =NORMSINV(F36) -> 0.84305801 | I36: =NORMSINV(G36) -> 0.97494811 | J36: =mc_s0*EXP((mc_mu-mc_vol^2/2)*mc_t1+mc_vol*SQRT(mc_t1)*H36) -> 1242.3957 | K36: =J36*EXP((mc_mu-mc_vol^2/2)*(mc_t2-mc_t1)+mc_vol*SQRT(mc_t2-mc_t1)*I36) -> 1475.2588 | L36: =(t1_usd*J36+t2_usd*K36)/1000 -> 11499.762
B37: 10250 | C37: =COUNTIFS($L$5:$L$2004,">="&B37,$L$5:$L$2004,"<"&B38) -> 182 | E37: 33 | F37: 0.4381 | G37: 0.609387 | H37: =NORMSINV(F37) -> -0.15578816 | I37: =NORMSINV(G37) -> 0.2777217 | J37: =mc_s0*EXP((mc_mu-mc_vol^2/2)*mc_t1+mc_vol*SQRT(mc_t1)*H37) -> 1129.3352 | K37: =J37*EXP((mc_mu-mc_vol^2/2)*(mc_t2-mc_t1)+mc_vol*SQRT(mc_t2-mc_t1)*I37) -> 1201.4665 | L37: =(t1_usd*J37+t2_usd*K37)/1000 -> 10188.133
B38: 10500 | C38: =COUNTIFS($L$5:$L$2004,">="&B38,$L$5:$L$2004,"<"&B39) -> 185 | E38: 34 | F38: 0.253671 | G38: 0.999382 | H38: =NORMSINV(F38) -> -0.66298213 | I38: =NORMSINV(G38) -> 3.2304396 | J38: =mc_s0*EXP((mc_mu-mc_vol^2/2)*mc_t1+mc_vol*SQRT(mc_t1)*H38) -> 1075.9249 | K38: =J38*EXP((mc_mu-mc_vol^2/2)*(mc_t2-mc_t1)+mc_vol*SQRT(mc_t2-mc_t1)*I38) -> 1822.8891 | L38: =(t1_usd*J38+t2_usd*K38)/1000 -> 10994.963
B39: 10750 | C39: =COUNTIFS($L$5:$L$2004,">="&B39,$L$5:$L$2004,"<"&B40) -> 159 | E39: 35 | F39: 0.791908 | G39: 0.481943 | H39: =NORMSINV(F39) -> 0.8130594 | I39: =NORMSINV(G39) -> -0.045277652 | J39: =mc_s0*EXP((mc_mu-mc_vol^2/2)*mc_t1+mc_vol*SQRT(mc_t1)*H39) -> 1238.8407 | K39: =J39*EXP((mc_mu-mc_vol^2/2)*(mc_t2-mc_t1)+mc_vol*SQRT(mc_t2-mc_t1)*I39) -> 1252.5572 | L39: =(t1_usd*J39+t2_usd*K39)/1000 -> 11051.743
B40: 11000 | C40: =COUNTIFS($L$5:$L$2004,">="&B40,$L$5:$L$2004,"<"&B41) -> 123 | E40: 36 | F40: 0.129581 | G40: 0.801098 | H40: =NORMSINV(F40) -> -1.128374 | I40: =NORMSINV(G40) -> 0.84554969 | J40: =mc_s0*EXP((mc_mu-mc_vol^2/2)*mc_t1+mc_vol*SQRT(mc_t1)*H40) -> 1029.1417 | K40: =J40*EXP((mc_mu-mc_vol^2/2)*(mc_t2-mc_t1)+mc_vol*SQRT(mc_t2-mc_t1)*I40) -> 1197.3667 | L40: =(t1_usd*J40+t2_usd*K40)/1000 -> 9478.9889
B41: 11250 | C41: =COUNTIFS($L$5:$L$2004,">="&B41,$L$5:$L$2004,"<"&B42) -> 96 | E41: 37 | F41: 0.073614 | G41: 0.972378 | H41: =NORMSINV(F41) -> -1.4493925 | I41: =NORMSINV(G41) -> 1.9169522 | J41: =mc_s0*EXP((mc_mu-mc_vol^2/2)*mc_t1+mc_vol*SQRT(mc_t1)*H41) -> 998.06253 | K41: =J41*EXP((mc_mu-mc_vol^2/2)*(mc_t2-mc_t1)+mc_vol*SQRT(mc_t2-mc_t1)*I41) -> 1374.7969 | L41: =(t1_usd*J41+t2_usd*K41)/1000 -> 9598.5517
...

Sheet Sensitivity
B1: Sensitivity of year-1 EPS accretion
B2: Each cell recomputes the Model with that row/column value; everything else from Inputs.
B4: A. Synergies (rows, US$ mn) x share funded by debt (columns; rest cash, no new shares)
B5: Synergies \ Debt % | C5: 0 | D5: 0.25 | E5: 0.5 | F5: 0.75 | G5: 1
B6: 0 | C6: =((tgt_ebit+$B6)*fx_earn/1000-(price_usd*fx_ann/1000)*intang_pct/amort_yrs-ppe_step*fx_ann/1000/ppe_life-(price_usd*fx_ann/1000)*C$5*kd-(price_usd*fx_ann/1000)*(1-C$5)*ri)*(1-tax)/buyer_ni -> 0.10207526 | D6: =((tgt_ebit+$B6)*fx_earn/1000-(price_usd*fx_ann/1000)*intang_pct/amort_yrs-ppe_step*fx_ann/1000/ppe_life-(price_usd*fx_ann/1000)*D$5*kd-(price_usd*fx_ann/1000)*(1-D$5)*ri)*(1-tax)/buyer_ni -> 0.098953538 | E6: =((tgt_ebit+$B6)*fx_earn/1000-(price_usd*fx_ann/1000)*intang_pct/amort_yrs-ppe_step*fx_ann/1000/ppe_life-(price_usd*fx_ann/1000)*E$5*kd-(price_usd*fx_ann/1000)*(1-E$5)*ri)*(1-tax)/buyer_ni -> 0.095831819 | F6: =((tgt_ebit+$B6)*fx_earn/1000-(price_usd*fx_ann/1000)*intang_pct/amort_yrs-ppe_step*fx_ann/1000/ppe_life-(price_usd*fx_ann/1000)*F$5*kd-(price_usd*fx_ann/1000)*(1-F$5)*ri)*(1-tax)/buyer_ni -> 0.0927101 | G6: =((tgt_ebit+$B6)*fx_earn/1000-(price_usd*fx_ann/1000)*intang_pct/amort_yrs-ppe_step*fx_ann/1000/ppe_life-(price_usd*fx_ann/1000)*G$5*kd-(price_usd*fx_ann/1000)*(1-G$5)*ri)*(1-tax)/buyer_ni -> 0.089588381
B7: 100 | C7: =((tgt_ebit+$B7)*fx_earn/1000-(price_usd*fx_ann/1000)*intang_pct/amort_yrs-ppe_step*fx_ann/1000/ppe_life-(price_usd*fx_ann/1000)*C$5*kd-(price_usd*fx_ann/1000)*(1-C$5)*ri)*(1-tax)/buyer_ni -> 0.11941814 | D7: =((tgt_ebit+$B7)*fx_earn/1000-(price_usd*fx_ann/1000)*intang_pct/amort_yrs-ppe_step*fx_ann/1000/ppe_life-(price_usd*fx_ann/1000)*D$5*kd-(price_usd*fx_ann/1000)*(1-D$5)*ri)*(1-tax)/buyer_ni -> 0.11629642 | E7: =((tgt_ebit+$B7)*fx_earn/1000-(price_usd*fx_ann/1000)*intang_pct/amort_yrs-ppe_step*fx_ann/1000/ppe_life-(price_usd*fx_ann/1000)*E$5*kd-(price_usd*fx_ann/1000)*(1-E$5)*ri)*(1-tax)/buyer_ni -> 0.1131747 | F7: =((tgt_ebit+$B7)*fx_earn/1000-(price_usd*fx_ann/1000)*intang_pct/amort_yrs-ppe_step*fx_ann/1000/ppe_life-(price_usd*fx_ann/1000)*F$5*kd-(price_usd*fx_ann/1000)*(1-F$5)*ri)*(1-tax)/buyer_ni -> 0.11005298 | G7: =((tgt_ebit+$B7)*fx_earn/1000-(price_usd*fx_ann/1000)*intang_pct/amort_yrs-ppe_step*fx_ann/1000/ppe_life-(price_usd*fx_ann/1000)*G$5*kd-(price_usd*fx_ann/1000)*(1-G$5)*ri)*(1-tax)/buyer_ni -> 0.10693126
B8: 200 | C8: =((tgt_ebit+$B8)*fx_earn/1000-(price_usd*fx_ann/1000)*intang_pct/amort_yrs-ppe_step*fx_ann/1000/ppe_life-(price_usd*fx_ann/1000)*C$5*kd-(price_usd*fx_ann/1000)*(1-C$5)*ri)*(1-tax)/buyer_ni -> 0.13676102 | D8: =((tgt_ebit+$B8)*fx_earn/1000-(price_usd*fx_ann/1000)*intang_pct/amort_yrs-ppe_step*fx_ann/1000/ppe_life-(price_usd*fx_ann/1000)*D$5*kd-(price_usd*fx_ann/1000)*(1-D$5)*ri)*(1-tax)/buyer_ni -> 0.1336393 | E8: =((tgt_ebit+$B8)*fx_earn/1000-(price_usd*fx_ann/1000)*intang_pct/amort_yrs-ppe_step*fx_ann/1000/ppe_life-(price_usd*fx_ann/1000)*E$5*kd-(price_usd*fx_ann/1000)*(1-E$5)*ri)*(1-tax)/buyer_ni -> 0.13051759 | F8: =((tgt_ebit+$B8)*fx_earn/1000-(price_usd*fx_ann/1000)*intang_pct/amort_yrs-ppe_step*fx_ann/1000/ppe_life-(price_usd*fx_ann/1000)*F$5*kd-(price_usd*fx_ann/1000)*(1-F$5)*ri)*(1-tax)/buyer_ni -> 0.12739587 | G8: =((tgt_ebit+$B8)*fx_earn/1000-(price_usd*fx_ann/1000)*intang_pct/amort_yrs-ppe_step*fx_ann/1000/ppe_life-(price_usd*fx_ann/1000)*G$5*kd-(price_usd*fx_ann/1000)*(1-G$5)*ri)*(1-tax)/buyer_ni -> 0.12427415
B9: 300 | C9: =((tgt_ebit+$B9)*fx_earn/1000-(price_usd*fx_ann/1000)*intang_pct/amort_yrs-ppe_step*fx_ann/1000/ppe_life-(price_usd*fx_ann/1000)*C$5*kd-(price_usd*fx_ann/1000)*(1-C$5)*ri)*(1-tax)/buyer_ni -> 0.15410391 | D9: =((tgt_ebit+$B9)*fx_earn/1000-(price_usd*fx_ann/1000)*intang_pct/amort_yrs-ppe_step*fx_ann/1000/ppe_life-(price_usd*fx_ann/1000)*D$5*kd-(price_usd*fx_ann/1000)*(1-D$5)*ri)*(1-tax)/buyer_ni -> 0.15098219 | E9: =((tgt_ebit+$B9)*fx_earn/1000-(price_usd*fx_ann/1000)*intang_pct/amort_yrs-ppe_step*fx_ann/1000/ppe_life-(price_usd*fx_ann/1000)*E$5*kd-(price_usd*fx_ann/1000)*(1-E$5)*ri)*(1-tax)/buyer_ni -> 0.14786047 | F9: =((tgt_ebit+$B9)*fx_earn/1000-(price_usd*fx_ann/1000)*intang_pct/amort_yrs-ppe_step*fx_ann/1000/ppe_life-(price_usd*fx_ann/1000)*F$5*kd-(price_usd*fx_ann/1000)*(1-F$5)*ri)*(1-tax)/buyer_ni -> 0.14473875 | G9: =((tgt_ebit+$B9)*fx_earn/1000-(price_usd*fx_ann/1000)*intang_pct/amort_yrs-ppe_step*fx_ann/1000/ppe_life-(price_usd*fx_ann/1000)*G$5*kd-(price_usd*fx_ann/1000)*(1-G$5)*ri)*(1-tax)/buyer_ni -> 0.14161703
B10: 400 | C10: =((tgt_ebit+$B10)*fx_earn/1000-(price_usd*fx_ann/1000)*intang_pct/amort_yrs-ppe_step*fx_ann/1000/ppe_life-(price_usd*fx_ann/1000)*C$5*kd-(price_usd*fx_ann/1000)*(1-C$5)*ri)*(1-tax)/buyer_ni -> 0.17144679 | D10: =((tgt_ebit+$B10)*fx_earn/1000-(price_usd*fx_ann/1000)*intang_pct/amort_yrs-ppe_step*fx_ann/1000/ppe_life-(price_usd*fx_ann/1000)*D$5*kd-(price_usd*fx_ann/1000)*(1-D$5)*ri)*(1-tax)/buyer_ni -> 0.16832507 | E10: =((tgt_ebit+$B10)*fx_earn/1000-(price_usd*fx_ann/1000)*intang_pct/amort_yrs-ppe_step*fx_ann/1000/ppe_life-(price_usd*fx_ann/1000)*E$5*kd-(price_usd*fx_ann/1000)*(1-E$5)*ri)*(1-tax)/buyer_ni -> 0.16520335 | F10: =((tgt_ebit+$B10)*fx_earn/1000-(price_usd*fx_ann/1000)*intang_pct/amort_yrs-ppe_step*fx_ann/1000/ppe_life-(price_usd*fx_ann/1000)*F$5*kd-(price_usd*fx_ann/1000)*(1-F$5)*ri)*(1-tax)/buyer_ni -> 0.16208163 | G10: =((tgt_ebit+$B10)*fx_earn/1000-(price_usd*fx_ann/1000)*intang_pct/amort_yrs-ppe_step*fx_ann/1000/ppe_life-(price_usd*fx_ann/1000)*G$5*kd-(price_usd*fx_ann/1000)*(1-G$5)*ri)*(1-tax)/buyer_ni -> 0.15895991
B11: 500 | C11: =((tgt_ebit+$B11)*fx_earn/1000-(price_usd*fx_ann/1000)*intang_pct/amort_yrs-ppe_step*fx_ann/1000/ppe_life-(price_usd*fx_ann/1000)*C$5*kd-(price_usd*fx_ann/1000)*(1-C$5)*ri)*(1-tax)/buyer_ni -> 0.18878967 | D11: =((tgt_ebit+$B11)*fx_earn/1000-(price_usd*fx_ann/1000)*intang_pct/amort_yrs-ppe_step*fx_ann/1000/ppe_life-(price_usd*fx_ann/1000)*D$5*kd-(price_usd*fx_ann/1000)*(1-D$5)*ri)*(1-tax)/buyer_ni -> 0.18566795 | E11: =((tgt_ebit+$B11)*fx_earn/1000-(price_usd*fx_ann/1000)*intang_pct/amort_yrs-ppe_step*fx_ann/1000/ppe_life-(price_usd*fx_ann/1000)*E$5*kd-(price_usd*fx_ann/1000)*(1-E$5)*ri)*(1-tax)/buyer_ni -> 0.18254624 | F11: =((tgt_ebit+$B11)*fx_earn/1000-(price_usd*fx_ann/1000)*intang_pct/amort_yrs-ppe_step*fx_ann/1000/ppe_life-(price_usd*fx_ann/1000)*F$5*kd-(price_usd*fx_ann/1000)*(1-F$5)*ri)*(1-tax)/buyer_ni -> 0.17942452 | G11: =((tgt_ebit+$B11)*fx_earn/1000-(price_usd*fx_ann/1000)*intang_pct/amort_yrs-ppe_step*fx_ann/1000/ppe_life-(price_usd*fx_ann/1000)*G$5*kd-(price_usd*fx_ann/1000)*(1-G$5)*ri)*(1-tax)/buyer_ni -> 0.1763028
B12: No new shares, so accretion = after-tax contribution / standalone net income.
B14: B. USD/KRW for target earnings (rows) x USD/KRW paid for the target (columns), base financing
B15: Earnings FX \ Price FX | C15: 1000 | D15: 1100 | E15: 1200 | F15: 1300 | G15: 1400 | H15: 1500 | I15: 1600
B16: 1000 | C16: =((buyer_ni+((tgt_ebit+syn_usd)*$B16/1000-(price_usd*C$15/1000)*intang_pct/amort_yrs-ppe_step*C$15/1000/ppe_life-(price_usd*C$15/1000)*pct_debt*kd-(price_usd*C$15/1000)*pct_cash*ri)*(1-tax))/(buyer_sh+(price_usd*C$15/1000)*pct_stock*1000/buyer_px))/(buyer_ni/buyer_sh)-1 -> 0.084162665 | D16: =((buyer_ni+((tgt_ebit+syn_usd)*$B16/1000-(price_usd*D$15/1000)*intang_pct/amort_yrs-ppe_step*D$15/1000/ppe_life-(price_usd*D$15/1000)*pct_debt*kd-(price_usd*D$15/1000)*pct_cash*ri)*(1-tax))/(buyer_sh+(price_usd*D$15/1000)*pct_stock*1000/buyer_px))/(buyer_ni/buyer_sh)-1 -> 0.074301621 | E16: =((buyer_ni+((tgt_ebit+syn_usd)*$B16/1000-(price_usd*E$15/1000)*intang_pct/amort_yrs-ppe_step*E$15/1000/ppe_life-(price_usd*E$15/1000)*pct_debt*kd-(price_usd*E$15/1000)*pct_cash*ri)*(1-tax))/(buyer_sh+(price_usd*E$15/1000)*pct_stock*1000/buyer_px))/(buyer_ni/buyer_sh)-1 -> 0.064440576 | F16: =((buyer_ni+((tgt_ebit+syn_usd)*$B16/1000-(price_usd*F$15/1000)*intang_pct/amort_yrs-ppe_step*F$15/1000/ppe_life-(price_usd*F$15/1000)*pct_debt*kd-(price_usd*F$15/1000)*pct_cash*ri)*(1-tax))/(buyer_sh+(price_usd*F$15/1000)*pct_stock*1000/buyer_px))/(buyer_ni/buyer_sh)-1 -> 0.054579532 | G16: =((buyer_ni+((tgt_ebit+syn_usd)*$B16/1000-(price_usd*G$15/1000)*intang_pct/amort_yrs-ppe_step*G$15/1000/ppe_life-(price_usd*G$15/1000)*pct_debt*kd-(price_usd*G$15/1000)*pct_cash*ri)*(1-tax))/(buyer_sh+(price_usd*G$15/1000)*pct_stock*1000/buyer_px))/(buyer_ni/buyer_sh)-1 -> 0.044718487 | H16: =((buyer_ni+((tgt_ebit+syn_usd)*$B16/1000-(price_usd*H$15/1000)*intang_pct/amort_yrs-ppe_step*H$15/1000/ppe_life-(price_usd*H$15/1000)*pct_debt*kd-(price_usd*H$15/1000)*pct_cash*ri)*(1-tax))/(buyer_sh+(price_usd*H$15/1000)*pct_stock*1000/buyer_px))/(buyer_ni/buyer_sh)-1 -> 0.034857443 | I16: =((buyer_ni+((tgt_ebit+syn_usd)*$B16/1000-(price_usd*I$15/1000)*intang_pct/amort_yrs-ppe_step*I$15/1000/ppe_life-(price_usd*I$15/1000)*pct_debt*kd-(price_usd*I$15/1000)*pct_cash*ri)*(1-tax))/(buyer_sh+(price_usd*I$15/1000)*pct_stock*1000/buyer_px))/(buyer_ni/buyer_sh)-1 -> 0.024996399
